Workbook

Sheet Index
A2: Workbook Index
A5: Disposition Sheet | B5: This Sheet tracks daily progress on all activities - this sheet automatically populates the Section 1 Baselay. This sheet is customized to track the specific tasks as required by the company
A7: Report | B7: This sheet is the summary of the project - includes all progress for each activity and all costs
A8: Section 1 - Baselay | B8: This sheet has a copy of the baselay contract in it and all progress invoices are tracked and totalled on these sheets
A9: Section 1, 2 & 3 | B9: These sheets can be used to track all lump sum, quantities and unit pay items
A11: Extra Work (Contractor) | B11: This sheet is used to track all extra work items done by the contractor
A13: Schedule D - Other | B13: This sheet is used to track all costs of others on the project other than the contractor.
A15: All costs from the Baselay, Section 1, 2 & 3, Extra Work and Schedule D are linked to the report in the costs section'
A16: Contractor Holdback | B16: This sheet tracks all holdbacks from Contractors Progress Billings.
A18: Change Order Log, SQ Log, | B18: These logs track all site queries/change orders from the Contractor to be approved by the company
A20: Progress Chart | B20: Chart tracking progress - information from report
A25: All of the worksheets are customized to fit the project, if there is more than one segment on the project, other disposition sheets can be added to accommodate

Sheet REPORT
A1: REPORT DATE: | B1: ='Actual PROGRESS'!B5+1 -> 1 | D1: PROGRESS DATE: | H1: ROW Conditions | J1: REPORT # | L1: =SUM(L3:M11) -> 0 | N1: Man Days | Q1: Manday Projection based on a 12 hour day
H2: Drying | J2: 1 | L2: Estimated Total Man Hours | N2: To Date | O2: Previous | P2: =E1 -> 0 | Q2: Company
A3: ATTENTION: | H3: Wet | L3: =N3*12 -> 0 | N3: =O3+P3 -> 0
A4: OWNER: | B4: Pembina Pipeline | L4: =N4*12 -> 0 | N4: =O4+P4 -> 0
A5: JOB #: | B5: Namao to RFS | L5: =N5*12 -> 0 | N5: =O5+P5 -> 0
A6: PROJECT # : | B6: M/13295 | I6: =B1 -> 1 | L6: =N6*12 -> 0 | N6: =O6+P6 -> 0
A7: PROJECT MANAGER: | H7: Sunny | L7: =N7*12 -> 0 | N7: =O7+P7 -> 0
A8: SUPERINTENDANT: | H8: High | L8: =N8*12 -> 0 | N8: =O8+P8 -> 0
A9: ASST. SUPER. | H9: Low | L9: =N9*12 -> 0 | N9: =O9+P9 -> 0
H10: Wind | L10: =N10*12 -> 0 | N10: =O10+P10 -> 0
H11: Feels Like | L11: =N11*12 -> 0 | N11: =O11+P11 -> 0
C12: Based on Schedule Rev: | D12: 1 | H12: AFTERNOON FORECAST
A13: TOTAL PROJECT PROGRESS: | F13: =+'Actual PROGRESS'!J2 -> 0
A14: PROGRESS BY OPERATION | D14: % COMPLETE | F14: PLANNED % COMPLETE | H14: TOTAL TO DATE | K14: PROGRESS TODAY | N14: BALANCE
A15: ='Actual PROGRESS'!C12 -> Survey | D15: ='Actual PROGRESS'!C8 -> 0 | E15: +/- complete vs planned | F15: ='Planned PROGRESS'!C8 -> #DIV/0! | H15: ='Actual PROGRESS'!C10 -> 0 | I15: METERS | K15: =VLOOKUP(REPORT!$E$1,'Actual PROGRESS'!$B$13:$N$163,2,FALSE) -> #N/A | L15: METERS | N15: ='Actual PROGRESS'!C9 -> 36000 | O15: METERS
A16: ='Actual PROGRESS'!D12 -> Clear and Grub | D16: ='Actual PROGRESS'!D8 -> 0 | E16: =D16-F16 -> #DIV/0! | F16: ='Planned PROGRESS'!D8 -> #DIV/0! | H16: ='Actual PROGRESS'!D10 -> 0 | I16: METERS | K16: =VLOOKUP(REPORT!$E$1,'Actual PROGRESS'!$B$13:$N$163,3,FALSE) -> #N/A | L16: METERS | N16: ='Actual PROGRESS'!D9 -> 36000 | O16: METERS
A17: ='Actual PROGRESS'!E12 -> Grade the Site | D17: ='Actual PROGRESS'!E8 -> 0 | E17: =D17-F17 -> #DIV/0! | F17: ='Planned PROGRESS'!E8 -> #DIV/0! | H17: ='Actual PROGRESS'!E10 -> 0 | I17: METERS | K17: =VLOOKUP(REPORT!$E$1,'Actual PROGRESS'!$B$13:$N$163,4,FALSE) -> #N/A | L17: METERS | N17: ='Actual PROGRESS'!E9 -> 36000 | O17: METERS
A18: ='Actual PROGRESS'!F12 -> Unload, Haul & String | D18: ='Actual PROGRESS'!F8 -> 0 | E18: =D18-F18 -> #DIV/0! | F18: ='Planned PROGRESS'!F8 -> #DIV/0! | H18: ='Actual PROGRESS'!F10 -> 0 | I18: METERS | K18: =VLOOKUP(REPORT!$E$1,'Actual PROGRESS'!$B$13:$N$163,5,FALSE) -> #N/A | L18: METERS | N18: ='Actual PROGRESS'!F9 -> 36000 | O18: METERS
A19: ='Actual PROGRESS'!G12 -> Bending | D19: ='Actual PROGRESS'!G8 -> 0 | E19: =D19-F19 -> #DIV/0! | F19: ='Planned PROGRESS'!G8 -> #DIV/0! | H19: ='Actual PROGRESS'!G10 -> 0 | I19: METERS | K19: =VLOOKUP(REPORT!$E$1,'Actual PROGRESS'!$B$13:$N$163,6,FALSE) -> #N/A | L19: METERS | N19: ='Actual PROGRESS'!G9 -> 36000 | O19: METERS
A20: ='Actual PROGRESS'!H12 -> Welding | D20: =+'Actual PROGRESS'!H8 -> 0 | E20: =D20-F20 -> #DIV/0! | F20: ='Planned PROGRESS'!H8 -> #DIV/0! | H20: ='Actual PROGRESS'!H10 -> 0 | I20: METERS | K20: =VLOOKUP(REPORT!$E$1,'Actual PROGRESS'!$B$13:$N$163,7,FALSE) -> #N/A | L20: METERS | N20: ='Actual PROGRESS'!H9 -> 36000 | O20: METERS
A21: ='Actual PROGRESS'!I12 -> Trenching | D21: ='Actual PROGRESS'!I8 -> 0 | E21: =D21-F21 -> #DIV/0! | F21: ='Planned PROGRESS'!I8 -> #DIV/0! | H21: ='Actual PROGRESS'!I10 -> 0 | I21: METERS | K21: =VLOOKUP(REPORT!$E$1,'Actual PROGRESS'!$B$13:$N$163,8,FALSE) -> #N/A | L21: METERS | N21: ='Actual PROGRESS'!I9 -> 36000 | O21: METERS
A22: ='Actual PROGRESS'!J12 -> Lower-In | D22: =+'Actual PROGRESS'!J8 -> 0 | E22: =D22-F22 -> #DIV/0! | F22: ='Planned PROGRESS'!J8 -> #DIV/0! | H22: ='Actual PROGRESS'!J10 -> 0 | I22: METERS | K22: =VLOOKUP(REPORT!$E$1,'Actual PROGRESS'!$B$13:$N$163,9,FALSE) -> #N/A | L22: METERS | N22: ='Actual PROGRESS'!J9 -> 36000 | O22: METERS
A23: ='Actual PROGRESS'!K12 -> Backfill | D23: =+'Actual PROGRESS'!K8 -> 0 | E23: =D23-F23 -> #DIV/0! | F23: ='Planned PROGRESS'!K8 -> #DIV/0! | H23: ='Actual PROGRESS'!K10 -> 0 | I23: METERS | K23: =VLOOKUP(REPORT!$E$1,'Actual PROGRESS'!$B$13:$N$163,10,FALSE) -> #N/A | L23: METERS | N23: ='Actual PROGRESS'!K9 -> 36000 | O23: METERS
A24: ='Actual PROGRESS'!L12 -> Machine Clean-Up | D24: =+'Actual PROGRESS'!L8 -> 0 | E24: =D24-F24 -> #DIV/0! | F24: ='Planned PROGRESS'!L8 -> #DIV/0! | H24: ='Actual PROGRESS'!L10 -> 0 | I24: METERS | K24: =VLOOKUP(REPORT!$E$1,'Actual PROGRESS'!$B$13:$N$163,11,FALSE) -> #N/A | L24: METERS | N24: ='Actual PROGRESS'!L9 -> 36000 | O24: METERS
A25: ='Actual PROGRESS'!M12 -> Testing | D25: =+'Actual PROGRESS'!M8 -> 0 | E25: =D25-F25 -> #DIV/0! | F25: ='Planned PROGRESS'!M8 -> #DIV/0! | H25: ='Actual PROGRESS'!M10 -> 0 | I25: METERS | K25: =VLOOKUP(REPORT!$E$1,'Actual PROGRESS'!$B$13:$N$163,12,FALSE) -> #N/A | L25: METERS | N25: ='Actual PROGRESS'!M9 -> 36000 | O25: METERS
A26: ='Actual PROGRESS'!N12 -> Final Clean-Up | D26: =+'Actual PROGRESS'!N8 -> 0 | E26: =D26-F26 -> #DIV/0! | F26: ='Planned PROGRESS'!N8 -> #DIV/0! | H26: ='Actual PROGRESS'!N10 -> 0 | I26: METERS | K26: =VLOOKUP(REPORT!$E$1,'Actual PROGRESS'!$B$13:$N$163,13,FALSE) -> #N/A | L26: METERS | N26: ='Actual PROGRESS'!N9 -> 36000 | O26: METERS
A27: Banister & Subs as of: | B27: =E1 -> 0 | C27: MTS as of: | D27: =E1 -> 0 | E27: Others as of: | F27: =E1 -> 0 | G27: SAFETY
A28: Lost Time Accident (LTA) | B28: 0 | C28: LTA | D28: 0 | E28: LTA | F28: 0
A29: Medical Aid (MA) | B29: 0 | C29: MA | D29: 0 | E29: MA | F29: 0
A30: Restricted Work (RW) | B30: 0 | C30: RW | D30: 0 | E30: RW | F30: 0
A31: First Aid (FA) | B31: 0 | C31: FA | D31: 0 | E31: FA | F31: 0 | G31: ENVIRONMENTAL
A32: Property Damage (PD) | B32: 0 | C32: PD | D32: 0 | E32: PD | F32: 0
A33: Motor Vehicle Accident (MVA) | B33: 0 | C33: MVA | D33: 0 | E33: MVA | F33: 0
A34: Non-Conformance (NC) | B34: 0 | C34: NC | D34: 0 | E34: NC | F34: 0
A35: Near Miss | B35: 0 | C35: NM | D35: 0 | E35: NM | F35: 0
A36: NOTE: The statistics for this table are found on the Central Spread Reports.
A37: GENERAL PROGRESS
A38: SURVEY / LOCATES
A43: ACCESS
A49: GRADE
...

Sheet Actual PROGRESS
A1: Superintendent | G1: Total ROW Meters | J1: 36000 | AC1: 1
G2: % Project is complete | J2: =SUM(D8+E8+F8+G8+H8+I8+J8+K8+L8+M8+N8)/11 -> 0
A3: Contractor: Surerus
G4: Meters of Pipe
A5: Date | B5: =REPORT!E1 -> 0
A7: % LEFT TO DO | C7: =100%-C8 -> 1 | D7: =100%-D8 -> 1 | E7: =100%-E8 -> 1 | F7: =100%-F8 -> 1 | G7: =100%-G8 -> 1 | H7: =100%-H8 -> 1 | I7: =100%-I8 -> 1 | J7: =100%-J8 -> 1 | ... R7: =100%-R8 -> 1
A8: % COMPLETE TO DATE | C8: =+C10/$J1 -> 0 | D8: =+D10/$J1 -> 0 | E8: =+E10/$J1 -> 0 | F8: =+F10/$J1 -> 0 | G8: =+G10/$J1 -> 0 | H8: =+H10/$J1 -> 0 | I8: =+I10/$J1 -> 0 | J8: =+J10/$J1 -> 0 | ... R8: =+R10/$J1 -> 0
A9: Remaining balance | C9: =+$J1-C10 -> 36000 | D9: =+$J1-D10 -> 36000 | E9: =+$J1-E10 -> 36000 | F9: =+$J1-F10 -> 36000 | G9: =+$J1-G10 -> 36000 | H9: =+$J1-H10 -> 36000 | I9: =+$J1-I10 -> 36000 | J9: =+$J1-J10 -> 36000 | ... R9: =+$J1-R10 -> 36000
A10: Completed to Date | C10: =SUM(C13:C163) -> 0 | D10: =SUM(D13:D163) -> 0 | E10: =SUM(E13:E163) -> 0 | F10: =SUM(F13:F163) -> 0 | G10: =SUM(G13:G163) -> 0 | H10: =SUM(H13:H163) -> 0 | I10: =SUM(I13:I163) -> 0 | J10: =SUM(J13:J163) -> 0 | ... R10: =SUM(R13:R163) -> 0
J11: =SUM(J10+K10)/2 -> 0
A12: Day | B12: Date | C12: Survey | D12: Clear and Grub | E12: Grade the Site | F12: Unload, Haul & String | G12: Bending | H12: Welding | I12: Trenching | J12: Lower-In | K12: Backfill | L12: Machine Clean-Up | M12: Testing | N12: Final Clean-Up | O12: Coating
A13: 1 | B13: 42217
A14: 2 | B14: 42218
A15: 3 | B15: 42219
A16: 4 | B16: 42220
A17: 5 | B17: 42221
A18: 6 | B18: 42222
A19: 7 | B19: 42223
A20: 8 | B20: 42224
A21: 9 | B21: 42225
A22: 10 | B22: 42226
A23: 11 | B23: 42227
A24: 12 | B24: 42228
... A163: 151 | B163: 42367

Sheet Planned PROGRESS
A1: ='Actual PROGRESS'!A1 -> Superintendent | G1: Total ROW Meters | J1: 0 | AC1: 1
A2: ='Actual PROGRESS'!A2 -> 0 | C2: Project | G2: % Project PLANNED complete | J2: =SUM(D8+E8+F8+G8+H8+I8+J8+K8+L8+M8+N8)/11 -> #DIV/0!
A3: ='Actual PROGRESS'!A3 -> Contractor: Surerus | C3: PLANNED PROGRESS - As per Start Progress REV01, End Progress REV07
A4: ='Actual PROGRESS'!A4 -> 0 | G4: Meters of Pipe | I4: 88300
A5: Date | B5: ='Actual PROGRESS'!B5 -> 0
A7: % LEFT TO DO | C7: =100%-C8 -> #DIV/0! | D7: =100%-D8 -> #DIV/0! | E7: =100%-E8 -> #DIV/0! | F7: =100%-F8 -> #DIV/0! | G7: =100%-G8 -> #DIV/0! | H7: =100%-H8 -> #DIV/0! | I7: =100%-I8 -> #DIV/0! | J7: =100%-J8 -> #DIV/0! | ... R7: =100%-R8 -> #DIV/0!
A8: % COMPLETE TO DATE | C8: =+C10/$J1 -> #DIV/0! | D8: =+D10/$J1 -> #DIV/0! | E8: =+E10/$J1 -> #DIV/0! | F8: =+F10/$J1 -> #DIV/0! | G8: =+G10/$J1 -> #DIV/0! | H8: =+H10/$J1 -> #DIV/0! | I8: =+I10/$J1 -> #DIV/0! | J8: =+J10/$J1 -> #DIV/0! | ... R8: =+R10/$J1 -> #DIV/0!
A9: Remaining balance | C9: =+$J1-C10 -> 0 | D9: =+$J1-D10 -> 0 | E9: =+$J1-E10 -> 0 | F9: =+$J1-F10 -> 0 | G9: =+$J1-G10 -> 0 | H9: =+$J1-H10 -> 0 | I9: =+$J1-I10 -> 0 | J9: =+$J1-J10 -> 0 | ... R9: =+$J1-R10 -> 0
A10: Completed to Date (FIX DAILY FORMULA) | C10: =SUM(C13:C16) -> 0 | D10: =SUM(D13:D16) -> 0 | E10: =SUM(E13:E16) -> 0 | F10: =SUM(F13:F16) -> 0 | G10: =SUM(G13:G16) -> 0 | H10: =SUM(H13:H16) -> 0 | I10: =SUM(I13:I16) -> 0 | J10: =SUM(J13:J16) -> 0 | ... R10: =SUM(R13:R16) -> 0
J11: =SUM(J10+K10)/2 -> 0
A12: Day | B12: Date | C12: Survey | D12: Clear and Grub | E12: Grade | F12: Unload, Haul & String | G12: Bending | H12: Welding | I12: Trenching | J12: Lower-In | K12: Backfill | L12: Machine Clean-Up | M12: Testing | N12: Final Clean-Up
A13: 166 | B13: 41988
A14: 167 | B14: 41989
A15: 168 | B15: 41990
A16: 169 | B16: 41991
A17: 170 | B17: 41992
A18: 166 | B18: 42009
A19: 167 | B19: 42010
A20: 168 | B20: 42011
A21: 169 | B21: 42012
A22: 170 | B22: 42013
A23: 171 | B23: 42014
A24: 172 | B24: 42015
... A148: 296 | B148: 42139

Sheet SECTION 1a (BASELAY)
A1: Baselay
A3: 1a - Lay Price
G4: TODAY | H4: Amount of This Progress | J4: =I19 -> 0 | K4: Amount of This Progress | M4: =L19 -> 0 | N4: Amount of This Progress | P4: =O19 -> 0 | Q4: Amount of This Progress | S4: =R19 -> 0 | T4: Amount of This Progress | V4: =U19 -> 0 | W4: Amount of This Progress | Y4: =X19 -> 0 | Z4: Amount of This Progress | AB4: =AA19 -> 0 | AC4: Amount of This Progress | AE4: =AD19 -> 0 | AF4: Amount of This Progress | AH4: =AG19 -> 0 | AI4: Amount of This Progress | AK4: =AJ19 -> 0 | AL4: Amount of This Progress | AN4: =AM19 -> 0 | AO4: Amount of This Progress | AQ4: =AP19 -> 0 | AR4: Amount of This Progress | AT4: =AS19 -> 0 | AU4: Amount of This Progress | AW4: =AV19 -> 0 | AX4: Amount of This Progress | AZ4: =AY19 -> 0 | BA4: Amount of This Progress | BC4: =BB19 -> 0 | BD4: Amount of This Progress | BF4: =BE19 -> 0 | BG4: Amount of This Progress | BI4: =BH19 -> 0 | BK4: Mobilization Payment Reduction to Line Price
B5: # m | E5: Est Total cost | G5: =G19 -> 0
A6: 42" | C6: 0 | H6: Progress #1 billed January 28 | K6: Progress #2 billed FEB 4 | N6: Progress #3 billed FEB 11 | Q6: Progress #4 billed MAR 11 | T6: Progress #5 billed MAR 19 | W6: Progress #6 billed MAY 2 | Z6: Progress #7 billed JUNE 11 | AC6: Progress #9 billed JUNE 25 | AF6: Progress #11 billed JULY 9 | AI6: Progress #12 billed JULY 16 | AL6: Progress #13 billed JULY 23 | AO6: Progress #14 billed JULY 29 | AR6: Progress #15 billed AUG 6 | AU6: Progress #16 billed AUG 12 | AX6: Progress #17 billed AUG 19 | BA6: Progress #18 billed AUG 26 | BD6: Progress #19 billed SEP 3 | BG6: Progress #20 billed SEP 9 | BN6: Credit Amounts | BP6: Progress Billed
A7: Total Cost per Task | B7: PERCENT | C7: Cost Per Meter | D7: WORK ITEM | E7: Estimated % Complete | F7: Total Meters | G7: Estimated cost TO DATE | H7: Billing Quantity (m) Period ending Jan 27 | I7: Progress Billing #1 | J7: TOTAL AMOUNT INVOICED TO DATE | K7: Billing Quantity (m) Period ending FEB 3 | L7: Progress Billing #2 Invoice | M7: TOTAL AMOUNT INVOICED TO DATE | N7: Billing Quantity (m) Period ending FEB 10 | O7: Progress Billing #3 Invoice | P7: TOTAL AMOUNT INVOICED TO DATE | Q7: Billing Quantity (m) Period ending MAR 10 | R7: Progress Billing #4 Invoice | S7: TOTAL AMOUNT INVOICED TO DATE | T7: Billing Quantity (m) Period ending MAR 17 | U7: Progress Billing #5 Invoice | V7: TOTAL AMOUNT INVOICED TO DATE | W7: Billing Quantity (m) Period ending MAR 17 | X7: Progress Billing #6 Invoice | Y7: TOTAL AMOUNT INVOICED TO DATE | Z7: Billing Quantity (m) Period ending June 9 | AA7: Progress Billing #7 Invoice | AB7: TOTAL AMOUNT INVOICED TO DATE | AC7: Billing Quantity (m) Period ending JUNE 23 | AD7: Progress Billing #7 Invoice | AE7: TOTAL AMOUNT INVOICED TO DATE | AF7: Billing Quantity (m) Period ending JULY 7 | AG7: Progress Billing #11 Invoice | AH7: TOTAL AMOUNT INVOICED TO DATE | AI7: Billing Quantity (m) Period ending JULY 14 | AJ7: Progress Billing #12 Invoice | AK7: TOTAL AMOUNT INVOICED TO DATE | AL7: Billing Quantity (m) Period ending JULY 21 | AM7: Progress Billing #13 Invoice | AN7: TOTAL AMOUNT INVOICED TO DATE | AO7: Billing Quantity (m) Period ending JULY 28 | AP7: Progress Billing #14 Invoice | AQ7: TOTAL AMOUNT INVOICED TO DATE | AR7: Billing Quantity (m) Period ending AUG 4 | AS7: Progress Billing #15 Invoice | AT7: TOTAL AMOUNT INVOICED TO DATE | AU7: Billing Quantity (m) Period ending AUG 11 | AV7: Progress Billing #16 Invoice | AW7: TOTAL AMOUNT INVOICED TO DATE | AX7: Billing Quantity (m) Period ending AUG 18 | AY7: Progress Billing #17 Invoice | AZ7: TOTAL AMOUNT INVOICED TO DATE | BA7: Billing Quantity (m) Period ending AUG 25 | BB7: Progress Billing #18 Invoice | BC7: TOTAL AMOUNT INVOICED TO DATE | BD7: Billing Quantity (m) Period ending SEP 1 | BE7: Progress Billing #19 Invoice | BF7: TOTAL AMOUNT INVOICED TO DATE | BG7: Billing Quantity (m) Period ending SEP 8 | BH7: Progress Billing #20 | BI7: TOTAL AMOUNT INVOICED TO DATE | BJ7: BUDGET REMAINING | BK7: CREDIT (m) credit unit cost | BL7: CREDIT $ This Period (SEP 9 PP20) | BM7: CREDIT TO DATE $ (m to date x credit unit cost) | BN7: (m) Billed to date | BO7: (m) Remaining to be billed | BP7: (m) Billed to date | BQ7: (m) Remaining to be billed
A8: =$B$6*C8 -> 0 | B8: 0.05 | C8: =$C$6*B8 -> 0 | D8: Clearing and Grubbing | E8: ='Actual PROGRESS'!D8 -> 0 | F8: ='Actual PROGRESS'!D10 -> 0 | G8: =F8*C8 -> 0 | I8: =C8*H8 -> 0 | J8: =I8 -> 0 | L8: =C8*K8 -> 0 | M8: =I8+L8 -> 0 | O8: =C8*N8 -> 0 | P8: =L8+O8+I8 -> 0 | R8: =C8*Q8 -> 0 | S8: =I8+L8+O8+R8 -> 0 | U8: =T8*C8 -> 0 | V8: =U8+R8+O8+L8+I8 -> 0 | X8: =W8*C8 -> 0 | Y8: =I8+L8+O8+R8+U8+X8 -> 0 | AA8: =Z8*C8 -> 0 | AB8: =I8+L8+O8+R8+U8+X8+AA8 -> 0 | AD8: =AC8*C8 -> 0 | AE8: =I8+L8+O8+R8+U8+X8+AA8+AD8 -> 0 | AG8: =AF8*C8 -> 0 | AH8: =I8+L8+O8+R8+U8+X8+AA8+AD8+AG8 -> 0 | AI8: 0 | AJ8: =AI8*F8 -> 0 | AK8: =I8+L8+O8+R8+U8+X8+AA8+AD8+AG8+AJ8 -> 0 | AL8: 0 | AM8: =AL8*I8 -> 0 | AN8: =I8+L8+O8+R8+U8+X8+AA8+AD8+AG8+AJ8+AM8 -> 0 | AO8: 0 | AP8: =AO8*C8 -> 0 | AQ8: =I8+L8+O8+R8+U8+X8+AA8+AD8+AG8+AJ8+AM8+AP8 -> 0 | AR8: 0 | AS8: 0 | AT8: =I8+L8+O8+R8+U8+X8+AA8+AD8+AG8+AJ8+AM8+AP8+AS8 -> 0 | AU8: 0 | AV8: =AU8*C8 -> 0 | AW8: =I8+L8+O8+R8+U8+X8+AA8+AD8+AG8+AJ8+AM8+AP8+AS8+AV8 -> 0 | AX8: 0 | AY8: =AX8*F8 -> 0 | AZ8: =AW8 -> 0 | BA8: 0 | BB8: =BA8*I8 -> 0 | BC8: =AZ8 -> 0 | BD8: 0 | BE8: =BD8*C8 -> 0 | BF8: =BC8 -> 0 | BH8: =BG8*F8 -> 0 | BI8: =BF8 -> 0 | BJ8: =A8-I8-L8-O8-R8-U8-X8-AA8-AD8-AG8-AJ8-AM8-AP8-AS8-AV8-AY8-BB8-BE8-BH8 -> 0 | BL8: 0 | BM8: =BK8*BN8 -> 0 | BN8: =H8+K8+N8+Q8+T8+W8+Z8+AC8+AF8+AI8+AO8+AU8+AX8 -> 0 | BO8: =$BN$5-BN8 -> 0 | BP8: =BN8 -> 0 | BQ8: =B6-BP8 -> 0
A9: =$B$6*C9 -> 0 | B9: 0.1 | C9: =$C$6*B9 -> 0 | D9: Grade | E9: ='Actual PROGRESS'!E8 -> 0 | F9: ='Actual PROGRESS'!E10 -> 0 | G9: =F9*C9 -> 0 | H9: 0 | I9: =C9*H9 -> 0 | J9: =I9 -> 0 | K9: 0 | L9: =F9*K9 -> 0 | M9: =L9 -> 0 | N9: 0 | O9: =I9*N9 -> 0 | P9: =O9 -> 0 | Q9: 0 | R9: =L9*Q9 -> 0 | S9: =R9 -> 0 | T9: 0 | U9: =O9*T9 -> 0 | V9: =U9 -> 0 | W9: 0 | X9: =R9*W9 -> 0 | Y9: =X9 -> 0 | Z9: 0 | AA9: =U9*Z9 -> 0 | AB9: =AA9 -> 0 | AC9: 0 | AD9: =X9*AC9 -> 0 | AE9: =AD9 -> 0 | AF9: 0 | AG9: =AA9*AF9 -> 0 | AH9: =AG9 -> 0 | AJ9: =AI9*C9 -> 0 | AK9: =I9+L9+O9+R9+U9+X9+AA9+AD9+AG9+AJ9 -> 0 | AM9: =AL9*C9 -> 0 | AN9: =I9+L9+O9+R9+U9+X9+AA9+AD9+AG9+AJ9+AM9 -> 0 | AP9: =AO9*C9 -> 0 | AQ9: =I9+L9+O9+R9+U9+X9+AA9+AD9+AG9+AJ9+AM9+AP9 -> 0 | AS9: =AR9*C9 -> 0 | AT9: =I9+L9+O9+R9+U9+X9+AA9+AD9+AG9+AJ9+AM9+AP9+AS9 -> 0 | AV9: =AU9*C9 -> 0 | AW9: =I9+L9+O9+R9+U9+X9+AA9+AD9+AG9+AJ9+AM9+AP9+AS9+AV9 -> 0 | AY9: =AX9*C9 -> 0 | AZ9: =L9+O9+R9+U9+X9+AA9+AD9+AG9+AJ9+AM9+AP9+AS9+AV9+AY9 -> 0 | BB9: =BA9*C9 -> 0 | BC9: =O9+R9+U9+X9+AA9+AD9+AG9+AJ9+AM9+AP9+AS9+AV9+AY9+BB9 -> 0 | BE9: =BD9*C9 -> 0 | BF9: =R9+U9+X9+AA9+AD9+AG9+AJ9+AM9+AP9+AS9+AV9+AY9+BB9+BE9 -> 0 | BH9: =BG9*C9 -> 0 | BI9: =U9+X9+AA9+AD9+AG9+AJ9+AM9+AP9+AS9+AV9+AY9+BB9+BE9+BH9 -> 0 | BJ9: =A9-I9-L9-O9-R9-U9-X9-AA9-AD9-AG9-AJ9-AM9-AP9-AS9-AV9-AY9-BB9-BE9-BH9 -> 0 | BL9: =BK9*BG9 -> 0 | BM9: =BN9*BK9 -> 0 | BN9: =AO9+AR9+AU9+AX9+BA9+BD9+BG9 -> 0 | BO9: =$BN$5-BN9 -> 0 | BP9: =BN9 -> 0 | BQ9: =B6-BP9 -> 0
A10: =$B$6*C10 -> 0 | B10: 0.08 | C10: =$C$6*B10 -> 0 | D10: Unload, Haul and String | E10: ='Actual PROGRESS'!F8 -> 0 | F10: ='Actual PROGRESS'!F10 -> 0 | G10: =F10*C10 -> 0 | H10: 0 | I10: =C10*H10 -> 0 | J10: =I10 -> 0 | K10: 0 | L10: =F10*K10 -> 0 | M10: =L10 -> 0 | N10: 0 | O10: =I10*N10 -> 0 | P10: =O10 -> 0 | Q10: 0 | R10: =L10*Q10 -> 0 | S10: =R10 -> 0 | T10: 0 | U10: =O10*T10 -> 0 | V10: =U10 -> 0 | W10: 0 | X10: =R10*W10 -> 0 | Y10: =X10 -> 0 | Z10: 0 | AA10: =U10*Z10 -> 0 | AB10: =AA10 -> 0 | AC10: 0 | AD10: =X10*AC10 -> 0 | AE10: =AD10 -> 0 | AF10: 0 | AG10: =AA10*AF10 -> 0 | AH10: =AG10 -> 0 | AI10: 0 | AJ10: =AD10*AI10 -> 0 | AK10: =I10+L10+O10+R10+U10+X10+AA10+AD10+AG10+AJ10 -> 0 | AL10: 0 | AM10: =AG10*AL10 -> 0 | AN10: =I10+L10+O10+R10+U10+X10+AA10+AD10+AG10+AJ10+AM10 -> 0 | AP10: =AO10*C10 -> 0 | AQ10: =I10+L10+O10+R10+U10+X10+AA10+AD10+AG10+AJ10+AM10+AP10 -> 0 | AS10: =AR10*C10 -> 0 | AT10: =I10+L10+O10+R10+U10+X10+AA10+AD10+AG10+AJ10+AM10+AP10+AS10 -> 0 | AV10: =AU10*C10 -> 0 | AW10: =I10+L10+O10+R10+U10+X10+AA10+AD10+AG10+AJ10+AM10+AP10+AS10+AV10 -> 0 | AY10: =AX10*C10 -> 0 | AZ10: =L10+O10+R10+U10+X10+AA10+AD10+AG10+AJ10+AM10+AP10+AS10+AV10+AY10 -> 0 | BB10: =BA10*C10 -> 0 | BC10: =O10+R10+U10+X10+AA10+AD10+AG10+AJ10+AM10+AP10+AS10+AV10+AY10+BB10 -> 0 | BE10: =BD10*C10 -> 0 | BF10: =R10+U10+X10+AA10+AD10+AG10+AJ10+AM10+AP10+AS10+AV10+AY10+BB10+BE10 -> 0 | BH10: =BG10*C10 -> 0 | BI10: =U10+X10+AA10+AD10+AG10+AJ10+AM10+AP10+AS10+AV10+AY10+BB10+BE10+BH10 -> 0 | BJ10: =A10-I10-L10-O10-R10-U10-X10-AA10-AD10-AG10-AJ10-AM10-AP10-AS10-AV10-AY10-BB10-BE10-BH10 -> 0 | BL10: =BK10*BG10 -> 0 | BM10: =BN10*BK10 -> 0 | BN10: =AO10+AR10+AU10+AX10+BA10+BD10+BG10 -> 0 | BO10: =$BN$5-BN10 -> 0 | BP10: =BN10 -> 0 | BQ10: =B6-BP10 -> 0
A11: =$B$6*C11 -> 0 | B11: 0.05 | C11: =$C$6*B11 -> 0 | D11: Bending | E11: ='Actual PROGRESS'!G8 -> 0 | F11: ='Actual PROGRESS'!G10 -> 0 | G11: =F11*C11 -> 0 | H11: 0 | I11: =C11*H11 -> 0 | J11: =I11 -> 0 | K11: 0 | L11: =F11*K11 -> 0 | M11: =L11 -> 0 | N11: 0 | O11: =I11*N11 -> 0 | P11: =O11 -> 0 | Q11: 0 | R11: =L11*Q11 -> 0 | S11: =R11 -> 0 | T11: 0 | U11: =O11*T11 -> 0 | V11: =U11 -> 0 | W11: 0 | X11: =R11*W11 -> 0 | Y11: =X11 -> 0 | Z11: 0 | AA11: =U11*Z11 -> 0 | AB11: =AA11 -> 0 | AC11: 0 | AD11: =X11*AC11 -> 0 | AE11: =AD11 -> 0 | AF11: 0 | AG11: =AA11*AF11 -> 0 | AH11: =AG11 -> 0 | AI11: 0 | AJ11: =AD11*AI11 -> 0 | AK11: =I11+L11+O11+R11+U11+X11+AA11+AD11+AG11+AJ11 -> 0 | AL11: 0 | AM11: =AG11*AL11 -> 0 | AN11: =I11+L11+O11+R11+U11+X11+AA11+AD11+AG11+AJ11+AM11 -> 0 | AP11: =AO11*C11 -> 0 | AQ11: =I11+L11+O11+R11+U11+X11+AA11+AD11+AG11+AJ11+AM11+AP11 -> 0 | AS11: =AR11*C11 -> 0 | AT11: =I11+L11+O11+R11+U11+X11+AA11+AD11+AG11+AJ11+AM11+AP11+AS11 -> 0 | AV11: =AU11*C11 -> 0 | AW11: =I11+L11+O11+R11+U11+X11+AA11+AD11+AG11+AJ11+AM11+AP11+AS11+AV11 -> 0 | AY11: =AX11*C11 -> 0 | AZ11: =L11+O11+R11+U11+X11+AA11+AD11+AG11+AJ11+AM11+AP11+AS11+AV11+AY11 -> 0 | BB11: =BA11*C11 -> 0 | BC11: =O11+R11+U11+X11+AA11+AD11+AG11+AJ11+AM11+AP11+AS11+AV11+AY11+BB11 -> 0 | BE11: =BD11*C11 -> 0 | BF11: =R11+U11+X11+AA11+AD11+AG11+AJ11+AM11+AP11+AS11+AV11+AY11+BB11+BE11 -> 0 | BH11: =BG11*C11 -> 0 | BI11: =U11+X11+AA11+AD11+AG11+AJ11+AM11+AP11+AS11+AV11+AY11+BB11+BE11+BH11 -> 0 | BJ11: =A11-I11-L11-O11-R11-U11-X11-AA11-AD11-AG11-AJ11-AM11-AP11-AS11-AV11-AY11-BB11-BE11-BH11 -> 0 | BL11: =BK11*BG11 -> 0 | BM11: =BK11*BN11 -> 0 | BN11: =AO11+AR11+AU11+AX11+BA11+BD11+BG11 -> 0 | BO11: =$BN$5-BN11 -> 0 | BP11: =BN11 -> 0 | BQ11: =B6-BP11 -> 0
A12: =$B$6*C12 -> 0 | B12: 0.2 | C12: =$C$6*B12 -> 0 | D12: Welding | E12: ='Actual PROGRESS'!H8 -> 0 | F12: ='Actual PROGRESS'!H10 -> 0 | G12: =F12*C12 -> 0 | H12: 0 | I12: =C12*H12 -> 0 | J12: =I12 -> 0 | K12: 0 | L12: =F12*K12 -> 0 | M12: =L12 -> 0 | N12: 0 | O12: =I12*N12 -> 0 | P12: =O12 -> 0 | Q12: 0 | R12: =L12*Q12 -> 0 | S12: =R12 -> 0 | T12: 0 | U12: =O12*T12 -> 0 | V12: =U12 -> 0 | W12: 0 | X12: =R12*W12 -> 0 | Y12: =X12 -> 0 | Z12: 0 | AA12: =U12*Z12 -> 0 | AB12: =AA12 -> 0 | AC12: 0 | AD12: =X12*AC12 -> 0 | AE12: =AD12 -> 0 | AF12: 0 | AG12: =AA12*AF12 -> 0 | AH12: =AG12 -> 0 | AI12: 0 | AJ12: =AD12*AI12 -> 0 | AK12: =I12+L12+O12+R12+U12+X12+AA12+AD12+AG12+AJ12 -> 0 | AL12: 0 | AM12: =AG12*AL12 -> 0 | AN12: =I12+L12+O12+R12+U12+X12+AA12+AD12+AG12+AJ12+AM12 -> 0 | AO12: 0 | AP12: =AO12*C12 -> 0 | AQ12: =I12+L12+O12+R12+U12+X12+AA12+AD12+AG12+AJ12+AM12+AP12 -> 0 | AR12: 0 | AS12: =AR12*C12 -> 0 | AT12: =I12+L12+O12+R12+U12+X12+AA12+AD12+AG12+AJ12+AM12+AP12+AS12 -> 0 | AV12: =AU12*C12 -> 0 | AW12: =I12+L12+O12+R12+U12+X12+AA12+AD12+AG12+AJ12+AM12+AP12+AS12+AV12 -> 0 | AY12: =AX12*C12 -> 0 | AZ12: =L12+O12+R12+U12+X12+AA12+AD12+AG12+AJ12+AM12+AP12+AS12+AV12+AY12 -> 0 | BB12: =BA12*C12 -> 0 | BC12: =O12+R12+U12+X12+AA12+AD12+AG12+AJ12+AM12+AP12+AS12+AV12+AY12+BB12 -> 0 | BE12: =BD12*C12 -> 0 | BF12: =R12+U12+X12+AA12+AD12+AG12+AJ12+AM12+AP12+AS12+AV12+AY12+BB12+BE12 -> 0 | BH12: =BG12*C12 -> 0 | BI12: =U12+X12+AA12+AD12+AG12+AJ12+AM12+AP12+AS12+AV12+AY12+BB12+BE12+BH12 -> 0 | BJ12: =A12-I12-L12-O12-R12-U12-X12-AA12-AD12-AG12-AJ12-AM12-AP12-AS12-AV12-AY12-BB12-BE12-BH12 -> 0 | BL12: =BK12*BG12 -> 0 | BM12: =BK12*BN12 -> 0 | BN12: =AO12+AR12+AU12+AX12+BA12+BD12+BG12 -> 0 | BO12: =$BN$5-BN12 -> 0 | BP12: =BN12 -> 0 | BQ12: =$B$6-BP12 -> 0
A13: =$B$6*C13 -> 0 | B13: 0.1 | C13: =$C$6*B13 -> 0 | D13: Coating | F13: ='Actual PROGRESS'!H11 -> 0 | G13: =F13*C13 -> 0 | H13: 1 | I13: =C13*H13 -> 0 | J13: =I13 -> 0 | K13: 1 | L13: =F13*K13 -> 0 | M13: =L13 -> 0 | N13: 1 | O13: =I13*N13 -> 0 | P13: =O13 -> 0 | Q13: 1 | R13: =L13*Q13 -> 0 | S13: =R13 -> 0 | T13: 1 | U13: =O13*T13 -> 0 | V13: =U13 -> 0 | W13: 1 | X13: =R13*W13 -> 0 | Y13: =X13 -> 0 | Z13: 1 | AA13: =U13*Z13 -> 0 | AB13: =AA13 -> 0 | AC13: 1 | AD13: =X13*AC13 -> 0 | AE13: =AD13 -> 0 | AF13: 1 | AG13: =AA13*AF13 -> 0 | AH13: =AG13 -> 0 | AI13: 1 | AJ13: =AD13*AI13 -> 0 | AK13: =I13+L13+O13+R13+U13+X13+AA13+AD13+AG13+AJ13 -> 0 | AL13: 1 | AM13: =AG13*AL13 -> 0 | AN13: =I13+L13+O13+R13+U13+X13+AA13+AD13+AG13+AJ13+AM13 -> 0 | AO13: 1 | AP13: =AO13*C13 -> 0 | AQ13: =I13+L13+O13+R13+U13+X13+AA13+AD13+AG13+AJ13+AM13+AP13 -> 0 | AR13: 1 | AS13: =AR13*C13 -> 0 | AT13: =I13+L13+O13+R13+U13+X13+AA13+AD13+AG13+AJ13+AM13+AP13+AS13 -> 0 | AV13: =AU13*C13 -> 0 | AW13: =I13+L13+O13+R13+U13+X13+AA13+AD13+AG13+AJ13+AM13+AP13+AS13+AV13 -> 0 | AY13: =AX13*C13 -> 0 | AZ13: =L13+O13+R13+U13+X13+AA13+AD13+AG13+AJ13+AM13+AP13+AS13+AV13+AY13 -> 0 | BB13: =BA13*C13 -> 0 | BC13: =O13+R13+U13+X13+AA13+AD13+AG13+AJ13+AM13+AP13+AS13+AV13+AY13+BB13 -> 0 | BE13: =BD13*C13 -> 0 | BF13: =R13+U13+X13+AA13+AD13+AG13+AJ13+AM13+AP13+AS13+AV13+AY13+BB13+BE13 -> 0 | BH13: =BG13*C13 -> 0 | BI13: =U13+X13+AA13+AD13+AG13+AJ13+AM13+AP13+AS13+AV13+AY13+BB13+BE13+BH13 -> 0 | BJ13: =A13-I13-L13-O13-R13-U13-X13-AA13-AD13-AG13-AJ13-AM13-AP13-AS13-AV13-AY13-BB13-BE13-BH13 -> 0 | BL13: =BK13*BG13 -> 0 | BM13: =BK13*BN13 -> 0 | BN13: =AO13+AR13+AU13+AX13+BA13+BD13+BG13 -> 2 | BO13: =$BN$5-BN13 -> -2 | BP13: =BN13 -> 2 | BQ13: =$B$6-BP13 -> -2
A14: =$B$6*C14 -> 0 | B14: 0.12 | C14: =$C$6*B14 -> 0 | D14: Trenching | E14: ='Actual PROGRESS'!I8 -> 0 | F14: ='Actual PROGRESS'!I10 -> 0 | G14: =F14*C14 -> 0 | H14: 0 | I14: =C14*H14 -> 0 | J14: =I14 -> 0 | K14: 0 | L14: =F14*K14 -> 0 | M14: =L14 -> 0 | N14: 0 | O14: =I14*N14 -> 0 | P14: =O14 -> 0 | Q14: 0 | R14: =L14*Q14 -> 0 | S14: =R14 -> 0 | T14: 0 | U14: =O14*T14 -> 0 | V14: =U14 -> 0 | W14: 0 | X14: =R14*W14 -> 0 | Y14: =X14 -> 0 | Z14: 0 | AA14: =U14*Z14 -> 0 | AB14: =AA14 -> 0 | AC14: 0 | AD14: =X14*AC14 -> 0 | AE14: =AD14 -> 0 | AF14: 0 | AG14: =AA14*AF14 -> 0 | AH14: =AG14 -> 0 | AI14: 0 | AJ14: =AD14*AI14 -> 0 | AK14: =I14+L14+O14+R14+U14+X14+AA14+AD14+AG14+AJ14 -> 0 | AL14: 0 | AM14: =AG14*AL14 -> 0 | AN14: =I14+L14+O14+R14+U14+X14+AA14+AD14+AG14+AJ14+AM14 -> 0 | AO14: 0 | AP14: =AO14*C14 -> 0 | AQ14: =I14+L14+O14+R14+U14+X14+AA14+AD14+AG14+AJ14+AM14+AP14 -> 0 | AR14: 0 | AS14: 0 | AT14: =I14+L14+O14+R14+U14+X14+AA14+AD14+AG14+AJ14+AM14+AP14+AS14 -> 0 | AU14: 0 | AV14: =AU14*C14 -> 0 | AW14: =I14+L14+O14+R14+U14+X14+AA14+AD14+AG14+AJ14+AM14+AP14+AS14+AV14 -> 0 | AY14: =AX14*C14 -> 0 | AZ14: =L14+O14+R14+U14+X14+AA14+AD14+AG14+AJ14+AM14+AP14+AS14+AV14+AY14 -> 0 | BB14: =BA14*C14 -> 0 | BC14: =O14+R14+U14+X14+AA14+AD14+AG14+AJ14+AM14+AP14+AS14+AV14+AY14+BB14 -> 0 | BE14: =BD14*C14 -> 0 | BF14: =R14+U14+X14+AA14+AD14+AG14+AJ14+AM14+AP14+AS14+AV14+AY14+BB14+BE14 -> 0 | BH14: =BG14*C14 -> 0 | BI14: =U14+X14+AA14+AD14+AG14+AJ14+AM14+AP14+AS14+AV14+AY14+BB14+BE14+BH14 -> 0 | BJ14: =A14-I14-L14-O14-R14-U14-X14-AA14-AD14-AG14-AJ14-AM14-AP14-AS14-AV14-AY14-BB14-BE14-BH14 -> 0 | BL14: =BK14*BG14 -> 0 | BM14: =BK14*BN14 -> 0 | BN14: =AO14+AR14+AU14+AX14+BA14+BD14+BG14 -> 0 | BO14: =$BN$5-BN14 -> 0 | BP14: =BN14 -> 0 | BQ14: =$B$6-BP14 -> 0
A15: =$B$6*C15 -> 0 | B15: 0.15 | C15: =$C$6*B15 -> 0 | D15: Lower in and Backfill | E15: =SUM('Actual PROGRESS'!J8+'Actual PROGRESS'!K8)/2 -> 0 | F15: =SUM('Actual PROGRESS'!J10+'Actual PROGRESS'!K10)/2 -> 0 | G15: =F15*C15 -> 0 | H15: 0 | I15: =C15*H15 -> 0 | J15: =I15 -> 0 | K15: 0 | L15: =F15*K15 -> 0 | M15: =L15 -> 0 | N15: 0 | O15: =I15*N15 -> 0 | P15: =O15 -> 0 | Q15: 0 | R15: =L15*Q15 -> 0 | S15: =R15 -> 0 | T15: 0 | U15: =O15*T15 -> 0 | V15: =U15 -> 0 | W15: 0 | X15: =R15*W15 -> 0 | Y15: =X15 -> 0 | Z15: 0 | AA15: =U15*Z15 -> 0 | AB15: =AA15 -> 0 | AC15: 0 | AD15: =X15*AC15 -> 0 | AE15: =AD15 -> 0 | AF15: 0 | AG15: =AA15*AF15 -> 0 | AH15: =AG15 -> 0 | AI15: 0 | AJ15: =AD15*AI15 -> 0 | AK15: =I15+L15+O15+R15+U15+X15+AA15+AD15+AG15+AJ15 -> 0 | AL15: 0 | AM15: =AG15*AL15 -> 0 | AN15: =I15+L15+O15+R15+U15+X15+AA15+AD15+AG15+AJ15+AM15 -> 0 | AO15: 0 | AP15: =AO15*C15 -> 0 | AQ15: =I15+L15+O15+R15+U15+X15+AA15+AD15+AG15+AJ15+AM15+AP15 -> 0 | AR15: 0 | AS15: 0 | AT15: =I15+L15+O15+R15+U15+X15+AA15+AD15+AG15+AJ15+AM15+AP15+AS15 -> 0 | AU15: 0 | AV15: =AU15*C15 -> 0 | AW15: =I15+L15+O15+R15+U15+X15+AA15+AD15+AG15+AJ15+AM15+AP15+AS15+AV15 -> 0 | AY15: =AX15*C15 -> 0 | AZ15: =L15+O15+R15+U15+X15+AA15+AD15+AG15+AJ15+AM15+AP15+AS15+AV15+AY15 -> 0 | BB15: =BA15*C15 -> 0 | BC15: =O15+R15+U15+X15+AA15+AD15+AG15+AJ15+AM15+AP15+AS15+AV15+AY15+BB15 -> 0 | BE15: =BD15*C15 -> 0 | BF15: =R15+U15+X15+AA15+AD15+AG15+AJ15+AM15+AP15+AS15+AV15+AY15+BB15+BE15 -> 0 | BH15: =BG15*C15 -> 0 | BI15: =U15+X15+AA15+AD15+AG15+AJ15+AM15+AP15+AS15+AV15+AY15+BB15+BE15+BH15 -> 0 | BJ15: =A15-I15-L15-O15-R15-U15-X15-AA15-AD15-AG15-AJ15-AM15-AP15-AS15-AV15-AY15-BB15-BE15-BH15 -> 0 | BL15: =BK15*BG15 -> 0 | BM15: =BK15*BN15 -> 0 | BN15: =AO15+AR15+AU15+AX15+BA15+BD15+BG15 -> 0 | BO15: =$BN$5-BN15 -> 0 | BP15: =BN15 -> 0 | BQ15: =$B$6-BP15 -> 0
A16: =$B$6*C16 -> 0 | B16: 0.05 | C16: =$C$6*B16 -> 0 | D16: Machine Clean Up | E16: ='Actual PROGRESS'!L8 -> 0 | F16: ='Actual PROGRESS'!L10 -> 0 | G16: =F16*C16 -> 0 | H16: 0 | I16: =C16*H16 -> 0 | J16: =I16 -> 0 | K16: 0 | L16: =F16*K16 -> 0 | M16: =L16 -> 0 | N16: 0 | O16: =I16*N16 -> 0 | P16: =O16 -> 0 | Q16: 0 | R16: =L16*Q16 -> 0 | S16: =R16 -> 0 | T16: 0 | U16: =O16*T16 -> 0 | V16: =U16 -> 0 | W16: 0 | X16: =R16*W16 -> 0 | Y16: =X16 -> 0 | Z16: 0 | AA16: =U16*Z16 -> 0 | AB16: =AA16 -> 0 | AC16: 0 | AD16: =X16*AC16 -> 0 | AE16: =AD16 -> 0 | AF16: 0 | AG16: =AA16*AF16 -> 0 | AH16: =AG16 -> 0 | AI16: 0 | AJ16: =AD16*AI16 -> 0 | AK16: =I16+L16+O16+R16+U16+X16+AA16+AD16+AG16+AJ16 -> 0 | AL16: 0 | AM16: =AG16*AL16 -> 0 | AN16: =I16+L16+O16+R16+U16+X16+AA16+AD16+AG16+AJ16+AM16 -> 0 | AO16: 0 | AP16: =AO16*C16 -> 0 | AQ16: =I16+L16+O16+R16+U16+X16+AA16+AD16+AG16+AJ16+AM16+AP16 -> 0 | AR16: 0 | AS16: 0 | AT16: =I16+L16+O16+R16+U16+X16+AA16+AD16+AG16+AJ16+AM16+AP16+AS16 -> 0 | AU16: 0 | AV16: =AU16*C16 -> 0 | AW16: =I16+L16+O16+R16+U16+X16+AA16+AD16+AG16+AJ16+AM16+AP16+AS16+AV16 -> 0 | AX16: 0 | AY16: =AX16*F16 -> 0 | AZ16: =L16+O16+R16+U16+X16+AA16+AD16+AG16+AJ16+AM16+AP16+AS16+AV16+AY16 -> 0 | BA16: 0 | BB16: =BA16*I16 -> 0 | BC16: =O16+R16+U16+X16+AA16+AD16+AG16+AJ16+AM16+AP16+AS16+AV16+AY16+BB16 -> 0 | BE16: =BD16*C16 -> 0 | BF16: =R16+U16+X16+AA16+AD16+AG16+AJ16+AM16+AP16+AS16+AV16+AY16+BB16+BE16 -> 0 | BH16: =BG16*F16 -> 0 | BI16: =U16+X16+AA16+AD16+AG16+AJ16+AM16+AP16+AS16+AV16+AY16+BB16+BE16+BH16 -> 0 | BJ16: =A16-I16-L16-O16-R16-U16-X16-AA16-AD16-AG16-AJ16-AM16-AP16-AS16-AV16-AY16-BB16-BE16-BH16 -> 0 | BL16: =BK16*BG16 -> 0 | BM16: =BK16*BN16 -> 0 | BN16: =AO16+AR16+AU16+AX16+BA16+BD16+BG16 -> 0 | BO16: =$BN$5-BN16 -> 0 | BP16: =BN16 -> 0 | BQ16: =$B$6-BP16 -> 0
A17: =$B$6*C17 -> 0 | B17: 0.07 | C17: =$C$6*B17 -> 0 | D17: Hydrostatic Testing | E17: ='Actual PROGRESS'!D16 -> 0 | F17: ='Actual PROGRESS'!M10 -> 0 | G17: =F17*C17 -> 0 | H17: 0 | I17: =C17*H17 -> 0 | J17: =I17 -> 0 | K17: 0 | L17: =F17*K17 -> 0 | M17: =L17 -> 0 | N17: 0 | O17: =I17*N17 -> 0 | P17: =O17 -> 0 | Q17: 0 | R17: =L17*Q17 -> 0 | S17: =R17 -> 0 | T17: 0 | U17: =O17*T17 -> 0 | V17: =U17 -> 0 | W17: 0 | X17: =R17*W17 -> 0 | Y17: =X17 -> 0 | Z17: 0 | AA17: =U17*Z17 -> 0 | AB17: =AA17 -> 0 | AC17: 0 | AD17: =X17*AC17 -> 0 | AE17: =AD17 -> 0 | AF17: 0 | AG17: =AA17*AF17 -> 0 | AH17: =AG17 -> 0 | AI17: 0 | AJ17: =AD17*AI17 -> 0 | AK17: =I17+L17+O17+R17+U17+X17+AA17+AD17+AG17+AJ17 -> 0 | AL17: 0 | AM17: =AG17*AL17 -> 0 | AN17: =I17+L17+O17+R17+U17+X17+AA17+AD17+AG17+AJ17+AM17 -> 0 | AO17: 0 | AP17: =AO17*C17 -> 0 | AQ17: =I17+L17+O17+R17+U17+X17+AA17+AD17+AG17+AJ17+AM17+AP17 -> 0 | AR17: 0 | AS17: 0 | AT17: =I17+L17+O17+R17+U17+X17+AA17+AD17+AG17+AJ17+AM17+AP17+AS17 -> 0 | AU17: 0 | AV17: =AU17*C17 -> 0 | AW17: =I17+L17+O17+R17+U17+X17+AA17+AD17+AG17+AJ17+AM17+AP17+AS17+AV17 -> 0 | AX17: 0 | AY17: =AX17*F17 -> 0 | AZ17: =L17+O17+R17+U17+X17+AA17+AD17+AG17+AJ17+AM17+AP17+AS17+AV17+AY17 -> 0 | BA17: 0 | BB17: =BA17*I17 -> 0 | BC17: =O17+R17+U17+X17+AA17+AD17+AG17+AJ17+AM17+AP17+AS17+AV17+AY17+BB17 -> 0 | BE17: =BD17*C17 -> 0 | BF17: =R17+U17+X17+AA17+AD17+AG17+AJ17+AM17+AP17+AS17+AV17+AY17+BB17+BE17 -> 0 | BH17: =BG17*F17 -> 0 | BI17: =U17+X17+AA17+AD17+AG17+AJ17+AM17+AP17+AS17+AV17+AY17+BB17+BE17+BH17 -> 0 | BJ17: =A17-I17-L17-O17-R17-U17-X17-AA17-AD17-AG17-AJ17-AM17-AP17-AS17-AV17-AY17-BB17-BE17-BH17 -> 0 | BL17: =BK17*BG17 -> 0 | BM17: =BK17*BN17 -> 0 | BN17: =AO17+AR17+AU17+AX17+BA17+BD17+BG17 -> 0 | BO17: =$BN$5-BN17 -> 0 | BP17: =BN17 -> 0 | BQ17: =$B$6-BP17 -> 0
A18: =$B$6*C18 -> 0 | B18: 0.03 | C18: =$C$6*B18 -> 0 | D18: Final Clean Up | E18: ='Actual PROGRESS'!D17 -> 0 | F18: ='Actual PROGRESS'!N10 -> 0 | G18: =F18*C18 -> 0 | H18: 0 | I18: =C18*H18 -> 0 | J18: =I18 -> 0 | K18: 0 | L18: =F18*K18 -> 0 | M18: =L18 -> 0 | N18: 0 | O18: =I18*N18 -> 0 | P18: =O18 -> 0 | Q18: 0 | R18: =L18*Q18 -> 0 | S18: =R18 -> 0 | T18: 0 | U18: =O18*T18 -> 0 | V18: =U18 -> 0 | W18: 0 | X18: =R18*W18 -> 0 | Y18: =X18 -> 0 | Z18: 0 | AA18: =U18*Z18 -> 0 | AB18: =AA18 -> 0 | AC18: 0 | AD18: =X18*AC18 -> 0 | AE18: =AD18 -> 0 | AF18: 0 | AG18: =AA18*AF18 -> 0 | AH18: =AG18 -> 0 | AI18: 0 | AJ18: =AD18*AI18 -> 0 | AK18: =I18+L18+O18+R18+U18+X18+AA18+AD18+AG18+AJ18 -> 0 | AL18: 0 | AM18: =AG18*AL18 -> 0 | AN18: =I18+L18+O18+R18+U18+X18+AA18+AD18+AG18+AJ18+AM18 -> 0 | AO18: 0 | AP18: =AO18*C18 -> 0 | AQ18: =I18+L18+O18+R18+U18+X18+AA18+AD18+AG18+AJ18+AM18+AP18 -> 0 | AR18: 0 | AS18: 0 | AT18: =I18+L18+O18+R18+U18+X18+AA18+AD18+AG18+AJ18+AM18+AP18+AS18 -> 0 | AU18: 0 | AV18: =AU18*C18 -> 0 | AW18: =I18+L18+O18+R18+U18+X18+AA18+AD18+AG18+AJ18+AM18+AP18+AS18+AV18 -> 0 | AX18: 0 | AY18: =AX18*F18 -> 0 | AZ18: =L18+O18+R18+U18+X18+AA18+AD18+AG18+AJ18+AM18+AP18+AS18+AV18+AY18 -> 0 | BA18: 0 | BB18: =BA18*I18 -> 0 | BC18: =O18+R18+U18+X18+AA18+AD18+AG18+AJ18+AM18+AP18+AS18+AV18+AY18+BB18 -> 0 | BE18: =BD18*C18 -> 0 | BF18: =R18+U18+X18+AA18+AD18+AG18+AJ18+AM18+AP18+AS18+AV18+AY18+BB18+BE18 -> 0 | BH18: =BG18*F18 -> 0 | BI18: =U18+X18+AA18+AD18+AG18+AJ18+AM18+AP18+AS18+AV18+AY18+BB18+BE18+BH18 -> 0 | BJ18: =A18-I18-L18-O18-R18-U18-X18-AA18-AD18-AG18-AJ18-AM18-AP18-AS18-AV18-AY18-BB18-BE18-BH18 -> 0 | BL18: =BK18*BG18 -> 0 | BM18: =BK18*BN18 -> 0 | BN18: =AO18+AR18+AU18+AX18+BA18+BD18+BG18 -> 0 | BO18: =$BN$5-BN18 -> 0 | BP18: =BN18 -> 0 | BQ18: =$B$6-BP18 -> 0
A19: =SUM(A8:A18) -> 0 | B19: =SUM(B8:B18) -> 1 | C19: =SUM(C8:C18) -> 0 | D19: TOTALS | G19: =SUM(G8:G18) -> 0 | I19: =SUM(I8:I18) -> 0 | J19: =SUM(J8:J18) -> 0 | L19: =SUM(L8:L18) -> 0 | M19: =SUM(M8:M18) -> 0 | O19: =SUM(O8:O18) -> 0 | P19: =SUM(P8:P18) -> 0 | R19: =SUM(R8:R18) -> 0 | S19: =SUM(S8:S18) -> 0 | U19: =SUM(U8:U18) -> 0 | V19: =SUM(V8:V18) -> 0 | X19: =SUM(X8:X18) -> 0 | Y19: =SUM(Y8:Y18) -> 0 | AA19: =SUM(AA8:AA18) -> 0 | AB19: =SUM(AB8:AB18) -> 0 | AD19: =SUM(AD8:AD18) -> 0 | AE19: =SUM(AE8:AE18) -> 0 | AG19: =SUM(AG8:AG18) -> 0 | AH19: =SUM(AH8:AH18) -> 0 | AJ19: =SUM(AJ8:AJ18) -> 0 | AK19: =SUM(AK8:AK18) -> 0 | AM19: =SUM(AM8:AM18) -> 0 | AN19: =SUM(AN8:AN18) -> 0 | AP19: =SUM(AP8:AP18) -> 0 | AQ19: =SUM(AQ8:AQ18) -> 0 | AS19: =SUM(AS8:AS18) -> 0 | AT19: =SUM(AT8:AT18) -> 0 | AV19: =SUM(AV8:AV18) -> 0 | AW19: =SUM(AW8:AW18) -> 0 | AY19: =SUM(AY8:AY18) -> 0 | AZ19: =SUM(AZ8:AZ18) -> 0 | BB19: =SUM(BB8:BB18) -> 0 | BC19: =SUM(BC8:BC18) -> 0 | BE19: =SUM(BE8:BE18) -> 0 | BF19: =SUM(BF8:BF18) -> 0 | BH19: =SUM(BH8:BH18) -> 0 | BI19: =SUM(BI8:BI18) -> 0 | BJ19: =SUM(BJ8:BJ18) -> 0 | BK19: =SUM(BK8:BK18) -> 0 | BL19: =SUM(BL8:BL18) -> 0 | BM19: =SUM(BM8:BM18) -> 0

Sheet SECTION 1b (LUMP SUM PRICING)
B1: Part A - Compensation for the Work | C1: Unit | D1: Unit Price | E1: Estimated Qty | F1: Extended Cost | G1: Est m To Date | H1: =H21 -> 0 | I1: =I21 -> 0 | K1: Inv Cost to Date | M1: =M21 -> 0
B2: Section 1b - SCHEDULE C | I2: Total | O2: See Log
A3: ITEM # | B3: Description | G3: Est M Complete | H3: Est Cost Complete | I3: LUMP SUM PRICE | J3: Field Ticket # | K3: Invoice # | L3: DATE ISSUED | M3: AMOUNT | N3: TOTAL COSTS INCURRED TO DATE | O3: Hold Back
A4: 1b | B4: Lump Sum Pricing
A5: i) | B5: Subsistence and/or camp | C5: LS | H5: =F5 -> 0 | I5: =H5 -> 0 | O5: =N5*10% -> 0
H6: =F6 -> 0 | I6: =H6 -> 0
H7: =F7 -> 0 | I7: =H7 -> 0
A8: ii) | B8: Mainline Block Valve | C8: LS | O8: =N8*10% -> 0
A9: iii) | B9: HDD Crossing and Support | C9: LS | O9: =N9*10% -> 0
A13: iv) | B13: Launcher / Receiver | C13: LS
A14: v) | B14: Open Cut Contingency to Redwater River | C14: LS
A15: vi) | B15: Open Cut Contingency to Piche River | C15: LS | O15: =N15*10% -> 0
O16: =N16*10% -> 0
O17: =N17*10% -> 0
O18: =N18*10% -> 0
C21: TOTAL | H21: =SUM(H4:H19) -> 0 | M21: =SUM(M5:M20) -> 0 | N21: =SUM(N5:N20) -> 0 | O21: =SUM(O5:O20) -> 0

Sheet SECTION 3 (Additional UPI)
C1: Unit | D1: Unit Price | E1: Estimated Qty | F1: Extended Cost | G1: Actual Qty | H1: Est m To Date | I1: =I196 -> 9824037 | J1: =O196 -> 9816245 | K1: Inv Cost to Date | N1: =N196 -> 9816245
B2: Section 3 - Scope of Work - Additional Unit Prices | J2: Total | P2: See Log
A3: ITEM # | B3: Description | H3: Est M Complete | I3: Est Cost Complete | J3: LUMP SUM PRICE (Possibly multiple costs) | K3: Field Ticket # (Possibly multiple ticket #'s) | L3: Invoice # (Possibly multiple invoice #'s) | M3: DATE ISSUED | N3: AMOUNT | O3: TOTAL COSTS INCURRED TO DATE | P3: Hold Back
A4: 3
A5: 3.1 | B5: Pit Run, off site | C5: CUBIC METERS | D5: 55.9 | F5: =E5*D5 -> 0 | G5: 0 | H5: =E5 -> 0 | I5: =F5 -> 0 | J5: =(G5*D5) -> 0 | N5: =F5 -> 0 | O5: =N5 -> 0 | P5: =O5*10% -> 0
A6: 3.2 | B6: Road Crush, off site | C6: CUBIC METERS | D6: 60 | E6: 450 | F6: =E6*D6 -> 27000 | H6: =E6 -> 450 | I6: =F6 -> 27000 | J6: =(G6*D6) -> 0 | N6: =F6 -> 27000 | O6: =N6 -> 27000 | P6: =O6*10% -> 2700
A7: 3.3 | B7: 3/4" Washed Gravel, off site | C7: CUBIC METERS | D7: 62.5 | F7: =E7*D7 -> 0 | H7: =E7 -> 0 | I7: =F7 -> 0 | J7: =(G7*D7) -> 0 | N7: =F7 -> 0 | O7: =N7 -> 0 | P7: =O7*10% -> 0
A8: 3.4 | B8: Native, onsite | C8: CUBIC METERS | D8: 13.5 | J8: =(G8*D8) -> 0
A9: 3.5 | B9: Rock excavation/ disposal | C9: CUBIC METERS | D9: 495 | E9: 953 | F9: =E9*D9 -> 471735 | H9: =E9 -> 953 | I9: =F9 -> 471735 | J9: =(G9*D9) -> 0 | N9: =F9 -> 471735 | O9: =N9 -> 471735 | P9: =O9*10% -> 47173.5
A10: 3.6 | B10: 3 Barbed and Wood Posts | C10: METER | D10: 30.75 | E10: 1000 | F10: =E10*D10 -> 30750 | H10: =E10 -> 1000 | I10: =F10 -> 30750 | J10: =(G10*D10) -> 0 | N10: =F10 -> 30750 | O10: =N10 -> 30750 | P10: =O10*10% -> 3075
A11: 3.7 | B11: 1.8m High Chain Link | C11: METER | J11: =(G11*D11) -> 0
A12: 3.8 | B12: Man-gate within chain link fence | C12: EACH | D12: 1500 | F12: =E12*D12 -> 0 | H12: =E12 -> 0 | I12: =F12 -> 0 | J12: =(G12*D12) -> 0 | N12: =F12 -> 0 | O12: =N12 -> 0 | P12: =O12*10% -> 0
A13: 3.9 | B13: Double Wide vehicle gate withink chain link fence | C13: EACH | D13: 2700 | F13: =E13*D13 -> 0 | H13: =E13 -> 0 | I13: =F13 -> 0 | J13: =(G13*D13) -> 0 | N13: =F13 -> 0 | O13: =N13 -> 0 | P13: =O13*10% -> 0
A14: 3.1 | B14: Temp fencing - snow | C14: METER | D14: 14.5 | E14: 5000 | F14: =E14*D14 -> 72500 | H14: =E14 -> 5000 | I14: =F14 -> 72500 | J14: =(G14*D14) -> 0 | N14: =F14 -> 72500 | O14: =N14 -> 72500 | P14: =O14*10% -> 7250
A15: 3.11 | B15: Trenching 0< or = 0.3m - Extra Depth | C15: METER | D15: 9 | E15: 1000 | F15: =E15*D15 -> 9000 | H15: =E15 -> 1000 | I15: =F15 -> 9000 | J15: =(G15*D15) -> 0 | N15: =F15 -> 9000 | O15: =N15 -> 9000 | P15: =O15*10% -> 900
A16: 3.12 | B16: Trenching 0.3< or 0.6m - Extra Depth | C16: METER | D16: 16 | E16: 500 | F16: =E16*D16 -> 8000 | H16: =E16 -> 500 | I16: =F16 -> 8000 | J16: =(G16*D16) -> 0 | N16: =F16 -> 8000 | O16: =N16 -> 8000 | P16: =O16*10% -> 800
A17: 3.13 | B17: Trenching > 0.6m - Extra Depth | C17: METER | D17: 21.5 | E17: 800 | F17: =E17*D17 -> 17200 | H17: =E17 -> 800 | I17: =F17 -> 17200 | J17: =(G17*D17) -> 0 | N17: =F17 -> 17200 | O17: =N17 -> 17200 | P17: =O17*10% -> 1720
A18: 3.14 | B18: Geotextile Felt | C18: CUBIC METERS | D18: 16.5 | E18: 9750 | F18: =E18*D18 -> 160875 | H18: =E18 -> 9750 | I18: =F18 -> 160875 | J18: =(G18*D18) -> 0 | N18: =F18 -> 160875 | O18: =N18 -> 160875 | P18: =O18*10% -> 16087.5
A19: 3.15 | B19: Rockshield | C19: METER | D19: 195 | E19: 100 | F19: =E19*D19 -> 19500 | H19: =E19 -> 100 | I19: =F19 -> 19500 | J19: =(G19*D19) -> 0 | N19: =F19 -> 19500 | O19: =N19 -> 19500 | P19: =O19*10% -> 1950
A20: 3.16 | B20: Continuous Concrete Coating - 16" | C20: METER | D20: 585 | E20: 48 | F20: =E20*D20 -> 28080 | H20: =E20 -> 48 | I20: =F20 -> 28080 | J20: =(G20*D20) -> 0 | N20: =F20 -> 28080 | O20: =N20 -> 28080 | P20: =O20*10% -> 2808
A21: 3.17 | B21: Continuous Concrete Coating - 24" | C21: METER | D21: 1075 | E21: 48 | F21: =E21*D21 -> 51600 | H21: =E21 -> 48 | I21: =F21 -> 51600 | J21: =(G21*D21) -> 0 | N21: =F21 -> 51600 | O21: =N21 -> 51600 | P21: =O21*10% -> 5160
A22: 3.18 | B22: Sack Breakers | C22: EACH | D22: 860 | F22: =E22*D22 -> 0 | H22: =E22 -> 0 | I22: =F22 -> 0 | J22: =(G22*D22) -> 0 | N22: =F22 -> 0 | O22: =N22 -> 0 | P22: =O22*10% -> 0
A23: 3.19 | B23: NOT USED | J23: =(G23*D23) -> 0
A24: 3.2 | B24: Ditch Breakers + Excavation - Polyurethane Foam | C24: CUBIC METERS | D24: 814 | J24: =(G24*D24) -> 0
A25: 3.21 | B25: Ditch Breakers + Excavation - Sand Bags | C25: CUBIC METERS | D25: 915 | E25: 12 | F25: =E25*D25 -> 10980 | H25: =E25 -> 12 | I25: =F25 -> 10980 | J25: =(G25*D25) -> 0 | N25: =F25 -> 10980 | O25: =N25 -> 10980 | P25: =O25*10% -> 1098
A26: 3.22 | B26: Diversion Berms - full width ROW | C26: METER | D26: 190 | E26: 350 | F26: =E26*D26 -> 66500 | H26: =E26 -> 350 | I26: =F26 -> 66500 | J26: =(G26*D26) -> 0 | N26: =F26 -> 66500 | O26: =N26 -> 66500 | P26: =O26*10% -> 6650
A27: 3.23 | B27: Sub Drains | C27: EACH | E27: 4 | F27: =E27*D27 -> 0 | H27: =E27 -> 4 | I27: =F27 -> 0 | J27: =(G27*D27) -> 0 | N27: =F27 -> 0 | O27: =N27 -> 0 | P27: =O27*10% -> 0
A28: 3.24 | B28: Concrete Bolt On Weights - 16" | C28: EACH | D28: 677 | J28: =(G28*D28) -> 0
A29: 3.25 | B29: Concrete Bolt On Weights - 24" | C29: EACH | D29: 2200 | J29: =(G29*D29) -> 0
A30: 3.26 | B30: Bag Weights - 16" Supply, fill, install | C30: EACH | D30: 419 | F30: =E30*D30 -> 0 | H30: =E30 -> 0 | I30: =F30 -> 0 | J30: =(G30*D30) -> 0 | N30: =F30 -> 0 | O30: =N30 -> 0 | P30: =O30*10% -> 0
A31: 3.27 | B31: Bag Weights - 24" Supply, fill, install | C31: EACH | D31: 748 | F31: =E31*D31 -> 0 | H31: =E31 -> 0 | I31: =F31 -> 0 | J31: =(G31*D31) -> 0 | N31: =F31+J32 -> 0 | O31: =N31 -> 0 | P31: =O31*10% -> 0
A32: 3.28 | B32: Cut and Rebevel pipe - Directed by company - 16" | C32: EACH | D32: 1200 | E32: 4 | F32: =E32*D31 -> 2992 | H32: =E32 -> 4 | I32: =F32 -> 2992 | J32: =(G32*D32) -> 0
A33: 3.29 | B33: Cut and Rebevel pipe - Directed by company - 24" | C33: EACH | D33: 1500 | E33: 4 | F33: =E33*D32 -> 4800 | H33: =E33 -> 4 | I33: =F33 -> 4800 | J33: =(G33*D33) -> 0
A34: 3.3 | B34: Cut out / replace welds - Directed by company 16" | C34: EACH | D34: 6000 | E34: 8 | F34: =E34*D34 -> 48000 | H34: =E34 -> 8 | I34: =F34 -> 48000 | J34: =(G34*D34) -> 0 | N34: =F34 -> 48000 | O34: =N34 -> 48000 | P34: =O34*10% -> 4800
A35: 3.31 | B35: Cut out / replace welds - Directed by company 24" | C35: EACH | D35: 8700 | E35: 8 | F35: =E35*D35 -> 69600 | H35: =E35 -> 8 | I35: =F35 -> 69600 | J35: =(G35*D35) -> 0 | N35: =F35 -> 69600 | O35: =N35 -> 69600 | P35: =O35*10% -> 6960
A36: 3.32 | B36: Additional Welds - Directed by Company - 16" | C36: EACH | D36: 2300 | E36: 8 | F36: =E36*D36 -> 18400 | H36: =E36 -> 8 | I36: =F36 -> 18400 | J36: =(G36*D36) -> 0 | N36: =F36 -> 18400 | O36: =N36 -> 18400 | P36: =O36*10% -> 1840
A37: 3.33 | B37: Additional Welds - Directed by Company - 24" | C37: EACH | D37: 3000 | E37: 8 | F37: =E37*D37 -> 24000 | H37: =E37 -> 8 | I37: =F37 -> 24000 | J37: =(G37*D37) -> 0 | N37: =F37 -> 24000 | O37: =N37 -> 24000 | P37: =O37*10% -> 2400
A38: 3.34 | B38: Sand Padding - over | C38: CUBIC METERS | D38: 145 | E38: 1750 | F38: =E38*D38 -> 253750 | H38: =E38 -> 1750 | I38: =F38 -> 253750 | J38: =(G38*D38) -> 0 | N38: =F38 -> 253750 | O38: =N38 -> 253750 | P38: =O38*10% -> 25375
A39: 3.35 | B39: Sand Padding - under | C39: CUBIC METERS | D39: 185 | E39: 875 | F39: =E39*D39 -> 161875 | H39: =E39 -> 875 | I39: =F39 -> 161875 | J39: =(G39*D39) -> 0 | N39: =F39 -> 161875 | O39: =N39 -> 161875 | P39: =O39*10% -> 16187.5
A40: 3.36 | B40: 2-wire test leads install | C40: EACH | D40: 3840 | E40: 875 | F40: =E40*D40 -> 3360000 | H40: =E40 -> 875 | I40: =F40 -> 3360000 | J40: =(G40*D40) -> 0 | N40: =F40 -> 3360000 | O40: =N40 -> 3360000 | P40: =O40*10% -> 336000
...

Sheet Holdback | Payment Log
A1: Contractor's Holdback Log | D1: =F23 -> 0
A2: Date | B2: Contractor | C2: Description | D2: Progress # | E2: Invoice # | F2: Amount | G2: Date Entered | H2: Entered In Report #
C23: TOTAL | F23: =SUM(F3:F22) -> 0
A27: Progress Payment Log | D27: =F49 -> 0
A28: Date | B28: Contractor | C28: Description | D28: Progress # | E28: Invoice # | F28: Amount | G28: Date Entered | H28: Entered In Report #
C49: TOTAL | F49: =SUM(F29:F48) -> 0
C69: TOTAL | F69: =SUM(F49:F67) -> 0

Sheet CO Log
B1: Value of Change Orders | D1: CHANGE ORDER LOG | G1: Value of Change Orders | H1: =G153 -> 147326 | I1: Actual Billed Costs of C/O | J1: =G153 -> 147326
A2: CO # | B2: Date | C2: Related RFI | D2: Description | E2: Cost Code | F2: Est Value | G2: Actual cost | H2: Ticket # | I2: Invoice # | J2: Date Submitted | K2: Entered In Report # | L2: Invoiced Total by Change Order
A3: 15 | B3: 42107 | D3: Rate Increase CH2MHill | E3: credit | G3: 147326 | J3: 42107 | L3: 0
G4: =F4 -> 0 | L4: 0
G5: =F5 -> 0 | L5: 0
G6: =F6 -> 0 | L6: 0
G7: =F7 -> 0 | L7: 0
G8: =F8 -> 0 | L8: 0
G9: =F9 -> 0 | L9: 0
G10: =F10 -> 0 | L10: 0
G11: =F11 -> 0 | L11: 0
G12: =F12 -> 0 | L12: 0
G13: =F13 -> 0 | L13: 0
G14: =F14 -> 0 | L14: 0
G15: =F15 -> 0 | L15: 0
... G33: =F33 -> 0 | L33: 0
L34: 0
D153: TOTAL | F153: =SUM(F2:F151) -> 0 | G153: =SUM(G2:G151) -> 147326

Sheet RFI Log
A2: Answered | B2: Pending | C2: Unused
A3: RFI # | B3: AFE | C3: Change Order # | D3: Type | E3: Description | F3: Date Received | G3: Date sent to Engineering | H3: Date Received from Engineering | I3: Date sent to Contractor | J3: Originator | K3: Comments

Sheet Actual vs Sch Days 
A1: Actual vs Scheduled Days of Project Completion | N1: Schedule % Complete | T1: =LOOKUP(A4,F10:F113,E10:E113) -> #N/A | Z1: Schedule % Complete | AF1: =LOOKUP(P1,'Actual vs Sch Days '!T10:T113,'Actual vs Sch Days '!S10:S113) -> #N/A
N2: Actual % Complete | T2: =REPORT!F13 -> 0 | Z2: Actual % Complete | AF2: =T18 -> 0
J3: % Ahead/Behind Schedule | T3: =T1-T2 -> #N/A | V3: % Ahead/Behind Schedule | AF3: =AF1-AF2 -> #N/A
A4: =REPORT!B1 -> 1 | J4: Days Ahead/Behind Schedule | T4: =(LOOKUP(T2,E10:E113,A10:A113)-(LOOKUP(T1,E10:E113,A10:A113))) -> #N/A | V4: Days Ahead/Behind Schedule | AF4: =(LOOKUP(AF2,'Actual vs Sch Days '!S10:S113,'Actual vs Sch Days '!O10:O113)-(LOOKUP(AF1,'Actual vs Sch Days '!S10:S113,'Actual vs Sch Days '!O10:O113))) -> #N/A
A6: Total Man Hours: | B6: 288192 | G6: 42003656 | I6: =G6/B6 -> 145.74886 | J6: /man/day
A9: DAY | B9: Man days | C9: Men Hours | D9: Scheduled Daily Completed | E9: Scheduled % Completed to Date | F9: Date | G9: Scheduled Daily Cost | H9: Scheduled Cost to date
A10: 1 | B10: 77 | C10: =B10*12 -> 924 | D10: =C10/288192 -> 0.0032061959 | E10: =D10 -> 0.0032061959 | F10: 39993 | G10: =C10*$I$6 -> 134671.95 | H10: =G10 -> 134671.95
A11: 2 | B11: 79 | C11: =B11*12 -> 948 | D11: =C11/288192 -> 0.0032894737 | E11: =E10+D11 -> 0.0064956696 | F11: 39994 | G11: =C11*$I$6 -> 138169.92 | H11: =G11 -> 138169.92
A12: 3 | B12: 81 | C12: =B12*12 -> 972 | D12: =C12/288192 -> 0.0033727515 | E12: =E11+D12 -> 0.0098684211 | F12: 39995 | G12: =C12*$I$6 -> 141667.89 | H12: =G12 -> 141667.89
A13: 4 | B13: 87 | C13: =B13*12 -> 1044 | D13: =C13/288192 -> 0.0036225849 | E13: =E12+D13 -> 0.013491006 | F13: 39996 | G13: =C13*$I$6 -> 152161.81 | H13: =G13 -> 152161.81
A14: 5 | B14: 92 | C14: =B14*12 -> 1104 | D14: =C14/288192 -> 0.0038307795 | E14: =E13+D14 -> 0.017321785 | F14: 39997 | G14: =C14*$I$6 -> 160906.74 | H14: =G14 -> 160906.74
A15: 6 | B15: 92 | C15: =B15*12 -> 1104 | D15: =C15/288192 -> 0.0038307795 | E15: =E14+D15 -> 0.021152565 | F15: 39998 | G15: =C15*$I$6 -> 160906.74 | H15: =G15 -> 160906.74
A16: 7 | B16: 3 | C16: =B16*12 -> 36 | D16: =C16/288192 -> 0.00012491672 | E16: =E15+D16 -> 0.021277482 | F16: 39999 | G16: =C16*$I$6 -> 5246.959 | H16: =G16 -> 5246.959
A17: 8 | B17: 138 | C17: =B17*12 -> 1656 | D17: =C17/288192 -> 0.0057461692 | E17: =E16+D17 -> 0.027023651 | F17: 40000 | G17: =C17*$I$6 -> 241360.11 | H17: =G17 -> 241360.11
A18: 9 | B18: 138 | C18: =B18*12 -> 1656 | D18: =C18/288192 -> 0.0057461692 | E18: =E17+D18 -> 0.03276982 | F18: 40001 | G18: =C18*$I$6 -> 241360.11 | H18: =G18 -> 241360.11
A19: 10 | B19: 146 | C19: =B19*12 -> 1752 | D19: =C19/288192 -> 0.0060792805 | E19: =E18+D19 -> 0.038849101 | F19: 40002 | G19: =C19*$I$6 -> 255352 | H19: =G19 -> 255352
A20: 11 | B20: 159 | C20: =B20*12 -> 1908 | D20: =C20/288192 -> 0.0066205863 | E20: =E19+D20 -> 0.045469687 | F20: 40003 | G20: =C20*$I$6 -> 278088.83 | H20: =G20 -> 278088.83
A21: 12 | B21: 159 | C21: =B21*12 -> 1908 | D21: =C21/288192 -> 0.0066205863 | E21: =E20+D21 -> 0.052090273 | F21: 40004 | G21: =C21*$I$6 -> 278088.83 | H21: =G21 -> 278088.83
A22: 13 | B22: 159 | C22: =B22*12 -> 1908 | D22: =C22/288192 -> 0.0066205863 | E22: =E21+D22 -> 0.058710859 | F22: 40005 | G22: =C22*$I$6 -> 278088.83 | H22: =G22 -> 278088.83
... A113: 104 | B113: 49 | C113: =B113*12 -> 588 | D113: =C113/288192 -> 0.0020403065 | E113: =E112+D113 -> 1 | F113: 40096 | G113: =C113*$I$6 -> 85700.33 | H113: =G113 -> 85700.33
B118: =SUM(B10:B113) -> 24016 | C118: =SUM(C10:C113) -> 288192 | D118: =SUM(D10:D113) -> 1
