Workbook

Sheet SUMMARY PAGE
A1: PROJECT: | G1: TOTAL PO. AMOUNT | H1: =SUM(G8:G82) -> 7007813.8
A2: A.F.E.# | G2: INVOICED | H2: =SUM(H8:H37) -> 5460281
A3: PROJECT # | G3: LEM TOTAL | H3: =SUM(J8:J37) -> 4886664.1
A4: E.W.R. # | E4: Percent Spent | H4: =H3/H1 -> 0.69731649
H6: INVOICED | I6: PO AMOUNT | J6: LEM TOTAL | K6: PO amount remaining from LEM total
A7: Sub Code | C7: Sub Description | E7: PO number | F7: Code | G7: PO AMOUNT (As of October 30th) | H7: TO DATE WITHOUT GST | I7: REMAINING WITHOUT GST
A8: 100 | B8: Vendor #1 | E8: 4500000000 | G8: 0 | H8: =SUMIF(H$86:I$227,A8,I$86:I$227) -> 0 | I8: =G8-H8 -> 0 | K8: =G8-J8 -> 0
A9: 103 | B9: Arete Design Solutions | E9: 4500091323 | G9: 90000 | H9: =SUMIF(H$86:I$281,A9,I$86:I$281) -> 87775 | I9: =G9-H9 -> 2225 | J9: =SUM('Arete Design Solutions'!R5) -> 87775 | K9: =G9-J9 -> 2225
A10: 104 | B10: Vendor #3 | E10: 4500000002 | G10: 70000 | H10: =SUMIF(H$86:I$281,A10,I$86:I$281) -> 36050 | I10: =G10-H10 -> 33950 | J10: ='Vendor #3'!AA5 -> 36050 | K10: =G10-J10 -> 33950
A11: 105 | B11: Vendor #4 | E11: 4500000003 | G11: 120000 | H11: =SUMIF(H$86:I$281,A11,I$86:I$281) -> 119300 | I11: =G11-H11 -> 700 | J11: =SUM('Vendor #4'!AB5) -> 116350 | K11: =G11-J11 -> 3650
A12: 106 | B12: Vendor #5 | E12: 4500000004 | G12: 25000 | H12: =SUMIF(H$86:I$227,A12,I$86:I$227) -> 15645.952 | I12: =G12-H12 -> 9354.0476 | J12: =H12 -> 15645.952 | K12: =G12-J12 -> 9354.0476
A13: 107 | B13: Vendor #6 | E13: 4500000005 | G13: =(74000+14800) -> 88800 | H13: =SUMIF(H$86:I$227,A13,I$86:I$227) -> 0 | I13: =G13-H13 -> 88800 | K13: =G13-J13 -> 88800
A14: 108 | B14: Vendor #7 | E14: 4500000006 | G14: 32500 | H14: =SUMIF(H$86:I$227,A14,I$86:I$227) -> 9675.2381 | I14: =G14-H14 -> 22824.762 | J14: =H14 -> 9675.2381 | K14: =G14-J14 -> 22824.762
A15: 109 | B15: Vendor #8 | E15: 4500000007 | G15: 210000 | H15: =SUMIF(H$86:H$575,A15,I$86:I$294) -> 193842 | I15: =G15-H15 -> 16158 | J15: =SUM('Vendor #8'!AA5) -> 193842 | K15: =G15-J15 -> 16158
A16: 110 | B16: Vendor #9 | E16: 4500000008 | G16: 12075 | H16: =SUMIF(H$86:I$227,A16,I$86:I$227) -> 9528.5714 | I16: =G16-H16 -> 2546.4286 | J16: =H16 -> 9528.5714 | K16: =G16-J16 -> 2546.4286
A17: 111 | B17: Vendor #10 | E17: 4500000009 | G17: 74347.94 | H17: =SUMIF(H$86:I$227,A17,I$86:I$227) -> 0 | I17: =G17-H17 -> 74347.94 | K17: =G17-J17 -> 74347.94
A18: 113 | B18: Vendor #11 | E18: 4500000010 | G18: 200000 | H18: =SUMIF(H$86:I$347,A18,I$86:I$354) -> 195250 | I18: =G18-H18 -> 4750 | J18: =SUM('Vendor #11'!AA5) -> 195250 | K18: =G18-J18 -> 4750
A19: 114 | B19: Vendor #12 | E19: 4500000011 | G19: 66300 | H19: =SUMIF(H$86:I$227,A19,I$86:I$227) -> 18245.5 | I19: =G19-H19 -> 48054.5 | J19: ='Vendor #12'!Y5 -> 18298 | K19: =G19-J19 -> 48002
A20: 115 | B20: Vendor #13 | E20: 4500000012 | G20: 140239 | H20: =SUMIF(H$86:I$289,A20,I$86:I$227) -> 131560.7 | I20: =G20-H20 -> 8678.3 | J20: =SUM('Vendor #13'!AA5) -> 131560.7 | K20: =G20-J20 -> 8678.3
A21: 116 | B21: Vendor #14- Survey | E21: 4500000013 | G21: 1374812 | H21: =SUMIF(H$86:I$343,A21,I$86:I$343) -> 1224133.5 | I21: =G21-H21 -> 150678.48 | J21: =SUM('Vendor #14'!AD7) -> 1224133.5 | K21: =G21-J21 -> 150678.49
A22: 120 | B22: Vendor #17 | E22: 4500000014 | G22: 94050 | H22: =SUMIF(H$86:I$302,A22,I$86:I$227) -> 85981 | I22: =G22-H22 -> 8069 | J22: =SUM('Vendor #17'!AG5) -> 89327 | K22: =G22-J22 -> 4723
A23: 121 | B23: Vendor #18 | E23: 4500000015 | G23: 950000 | H23: =SUMIF(H$86:I$281,A23,I$86:I$281) -> 848982.64 | I23: =G23-H23 -> 101017.36 | J23: =SUM('Vendor #18'!W5) -> 850360.14 | K23: =G23-J23 -> 99639.86
A24: 122 | B24: Vendor #19 | E24: 4500000016 | G24: 650000 | H24: =SUMIF(H$86:I$282,A24,I$86:I$282) -> 615159.5 | I24: =G24-H24 -> 34840.5 | J24: =SUM('Vendor #19'!AM5) -> 615159.5 | K24: =G24-J24 -> 34840.5
A25: 123 | B25: Vendor #20 | E25: 4500000017 | G25: 688004 | H25: =SUMIF(H$86:I$227,A25,I$86:I$227) -> 0 | I25: =G25-H25 -> 688004 | J25: =SUM('Vendor #20'!AW5) -> 228259.5 | K25: =G25-J25 -> 459744.5
A26: 125 | B26: Vendor #21 | E26: 4500000018 | G26: 117000 | H26: =SUMIF(H$86:I$227,A26,I$86:I$227) -> 117000 | I26: =G26-H26 -> 0 | J26: 117000 | K26: =G26-J26 -> 0
A27: 127 | B27: Vendor #23 | E27: 4500000019 | G27: 133650 | H27: =SUMIF(H$86:I$227,A27,I$86:I$227) -> 116045 | I27: =G27-H27 -> 17605 | J27: ='Vendor #23'!S5 -> 116045 | K27: =G27-J27 -> 17605
A28: 128 | B28: Vendor #24 | E28: 4500000020 | G28: 871045 | H28: =SUMIF(H$86:I$268,A28,I$86:I$262) -> 832506.4 | I28: =G28-H28 -> 38538.6 | J28: ='Vendor #24'!AJ4 -> 832404.02 | K28: =G28-J28 -> 38640.984
A29: 131 | B29: Vendor #27 | E29: 4500000021 | G29: 19990.9 | H29: =SUMIF(H$86:I$227,A29,I$86:I$227) -> 0 | I29: =G29-H29 -> 19990.9 | J29: ='Vendor #27'!AF7 -> 0 | K29: =G29-J29 -> 19990.9
A30: 132 | B30: Vendor #28 | E30: 4500000022 | G30: 980000 | H30: =SUMIF(H$86:I$227,A30,I$86:I$227) -> 803600 | I30: =G30-H30 -> 176400
H31: =SUMIF(H$86:I$227,A31,I$86:I$227) -> 0 | I31: =G31-H31 -> 0
H32: =SUMIF(H$86:I$227,A32,I$86:I$227) -> 0 | I32: =G32-H32 -> 0
H33: =SUMIF(H$86:I$227,A33,I$86:I$227) -> 0 | I33: =G33-H33 -> 0
A34: 136 | G34: 0 | H34: =SUMIF(H$86:I$227,A34,I$86:I$227) -> 0 | I34: =G34-H34 -> 0
A35: 137 | G35: 0 | H35: =SUMIF(H$86:I$227,A35,I$86:I$227) -> 0 | I35: =G35-H35 -> 0
A36: 138 | G36: 0 | H36: =SUMIF(H$86:I$227,A36,I$86:I$227) -> 0 | I36: =G36-H36 -> 0
A37: 139 | G37: 0 | H37: =SUMIF(H$86:I$227,A37,I$86:I$227) -> 0 | I37: =G37-H37 -> 0
A38: 140 | G38: 0 | H38: =SUMIF(H$86:I$227,A38,I$86:I$227) -> 0 | I38: =G38-H38 -> 0
A39: 141 | G39: 0 | H39: =SUMIF(H$86:I$227,A39,I$86:I$227) -> 0 | I39: =G39-H39 -> 0
A40: 142 | G40: 0 | H40: =SUMIF(H$86:I$227,A40,I$86:I$227) -> 0 | I40: =G40-H40 -> 0
A41: 143 | G41: 0 | H41: =SUMIF(H$86:I$227,A41,I$86:I$227) -> 0 | I41: =G41-H41 -> 0
...

Sheet Arete Design Solutions
A2: Arete Design Solutions
A4: Date | B4: Straight Hours Charged (ea.) | C4: Robert | D4: Rate | E4: Truck | F4: Rate | G4: Sub | H4: Rate | I4: KM's over 200 | J4: Rate | K4: Quad | L4: Rate | M4: Subtotal | N4: GST | O4: LEM Amount | P4: Affiliating Invoice | Q4: Approved By | R4: SUM OF ALL LEM'S (before GST)
R5: =SUM(M6:M156) -> 87775
A6: 42176 | C6: 1 | D6: 1100 | E6: 1 | F6: 200 | G6: 1 | H6: 175 | I6: 150 | J6: 1 | L6: 150 | M6: =(C6*D6)+(E6*F6)+(G6*H6)+(I6*J6)+(K6*L6) -> 1625 | N6: =(M6*5%) -> 81.25 | O6: =SUM(M6+N6) -> 1706.25 | P6: 0032
A7: 42177 | C7: 1 | D7: 1100 | E7: 1 | F7: 200 | G7: 1 | H7: 175 | J7: 1 | L7: 150 | M7: =(C7*D7)+(E7*F7)+(G7*H7)+(I7*J7)+(K7*L7) -> 1475 | N7: =(M7*5%) -> 73.75 | O7: =SUM(M7+N7) -> 1548.75 | P7: 0032
A8: 42178 | C8: 1 | D8: 1100 | E8: 1 | F8: 200 | G8: 1 | H8: 175 | J8: 1 | L8: 150 | M8: =(C8*D8)+(E8*F8)+(G8*H8)+(I8*J8)+(K8*L8) -> 1475 | N8: =(M8*5%) -> 73.75 | O8: =SUM(M8+N8) -> 1548.75 | P8: 0032
A9: 42179 | C9: 1 | D9: 1100 | E9: 1 | F9: 200 | G9: 1 | H9: 175 | J9: 1 | L9: 150 | M9: =(C9*D9)+(E9*F9)+(G9*H9)+(I9*J9)+(K9*L9) -> 1475 | N9: =(M9*5%) -> 73.75 | O9: =SUM(M9+N9) -> 1548.75 | P9: 0032
A10: 42180 | C10: 1 | D10: 1100 | E10: 1 | F10: 200 | G10: 1 | H10: 175 | J10: 1 | L10: 150 | M10: =(C10*D10)+(E10*F10)+(G10*H10)+(I10*J10)+(K10*L10) -> 1475 | N10: =(M10*5%) -> 73.75 | O10: =SUM(M10+N10) -> 1548.75 | P10: 0032
A11: 42181 | C11: 1 | D11: 1100 | E11: 1 | F11: 200 | G11: 1 | H11: 175 | J11: 1 | L11: 150 | M11: =(C11*D11)+(E11*F11)+(G11*H11)+(I11*J11)+(K11*L11) -> 1475 | N11: =(M11*5%) -> 73.75 | O11: =SUM(M11+N11) -> 1548.75 | P11: 0032
A12: 42182 | C12: 1 | D12: 1100 | E12: 1 | F12: 200 | G12: 1 | H12: 175 | J12: 1 | L12: 150 | M12: =(C12*D12)+(E12*F12)+(G12*H12)+(I12*J12)+(K12*L12) -> 1475 | N12: =(M12*5%) -> 73.75 | O12: =SUM(M12+N12) -> 1548.75 | P12: 0032
A13: 42183 | D13: 1100 | F13: 200 | G13: 1 | H13: 175 | J13: 1 | L13: 150 | M13: =(C13*D13)+(E13*F13)+(G13*H13)+(I13*J13)+(K13*L13) -> 175 | N13: =(M13*5%) -> 8.75 | O13: =SUM(M13+N13) -> 183.75 | P13: 0032
A14: 42184 | C14: 1 | D14: 1100 | E14: 1 | F14: 200 | G14: 1 | H14: 175 | J14: 1 | L14: 150 | M14: =(C14*D14)+(E14*F14)+(G14*H14)+(I14*J14)+(K14*L14) -> 1475 | N14: =(M14*5%) -> 73.75 | O14: =SUM(M14+N14) -> 1548.75 | P14: 0032
A15: 42185 | C15: 1 | D15: 1100 | E15: 1 | F15: 200 | G15: 1 | H15: 175 | J15: 1 | L15: 150 | M15: =(C15*D15)+(E15*F15)+(G15*H15)+(I15*J15)+(K15*L15) -> 1475 | N15: =(M15*5%) -> 73.75 | O15: =SUM(M15+N15) -> 1548.75 | P15: 0032
A16: 42186 | C16: 1 | D16: 1100 | E16: 1 | F16: 200 | G16: 1 | H16: 175 | J16: 1 | L16: 150 | M16: =(C16*D16)+(E16*F16)+(G16*H16)+(I16*J16)+(K16*L16) -> 1475 | N16: =(M16*5%) -> 73.75 | O16: =SUM(M16+N16) -> 1548.75 | P16: 0033
A17: 42187 | C17: 1 | D17: 1100 | E17: 1 | F17: 200 | G17: 1 | H17: 175 | J17: 1 | L17: 150 | M17: =(C17*D17)+(E17*F17)+(G17*H17)+(I17*J17)+(K17*L17) -> 1475 | N17: =(M17*5%) -> 73.75 | O17: =SUM(M17+N17) -> 1548.75 | P17: 0033
A18: 42188 | C18: 1 | D18: 1100 | E18: 1 | F18: 200 | G18: 1 | H18: 175 | J18: 1 | L18: 150 | M18: =(C18*D18)+(E18*F18)+(G18*H18)+(I18*J18)+(K18*L18) -> 1475 | N18: =(M18*5%) -> 73.75 | O18: =SUM(M18+N18) -> 1548.75 | P18: 0033
A19: 42189 | C19: 1 | D19: 1100 | E19: 1 | F19: 200 | G19: 1 | H19: 175 | J19: 1 | L19: 150 | M19: =(C19*D19)+(E19*F19)+(G19*H19)+(I19*J19)+(K19*L19) -> 1475 | N19: =(M19*5%) -> 73.75 | O19: =SUM(M19+N19) -> 1548.75 | P19: 0033
A20: 42190 | G20: 1 | H20: 175 | J20: 1 | L20: 150 | M20: =(C20*D20)+(E20*F20)+(G20*H20)+(I20*J20)+(K20*L20) -> 175 | N20: =(M20*5%) -> 8.75 | O20: =SUM(M20+N20) -> 183.75 | P20: 0033
A21: 42191 | C21: 1 | D21: 1100 | E21: 1 | F21: 200 | G21: 1 | H21: 175 | J21: 1 | L21: 150 | M21: =(C21*D21)+(E21*F21)+(G21*H21)+(I21*J21)+(K21*L21) -> 1475 | N21: =(M21*5%) -> 73.75 | O21: =SUM(M21+N21) -> 1548.75 | P21: 0033
A22: 42192 | C22: 1 | D22: 1100 | E22: 1 | F22: 200 | G22: 1 | H22: 175 | J22: 1 | L22: 150 | M22: =(C22*D22)+(E22*F22)+(G22*H22)+(I22*J22)+(K22*L22) -> 1475 | N22: =(M22*5%) -> 73.75 | O22: =SUM(M22+N22) -> 1548.75 | P22: 0033
A23: 42193 | C23: 1 | D23: 1100 | E23: 1 | F23: 200 | G23: 1 | H23: 175 | J23: 1 | L23: 150 | M23: =(C23*D23)+(E23*F23)+(G23*H23)+(I23*J23)+(K23*L23) -> 1475 | N23: =(M23*5%) -> 73.75 | O23: =SUM(M23+N23) -> 1548.75 | P23: 0033
A24: 42194 | C24: 1 | D24: 1100 | E24: 1 | F24: 200 | G24: 1 | H24: 175 | J24: 1 | L24: 150 | M24: =(C24*D24)+(E24*F24)+(G24*H24)+(I24*J24)+(K24*L24) -> 1475 | N24: =(M24*5%) -> 73.75 | O24: =SUM(M24+N24) -> 1548.75 | P24: 0033
A25: 42195 | C25: 1 | D25: 1100 | E25: 1 | F25: 200 | G25: 1 | H25: 175 | J25: 1 | L25: 150 | M25: =(C25*D25)+(E25*F25)+(G25*H25)+(I25*J25)+(K25*L25) -> 1475 | N25: =(M25*5%) -> 73.75 | O25: =SUM(M25+N25) -> 1548.75 | P25: 0033
A26: 42196 | C26: 1 | D26: 1100 | E26: 1 | F26: 200 | G26: 1 | H26: 175 | J26: 1 | L26: 150 | M26: =(C26*D26)+(E26*F26)+(G26*H26)+(I26*J26)+(K26*L26) -> 1475 | N26: =(M26*5%) -> 73.75 | O26: =SUM(M26+N26) -> 1548.75 | P26: 0033
A27: 42197 | D27: 1100 | F27: 200 | G27: 1 | H27: 175 | J27: 1 | L27: 150 | M27: =(C27*D27)+(E27*F27)+(G27*H27)+(I27*J27)+(K27*L27) -> 175 | N27: =(M27*5%) -> 8.75 | O27: =SUM(M27+N27) -> 183.75 | P27: 0033
A28: 42198 | D28: 1100 | F28: 200 | G28: 1 | H28: 175 | J28: 1 | L28: 150 | M28: =(C28*D28)+(E28*F28)+(G28*H28)+(I28*J28)+(K28*L28) -> 175 | N28: =(M28*5%) -> 8.75 | O28: =SUM(M28+N28) -> 183.75 | P28: 0033
A29: 42199 | C29: 1 | D29: 1100 | E29: 1 | F29: 200 | G29: 1 | H29: 175 | J29: 1 | L29: 150 | M29: =(C29*D29)+(E29*F29)+(G29*H29)+(I29*J29)+(K29*L29) -> 1475 | N29: =(M29*5%) -> 73.75 | O29: =SUM(M29+N29) -> 1548.75 | P29: 0033
A30: 42200 | C30: 1 | D30: 1100 | E30: 1 | F30: 200 | G30: 1 | H30: 175 | J30: 1 | L30: 150 | M30: =(C30*D30)+(E30*F30)+(G30*H30)+(I30*J30)+(K30*L30) -> 1475 | N30: =(M30*5%) -> 73.75 | O30: =SUM(M30+N30) -> 1548.75 | P30: 0033
A31: 42201 | C31: 1 | D31: 1100 | E31: 1 | F31: 200 | G31: 1 | H31: 175 | J31: 1 | L31: 150 | M31: =(C31*D31)+(E31*F31)+(G31*H31)+(I31*J31)+(K31*L31) -> 1475 | N31: =(M31*5%) -> 73.75 | O31: =SUM(M31+N31) -> 1548.75 | P31: 0034
A32: 42202 | D32: 1100 | F32: 200 | G32: 1 | H32: 175 | J32: 1 | L32: 150 | M32: =(C32*D32)+(E32*F32)+(G32*H32)+(I32*J32)+(K32*L32) -> 175 | N32: =(M32*5%) -> 8.75 | O32: =SUM(M32+N32) -> 183.75 | P32: 0034
A33: 42203 | D33: 1100 | F33: 200 | G33: 1 | H33: 175 | J33: 1 | L33: 150 | M33: =(C33*D33)+(E33*F33)+(G33*H33)+(I33*J33)+(K33*L33) -> 175 | N33: =(M33*5%) -> 8.75 | O33: =SUM(M33+N33) -> 183.75 | P33: 0034
A34: 42204 | D34: 1100 | F34: 200 | G34: 1 | H34: 175 | J34: 1 | L34: 150 | M34: =(C34*D34)+(E34*F34)+(G34*H34)+(I34*J34)+(K34*L34) -> 175 | N34: =(M34*5%) -> 8.75 | O34: =SUM(M34+N34) -> 183.75 | P34: 0034
A35: 42205 | C35: 1 | D35: 1100 | E35: 1 | F35: 200 | G35: 1 | H35: 175 | J35: 1 | L35: 150 | M35: =(C35*D35)+(E35*F35)+(G35*H35)+(I35*J35)+(K35*L35) -> 1475 | N35: =(M35*5%) -> 73.75 | O35: =SUM(M35+N35) -> 1548.75 | P35: 0034
A36: 42206 | C36: 1 | D36: 1100 | E36: 1 | F36: 200 | G36: 1 | H36: 175 | J36: 1 | L36: 150 | M36: =(C36*D36)+(E36*F36)+(G36*H36)+(I36*J36)+(K36*L36) -> 1475 | N36: =(M36*5%) -> 73.75 | O36: =SUM(M36+N36) -> 1548.75 | P36: 0034
A37: 42207 | C37: 1 | D37: 1100 | E37: 1 | F37: 200 | G37: 1 | H37: 175 | J37: 1 | L37: 150 | M37: =(C37*D37)+(E37*F37)+(G37*H37)+(I37*J37)+(K37*L37) -> 1475 | N37: =(M37*5%) -> 73.75 | O37: =SUM(M37+N37) -> 1548.75 | P37: 0034
A38: 42208 | C38: 1 | D38: 1100 | E38: 1 | F38: 200 | G38: 1 | H38: 175 | J38: 1 | L38: 150 | M38: =(C38*D38)+(E38*F38)+(G38*H38)+(I38*J38)+(K38*L38) -> 1475 | N38: =(M38*5%) -> 73.75 | O38: =SUM(M38+N38) -> 1548.75 | P38: 0034 | Q38: =SUM(M31:M46) -> 18400
A39: 42209 | C39: 1 | D39: 1100 | E39: 1 | F39: 200 | G39: 1 | H39: 175 | J39: 1 | L39: 150 | M39: =(C39*D39)+(E39*F39)+(G39*H39)+(I39*J39)+(K39*L39) -> 1475 | N39: =(M39*5%) -> 73.75 | O39: =SUM(M39+N39) -> 1548.75 | P39: 0034
A40: 42210 | C40: 1 | D40: 1100 | E40: 1 | F40: 200 | G40: 1 | H40: 175 | J40: 1 | L40: 150 | M40: =(C40*D40)+(E40*F40)+(G40*H40)+(I40*J40)+(K40*L40) -> 1475 | N40: =(M40*5%) -> 73.75 | O40: =SUM(M40+N40) -> 1548.75 | P40: 0034
A41: 42211 | D41: 1100 | F41: 200 | G41: 1 | H41: 175 | J41: 1 | L41: 150 | M41: =(C41*D41)+(E41*F41)+(G41*H41)+(I41*J41)+(K41*L41) -> 175 | N41: =(M41*5%) -> 8.75 | O41: =SUM(M41+N41) -> 183.75 | P41: 0034
A42: 42212 | C42: 1 | D42: 1100 | E42: 1 | F42: 200 | G42: 1 | H42: 175 | J42: 1 | L42: 150 | M42: =(C42*D42)+(E42*F42)+(G42*H42)+(I42*J42)+(K42*L42) -> 1475 | N42: =(M42*5%) -> 73.75 | O42: =SUM(M42+N42) -> 1548.75 | P42: 0034
...

Sheet Vendor #3
A2: Vendor #3
A4: Date | B4: Straight Hours Charged (ea.) | C4: Overtime Hours Charged (ea.) | D4: Vendor #3 | E4: DAY RATE | F4: Truck | G4: Subsistence | H4: Kms | S4: Total Hours Charged | T4: Equipment Detail | U4: Km's Charged | V4: Subtotal | W4: GST | X4: LEM Amount | Y4: Affiliating Invoice | Z4: Approved By | AA4: SUM OF ALL LEM'S (before GST)
A5: RATES | E5: 1100 | F5: 200 | G5: 1 | H5: 1 | AA5: =SUM(V5:V133) -> 36050
A6: 42225 | D6: 1 | E6: 1 | F6: 1 | G6: 175 | H6: 150 | V6: =SUM(E6*$E$5+F6*$F$5+G6*$G$5+H6*$H$5+I6*$I$5+J6*$J$5+K6*$K$5) -> 1625 | W6: =(V6*5%) -> 81.25 | X6: =SUM(V6+W6) -> 1706.25 | Y6: 31
A7: 42226 | D7: 1 | E7: 1 | F7: 1 | G7: 175 | V7: =SUM(E7*$E$5+F7*$F$5+G7*$G$5+H7*$H$5+I7*$I$5+J7*$J$5+K7*$K$5) -> 1475 | W7: =(V7*5%) -> 73.75 | X7: =SUM(V7+W7) -> 1548.75 | Y7: 31
A8: 42227 | D8: 1 | E8: 1 | F8: 1 | G8: 175 | V8: =SUM(E8*$E$5+F8*$F$5+G8*$G$5+H8*$H$5+I8*$I$5+J8*$J$5+K8*$K$5) -> 1475 | W8: =(V8*5%) -> 73.75 | X8: =SUM(V8+W8) -> 1548.75 | Y8: 31
A9: 42228 | D9: 1 | E9: 1 | F9: 1 | G9: 175 | V9: =SUM(E9*$E$5+F9*$F$5+G9*$G$5+H9*$H$5+I9*$I$5+J9*$J$5+K9*$K$5) -> 1475 | W9: =(V9*5%) -> 73.75 | X9: =SUM(V9+W9) -> 1548.75 | Y9: 31
A10: 42229 | D10: 1 | E10: 1 | F10: 1 | G10: 175 | V10: =SUM(E10*$E$5+F10*$F$5+G10*$G$5+H10*$H$5+I10*$I$5+J10*$J$5+K10*$K$5) -> 1475 | W10: =(V10*5%) -> 73.75 | X10: =SUM(V10+W10) -> 1548.75 | Y10: 31
A11: 42230 | D11: 1 | E11: 1 | F11: 1 | G11: 175 | V11: =SUM(E11*$E$5+F11*$F$5+G11*$G$5+H11*$H$5+I11*$I$5+J11*$J$5+K11*$K$5) -> 1475 | W11: =(V11*5%) -> 73.75 | X11: =SUM(V11+W11) -> 1548.75 | Y11: 31
A12: 42231 | D12: 1 | E12: 1 | F12: 1 | G12: 175 | V12: =SUM(E12*$E$5+F12*$F$5+G12*$G$5+H12*$H$5+I12*$I$5+J12*$J$5+K12*$K$5) -> 1475 | W12: =(V12*5%) -> 73.75 | X12: =SUM(V12+W12) -> 1548.75 | Y12: 31
A13: 42232 | D13: 0 | E13: 0 | F13: 0 | G13: 175 | V13: =SUM(E13*$E$5+F13*$F$5+G13*$G$5+H13*$H$5+I13*$I$5+J13*$J$5+K13*$K$5) -> 175 | W13: =(V13*5%) -> 8.75 | X13: =SUM(V13+W13) -> 183.75 | Y13: 32
A14: 42233 | D14: 1 | E14: 1 | F14: 1 | G14: 175 | V14: =SUM(E14*$E$5+F14*$F$5+G14*$G$5+H14*$H$5+I14*$I$5+J14*$J$5+K14*$K$5) -> 1475 | W14: =(V14*5%) -> 73.75 | X14: =SUM(V14+W14) -> 1548.75 | Y14: 32
A15: 42234 | D15: 1 | E15: 1 | F15: 1 | G15: 175 | V15: =SUM(E15*$E$5+F15*$F$5+G15*$G$5+H15*$H$5+I15*$I$5+J15*$J$5+K15*$K$5) -> 1475 | W15: =(V15*5%) -> 73.75 | X15: =SUM(V15+W15) -> 1548.75 | Y15: 32
A16: 42235 | D16: 1 | E16: 1 | F16: 1 | G16: 175 | V16: =SUM(E16*$E$5+F16*$F$5+G16*$G$5+H16*$H$5+I16*$I$5+J16*$J$5+K16*$K$5) -> 1475 | W16: =(V16*5%) -> 73.75 | X16: =SUM(V16+W16) -> 1548.75 | Y16: 32
A17: 42236 | D17: 1 | E17: 1 | F17: 1 | G17: 175 | V17: =SUM(E17*$E$5+F17*$F$5+G17*$G$5+H17*$H$5+I17*$I$5+J17*$J$5+K17*$K$5) -> 1475 | W17: =(V17*5%) -> 73.75 | X17: =SUM(V17+W17) -> 1548.75 | Y17: 32
A18: 42237 | D18: 1 | E18: 1 | F18: 1 | G18: 175 | V18: =SUM(E18*$E$5+F18*$F$5+G18*$G$5+H18*$H$5+I18*$I$5+J18*$J$5+K18*$K$5) -> 1475 | W18: =(V18*5%) -> 73.75 | X18: =SUM(V18+W18) -> 1548.75 | Y18: 32
... A26: 42245 | D26: 1 | E26: 1 | F26: 1 | G26: 175 | V26: =SUM(E26*$E$5+F26*$F$5+G26*$G$5+H26*$H$5+I26*$I$5+J26*$J$5+K26*$K$5) -> 1475 | W26: =(V26*5%) -> 73.75 | X26: =SUM(V26+W26) -> 1548.75 | Y26: 32
A27: 42246 | G27: 175 | V27: =SUM(E27*$E$5+F27*$F$5+G27*$G$5+H27*$H$5+I27*$I$5+J27*$J$5+K27*$K$5) -> 175 | W27: =(V27*5%) -> 8.75 | X27: =SUM(V27+W27) -> 183.75 | Y27: 32
A28: 42247 | D28: 1 | E28: 1 | F28: 1 | G28: 175 | V28: =SUM(E28*$E$5+F28*$F$5+G28*$G$5+H28*$H$5+I28*$I$5+J28*$J$5+K28*$K$5) -> 1475 | W28: =(V28*5%) -> 73.75 | X28: =SUM(V28+W28) -> 1548.75 | Y28: 32
A29: 42248 | D29: 1 | E29: 1 | F29: 1 | G29: 175 | V29: =SUM(E29*$E$5+F29*$F$5+G29*$G$5+H29*$H$5+I29*$I$5+J29*$J$5+K29*$K$5) -> 1475 | W29: =(V29*5%) -> 73.75 | X29: =SUM(V29+W29) -> 1548.75 | Y29: 33
A30: 42249 | D30: 1 | E30: 1 | F30: 1 | G30: 175 | V30: =SUM(E30*$E$5+F30*$F$5+G30*$G$5+H30*$H$5+I30*$I$5+J30*$J$5+K30*$K$5) -> 1475 | W30: =(V30*5%) -> 73.75 | X30: =SUM(V30+W30) -> 1548.75 | Y30: 33
A31: 42250 | D31: 1 | E31: 1 | F31: 1 | G31: 175 | V31: =SUM(E31*$E$5+F31*$F$5+G31*$G$5+H31*$H$5+I31*$I$5+J31*$J$5+K31*$K$5) -> 1475 | W31: =(V31*5%) -> 73.75 | X31: =SUM(V31+W31) -> 1548.75 | Y31: 33
A32: 42251 | D32: 1 | E32: 1 | F32: 1 | H32: 150 | V32: =SUM(E32*$E$5+F32*$F$5+G32*$G$5+H32*$H$5+I32*$I$5+J32*$J$5+K32*$K$5) -> 1450 | W32: =(V32*5%) -> 72.5 | X32: =SUM(V32+W32) -> 1522.5 | Y32: 33

Sheet Vendor #4
A2: Vendor #4
A4: Date | B4: Straight Hours Charged (ea.) | C4: Overtime Hours Charged (ea.) | D4: Vendor #4 | E4: Labourer class | F4: Rate | G4: Truck | H4: Rate | I4: Sub | J4: Rate | K4: KM's over 200 | L4: Rate | M4: Quad | N4: Rate | O4: Labourer class | P4: Rate | Q4: Labourer class | R4: Rate | S4: Total Labour Rate per hr | T4: Total Hours Charged | U4: Equipment Detail | V4: Km's Charged | W4: Subtotal | X4: GST | Y4: LEM Amount | Z4: Affiliating Invoice | AA4: Approved By | AB4: SUM OF ALL LEM'S (beforeGST)
AB5: =SUM(W6:W112) -> 116350
A6: 42149 | D6: 1 | F6: 1100 | G6: 1 | H6: 200 | I6: 1 | J6: 175 | K6: 150 | L6: 1 | N6: 150 | P6: 0 | R6: 0 | S6: =SUM(L6,J6,H6,F6) -> 1476 | T6: =(B6+C6)*D6 -> 0 | W6: =(D6*F6)+(G6*H6)+(I6*J6)+(K6*L6)+(M6*N6) -> 1625 | X6: =(W6*5%) -> 81.25 | Y6: =SUM(W6+X6) -> 1706.25 | Z6: 13
A7: 42150 | D7: 1 | F7: 1100 | G7: 1 | H7: 200 | I7: 1 | J7: 175 | L7: 1 | N7: 150 | P7: 0 | R7: 0 | S7: =SUM(L7,J7,H7,F7) -> 1476 | T7: =(B7+C7)*D7 -> 0 | W7: =(D7*F7)+(G7*H7)+(I7*J7)+(K7*L7)+(M7*N7) -> 1475 | X7: =(W7*5%) -> 73.75 | Y7: =SUM(W7+X7) -> 1548.75 | Z7: 13
A8: 42151 | D8: 1 | F8: 1100 | G8: 1 | H8: 200 | I8: 1 | J8: 175 | L8: 1 | N8: 150 | P8: 0 | R8: 0 | S8: =SUM(L8,J8,H8,F8) -> 1476 | T8: =(B8+C8)*D8 -> 0 | W8: =(D8*F8)+(G8*H8)+(I8*J8)+(K8*L8)+(M8*N8) -> 1475 | X8: =(W8*5%) -> 73.75 | Y8: =SUM(W8+X8) -> 1548.75 | Z8: 13
A9: 42152 | D9: 1 | F9: 1100 | G9: 1 | H9: 200 | I9: 1 | J9: 175 | L9: 1 | N9: 150 | P9: 0 | R9: 0 | S9: =SUM(L9,J9,H9,F9) -> 1476 | T9: =(B9+C9)*D9 -> 0 | W9: =(D9*F9)+(G9*H9)+(I9*J9)+(K9*L9)+(M9*N9) -> 1475 | X9: =(W9*5%) -> 73.75 | Y9: =SUM(W9+X9) -> 1548.75 | Z9: 13
A10: 42153 | D10: 1 | F10: 1100 | G10: 1 | H10: 200 | I10: 1 | J10: 175 | L10: 1 | N10: 150 | P10: 0 | R10: 0 | S10: =SUM(L10,J10,H10,F10) -> 1476 | T10: =(B10+C10)*D10 -> 0 | W10: =(D10*F10)+(G10*H10)+(I10*J10)+(K10*L10)+(M10*N10) -> 1475 | X10: =(W10*5%) -> 73.75 | Y10: =SUM(W10+X10) -> 1548.75 | Z10: 13
A11: 42156 | D11: 1 | F11: 1100 | G11: 1 | H11: 200 | I11: 1 | J11: 175 | L11: 1 | N11: 150 | P11: 0 | R11: 0 | S11: =SUM(L11,J11,H11,F11) -> 1476 | T11: =(B11+C11)*D11 -> 0 | W11: =(D11*F11)+(G11*H11)+(I11*J11)+(K11*L11)+(M11*N11) -> 1475 | X11: =(W11*5%) -> 73.75 | Y11: =SUM(W11+X11) -> 1548.75 | Z11: 14
A12: 42157 | D12: 1 | F12: 1100 | G12: 1 | H12: 200 | I12: 1 | J12: 175 | L12: 1 | N12: 150 | P12: 0 | R12: 0 | S12: =SUM(L12,J12,H12,F12) -> 1476 | T12: =(B12+C12)*D12 -> 0 | W12: =(D12*F12)+(G12*H12)+(I12*J12)+(K12*L12)+(M12*N12) -> 1475 | X12: =(W12*5%) -> 73.75 | Y12: =SUM(W12+X12) -> 1548.75 | Z12: 14
A13: 42158 | D13: 1 | F13: 1100 | G13: 1 | H13: 200 | I13: 1 | J13: 175 | L13: 1 | N13: 150 | P13: 0 | R13: 0 | S13: =SUM(L13,J13,H13,F13) -> 1476 | T13: =(B13+C13)*D13 -> 0 | W13: =(D13*F13)+(G13*H13)+(I13*J13)+(K13*L13)+(M13*N13) -> 1475 | X13: =(W13*5%) -> 73.75 | Y13: =SUM(W13+X13) -> 1548.75 | Z13: 14
A14: 42159 | D14: 1 | F14: 1100 | G14: 1 | H14: 200 | I14: 1 | J14: 175 | L14: 1 | N14: 150 | P14: 0 | R14: 0 | S14: =SUM(L14,J14,H14,F14) -> 1476 | T14: =(B14+C14)*D14 -> 0 | W14: =(D14*F14)+(G14*H14)+(I14*J14)+(K14*L14)+(M14*N14) -> 1475 | X14: =(W14*5%) -> 73.75 | Y14: =SUM(W14+X14) -> 1548.75 | Z14: 14
A15: 42160 | D15: 1 | F15: 1100 | G15: 1 | H15: 200 | I15: 1 | J15: 175 | L15: 1 | N15: 150 | P15: 0 | R15: 0 | S15: =SUM(L15,J15,H15,F15) -> 1476 | T15: =(B15+C15)*D15 -> 0 | W15: =(D15*F15)+(G15*H15)+(I15*J15)+(K15*L15)+(M15*N15) -> 1475 | X15: =(W15*5%) -> 73.75 | Y15: =SUM(W15+X15) -> 1548.75 | Z15: 14
A16: 42172 | D16: 1 | F16: 1100 | G16: 1 | H16: 200 | I16: 1 | J16: 175 | L16: 1 | N16: 150 | P16: 0 | R16: 0 | S16: =SUM(L16,J16,H16,F16) -> 1476 | T16: =(B16+C16)*D16 -> 0 | W16: =(D16*F16)+(G16*H16)+(I16*J16)+(K16*L16)+(M16*N16) -> 1475 | X16: =(W16*5%) -> 73.75 | Y16: =SUM(W16+X16) -> 1548.75 | Z16: 14
A17: 42173 | D17: 1 | F17: 1100 | G17: 1 | H17: 200 | I17: 1 | J17: 175 | L17: 1 | N17: 150 | P17: 0 | R17: 0 | S17: =SUM(L17,J17,H17,F17) -> 1476 | T17: =(B17+C17)*D17 -> 0 | W17: =(D17*F17)+(G17*H17)+(I17*J17)+(K17*L17)+(M17*N17) -> 1475 | X17: =(W17*5%) -> 73.75 | Y17: =SUM(W17+X17) -> 1548.75 | Z17: 14
A18: 42176 | D18: 1 | F18: 1100 | G18: 1 | H18: 200 | I18: 1 | J18: 175 | L18: 1 | N18: 150 | P18: 0 | R18: 0 | S18: =SUM(L18,J18,H18,F18) -> 1476 | T18: =(B18+C18)*D18 -> 0 | W18: =(D18*F18)+(G18*H18)+(I18*J18)+(K18*L18)+(M18*N18) -> 1475 | X18: =(W18*5%) -> 73.75 | Y18: =SUM(W18+X18) -> 1548.75 | Z18: 14
... A23: 42181 | D23: 1 | F23: 1100 | G23: 1 | H23: 200 | I23: 1 | J23: 175 | L23: 1 | N23: 150 | P23: 0 | R23: 0 | S23: =SUM(L23,J23,H23,F23) -> 1476 | T23: =(B23+C23)*D23 -> 0 | W23: =(D23*F23)+(G23*H23)+(I23*J23)+(K23*L23)+(M23*N23) -> 1475 | X23: =(W23*5%) -> 73.75 | Y23: =SUM(W23+X23) -> 1548.75 | Z23: 14
A24: 42186 | F24: 1100 | H24: 200 | I24: 1 | J24: 175 | L24: 1 | N24: 150 | P24: 0 | R24: 0 | S24: =SUM(L24,J24,H24,F24) -> 1476 | T24: =(B24+C24)*D24 -> 0 | W24: =(D24*F24)+(G24*H24)+(I24*J24)+(K24*L24)+(M24*N24) -> 175 | X24: =(W24*5%) -> 8.75 | Y24: 2015-18 | Z24: 15
A25: 42187 | D25: 1 | F25: 1100 | G25: 1 | H25: 200 | I25: 1 | J25: 175 | L25: 1 | N25: 150 | P25: 0 | R25: 0 | S25: =SUM(L25,J25,H25,F25) -> 1476 | T25: =(B25+C25)*D25 -> 0 | W25: =(D25*F25)+(G25*H25)+(I25*J25)+(K25*L25)+(M25*N25) -> 1475 | X25: =(W25*5%) -> 73.75 | Y25: 2015-18 | Z25: 15
A26: 42188 | D26: 1 | F26: 1100 | G26: 1 | H26: 200 | I26: 1 | J26: 175 | L26: 1 | N26: 150 | P26: 0 | R26: 0 | S26: =SUM(L26,J26,H26,F26) -> 1476 | T26: =(B26+C26)*D26 -> 0 | W26: =(D26*F26)+(G26*H26)+(I26*J26)+(K26*L26)+(M26*N26) -> 1475 | X26: =(W26*5%) -> 73.75 | Y26: 2015-18 | Z26: 15
A27: 42189 | D27: 1 | F27: 1100 | G27: 1 | H27: 200 | I27: 1 | J27: 175 | L27: 1 | N27: 150 | P27: 0 | R27: 0 | S27: =SUM(L27,J27,H27,F27) -> 1476 | T27: =(B27+C27)*D27 -> 0 | W27: =(D27*F27)+(G27*H27)+(I27*J27)+(K27*L27)+(M27*N27) -> 1475 | X27: =(W27*5%) -> 73.75 | Y27: 2015-18 | Z27: 15
A28: 42190 | F28: 1100 | H28: 200 | I28: 1 | J28: 175 | L28: 1 | N28: 150 | P28: 0 | R28: 0 | S28: =SUM(L28,J28,H28,F28) -> 1476 | T28: =(B28+C28)*D28 -> 0 | W28: =(D28*F28)+(G28*H28)+(I28*J28)+(K28*L28)+(M28*N28) -> 175 | X28: =(W28*5%) -> 8.75 | Y28: 2015-18 | Z28: 15
A29: 42191 | D29: 1 | F29: 1100 | G29: 1 | H29: 200 | I29: 1 | J29: 175 | L29: 1 | N29: 150 | W29: =(D29*F29)+(G29*H29)+(I29*J29)+(K29*L29)+(M29*N29) -> 1475 | X29: =(W29*5%) -> 73.75 | Y29: 2015-18 | Z29: 15
A30: 42192 | D30: 1 | F30: 1100 | G30: 1 | H30: 200 | I30: 1 | J30: 175 | L30: 1 | N30: 150 | W30: =(D30*F30)+(G30*H30)+(I30*J30)+(K30*L30)+(M30*N30) -> 1475 | X30: =(W30*5%) -> 73.75 | Y30: 2015-18 | Z30: 15
A31: 42193 | D31: 1 | F31: 1100 | G31: 1 | H31: 200 | I31: 1 | J31: 175 | L31: 1 | N31: 150 | W31: =(D31*F31)+(G31*H31)+(I31*J31)+(K31*L31)+(M31*N31) -> 1475 | X31: =(W31*5%) -> 73.75 | Y31: 2015-18 | Z31: 15
A32: 42194 | D32: 1 | F32: 1100 | G32: 1 | H32: 200 | I32: 1 | J32: 175 | L32: 1 | N32: 150 | W32: =(D32*F32)+(G32*H32)+(I32*J32)+(K32*L32)+(M32*N32) -> 1475 | X32: =(W32*5%) -> 73.75 | Y32: 2015-18 | Z32: 15
A33: 42195 | D33: 1 | F33: 1100 | G33: 1 | H33: 200 | I33: 1 | J33: 175 | L33: 1 | N33: 150 | W33: =(D33*F33)+(G33*H33)+(I33*J33)+(K33*L33)+(M33*N33) -> 1475 | X33: =(W33*5%) -> 73.75 | Y33: 2015-18 | Z33: 15
A34: 42196 | D34: 1 | F34: 1100 | G34: 1 | H34: 200 | I34: 1 | J34: 175 | L34: 1 | N34: 150 | W34: =(D34*F34)+(G34*H34)+(I34*J34)+(K34*L34)+(M34*N34) -> 1475 | X34: =(W34*5%) -> 73.75 | Y34: 2015-18 | Z34: 15
A35: 42197 | F35: 1100 | H35: 200 | I35: 1 | J35: 175 | L35: 1 | N35: 150 | W35: =(D35*F35)+(G35*H35)+(I35*J35)+(K35*L35)+(M35*N35) -> 175 | X35: =(W35*5%) -> 8.75 | Y35: 2015-18 | Z35: 15
A36: 42198 | F36: 1100 | H36: 200 | I36: 1 | J36: 175 | L36: 1 | N36: 150 | W36: =(D36*F36)+(G36*H36)+(I36*J36)+(K36*L36)+(M36*N36) -> 175 | X36: =(W36*5%) -> 8.75 | Y36: 2015-18 | Z36: 15
A37: 42199 | F37: 1100 | H37: 200 | I37: 1 | J37: 175 | L37: 1 | N37: 150 | W37: =(D37*F37)+(G37*H37)+(I37*J37)+(K37*L37)+(M37*N37) -> 175 | X37: =(W37*5%) -> 8.75 | Y37: 2015-18 | Z37: 15
A38: 42200 | D38: 1 | F38: 1100 | G38: 1 | H38: 200 | I38: 1 | J38: 175 | L38: 1 | N38: 150 | W38: =(D38*F38)+(G38*H38)+(I38*J38)+(K38*L38)+(M38*N38) -> 1475 | X38: =(W38*5%) -> 73.75 | Y38: 2015-18 | Z38: 15 | AA38: =SUM(W24:W54) -> 34025
A39: 42201 | D39: 1 | F39: 1100 | G39: 1 | H39: 200 | I39: 1 | J39: 175 | L39: 1 | N39: 150 | W39: =(D39*F39)+(G39*H39)+(I39*J39)+(K39*L39)+(M39*N39) -> 1475 | X39: =(W39*5%) -> 73.75 | Y39: =SUM(W39+X39) -> 1548.75 | Z39: 15
A40: 42202 | F40: 1100 | H40: 200 | I40: 1 | J40: 175 | L40: 1 | N40: 150 | W40: =(D40*F40)+(G40*H40)+(I40*J40)+(K40*L40)+(M40*N40) -> 175 | X40: =(W40*5%) -> 8.75 | Y40: =SUM(W40+X40) -> 183.75 | Z40: 15
A41: 42203 | C41: 425 | F41: 1100 | H41: 200 | I41: 1 | J41: 175 | L41: 1 | N41: 150 | W41: =(D41*F41)+(G41*H41)+(I41*J41)+(K41*L41)+(M41*N41) -> 175 | X41: =(W41*5%) -> 8.75 | Y41: =SUM(W41+X41) -> 183.75 | Z41: 15
A42: 42204 | C42: 426 | F42: 1100 | H42: 200 | I42: 1 | J42: 175 | L42: 1 | N42: 150 | W42: =(D42*F42)+(G42*H42)+(I42*J42)+(K42*L42)+(M42*N42) -> 175 | X42: =(W42*5%) -> 8.75 | Y42: =SUM(W42+X42) -> 183.75 | Z42: 15
A43: 42205 | C43: 427 | D43: 1 | F43: 1100 | G43: 1 | H43: 200 | I43: 1 | J43: 175 | L43: 1 | N43: 150 | W43: =(D43*F43)+(G43*H43)+(I43*J43)+(K43*L43)+(M43*N43) -> 1475 | X43: =(W43*5%) -> 73.75 | Y43: =SUM(W43+X43) -> 1548.75 | Z43: 15
A44: 42206 | C44: 427 | D44: 1 | F44: 1100 | G44: 1 | H44: 200 | I44: 1 | J44: 175 | L44: 1 | N44: 150 | W44: =(D44*F44)+(G44*H44)+(I44*J44)+(K44*L44)+(M44*N44) -> 1475 | X44: =(W44*5%) -> 73.75 | Y44: =SUM(W44+X44) -> 1548.75 | Z44: 15
A45: 42207 | C45: 427 | D45: 1 | F45: 1100 | G45: 1 | H45: 200 | I45: 1 | J45: 175 | L45: 1 | N45: 150 | W45: =(D45*F45)+(G45*H45)+(I45*J45)+(K45*L45)+(M45*N45) -> 1475 | X45: =(W45*5%) -> 73.75 | Y45: =SUM(W45+X45) -> 1548.75 | Z45: 15
A46: 42208 | C46: 427 | D46: 1 | F46: 1100 | G46: 1 | H46: 200 | I46: 1 | J46: 175 | L46: 1 | N46: 150 | W46: =(D46*F46)+(G46*H46)+(I46*J46)+(K46*L46)+(M46*N46) -> 1475 | X46: =(W46*5%) -> 73.75 | Y46: =SUM(W46+X46) -> 1548.75 | Z46: 15
...

Sheet Vendor #8
A2: Vendor #8
A4: Date | B4: Straight Hours Charged (ea.) | C4: Overtime Hours Charged (ea.) | D4: Vendor #8 | E4: Rate | F4: Vehicle | G4: Rate $200 | H4: Quad | I4: Rate $150 | J4: KM Over 180 | K4: Rate $1.00 | L4: Sub | M4: Rate $200 | N4: Labourer class | O4: Rate | P4: Labourer class | Q4: Rate | R4: Total Labour Rate per hr | S4: Total Hours Charged | T4: Equipment Detail | U4: Km's Charged | V4: Subtotal | W4: GST | X4: LEM Amount | Y4: Affiliating Invoice | Z4: Approved By | AA4: SUM OF ALL LEM'S (before GST)
AA5: =SUM(V6:V174) -> 193842
A6: 42124 | E6: 0 | G6: 0 | I6: 0 | K6: 0 | M6: 0 | O6: 0 | Q6: 0 | R6: =SUM(K6,I6,G6,E6) -> 0 | S6: =(B6+C6)*D6 -> 0 | T6: Invoice from April 16-30 | V6: 1360 | W6: =(V6*5%) -> 68 | X6: =SUM(V6+W6) -> 1428 | Y6: 2015-10
A7: 42139 | E7: 0 | G7: 0 | I7: 0 | K7: 0 | M7: 0 | O7: 0 | Q7: 0 | R7: =SUM(K7,I7,G7,E7) -> 0 | S7: =(B7+C7)*D7 -> 0 | T7: Invoice from May 1-15 | V7: 2980 | W7: =(V7*5%) -> 149 | X7: =V7+W7 -> 3129 | Y7: 2015-12
A8: 42155 | E8: 0 | G8: 0 | I8: 0 | K8: 0 | M8: 0 | O8: 0 | Q8: 0 | R8: =SUM(K8,I8,G8,E8) -> 0 | S8: =(B8+C8)*D8 -> 0 | T8: Invoice from May 16-31 | V8: 9400 | W8: =(V8*5%) -> 470 | X8: =SUM(V8+W8) -> 9870 | Y8: 2015-14
A9: 42156 | B9: 12 | C9: 0 | D9: 1 | E9: 1100 | F9: 1 | G9: 200 | I9: 150 | K9: 1 | L9: 1 | M9: 200 | O9: 0 | Q9: 0 | R9: =SUM(U9,I9,G9,E9) -> 1450 | S9: =(B9+C9)*D9 -> 12 | U9: =K9*J9 -> 0 | V9: =(D9*E9)+(F9*G9)+(H9*I9)+(J9*K9)+(L9*M9) -> 1500 | W9: =(V9*5%) -> 75 | X9: =SUM(V9+W9) -> 1575 | Y9: 2015-15
A10: 42157 | B10: 12 | C10: 0 | D10: 0.5 | E10: 1100 | F10: 0.5 | G10: 200 | I10: 150 | K10: 1 | L10: 1 | M10: 200 | O10: 0 | Q10: 0 | R10: =SUM(K10,I10,G10,E10) -> 1451 | S10: =(B10+C10)*D10 -> 6 | U10: =K10*J10 -> 0 | V10: =(D10*E10)+(F10*G10)+(H10*I10)+(J10*K10)+(L10*M10) -> 850 | W10: =(V10*5%) -> 42.5 | X10: =SUM(V10+W10) -> 892.5 | Y10: 2015-15
A11: 42158 | B11: 12 | C11: 0 | E11: 1100 | G11: 200 | I11: 150 | K11: 1 | L11: 1 | M11: 200 | O11: 0 | Q11: 0 | R11: =SUM(K11,I11,G11,E11) -> 1451 | S11: =(B11+C11)*D11 -> 0 | U11: =K11*J11 -> 0 | V11: =(D11*E11)+(F11*G11)+(H11*I11)+(J11*K11)+(L11*M11) -> 200 | W11: =(V11*5%) -> 10 | X11: =SUM(V11+W11) -> 210 | Y11: 2015-15
A12: 42159 | B12: 12 | C12: 0 | E12: 1100 | G12: 200 | I12: 150 | K12: 1 | L12: 1 | M12: 200 | O12: 0 | Q12: 0 | R12: =SUM(K12,I12,G12,E12) -> 1451 | S12: =(B12+C12)*D12 -> 0 | U12: =K12*J12 -> 0 | V12: =(D12*E12)+(F12*G12)+(H12*I12)+(J12*K12)+(L12*M12) -> 200 | W12: =(V12*5%) -> 10 | X12: =SUM(V12+W12) -> 210 | Y12: 2015-15
A13: 42160 | B13: 12 | C13: 0 | D13: 1 | E13: 1100 | F13: 1 | G13: 200 | I13: 150 | K13: 1 | L13: 1 | M13: 200 | O13: 0 | Q13: 0 | R13: =SUM(K13,I13,G13,E13) -> 1451 | S13: =(B13+C13)*D13 -> 12 | U13: =K13*J13 -> 0 | V13: =(D13*E13)+(F13*G13)+(H13*I13)+(J13*K13)+(L13*M13) -> 1500 | W13: =(V13*5%) -> 75 | X13: =SUM(V13+W13) -> 1575 | Y13: 2015-15
A14: 42163 | B14: 12 | C14: 0 | D14: 1 | E14: 1100 | F14: 1 | G14: 200 | I14: 150 | K14: 1 | L14: 1 | M14: 200 | O14: 0 | Q14: 0 | R14: =SUM(K14,I14,G14,E14) -> 1451 | S14: =(B14+C14)*D14 -> 12 | U14: =K14*J14 -> 0 | V14: =(D14*E14)+(F14*G14)+(H14*I14)+(J14*K14)+(L14*M14) -> 1500 | W14: =(V14*5%) -> 75 | X14: =SUM(V14+W14) -> 1575 | Y14: 2015-15
A15: 42164 | B15: 12 | C15: 0 | D15: 1 | E15: 1100 | F15: 1 | G15: 200 | I15: 150 | K15: 1 | L15: 1 | M15: 200 | O15: 0 | Q15: 0 | R15: =SUM(K15,I15,G15,E15) -> 1451 | S15: =(B15+C15)*D15 -> 12 | U15: =K15*J15 -> 0 | V15: =(D15*E15)+(F15*G15)+(H15*I15)+(J15*K15)+(L15*M15) -> 1500 | W15: =(V15*5%) -> 75 | X15: =SUM(V15+W15) -> 1575 | Y15: 2015-15 | Z15: =SUM(V9:V21) -> 14300
A16: 42165 | D16: 1 | E16: 1100 | F16: 1 | G16: 200 | I16: 150 | K16: 1 | L16: 1 | M16: 200 | O16: 0 | Q16: 0 | R16: =SUM(K16,I16,G16,E16) -> 1451 | S16: =(B16+C16)*D16 -> 0 | U16: =K16*J16 -> 0 | V16: =(D16*E16)+(F16*G16)+(H16*I16)+(J16*K16)+(L16*M16) -> 1500 | W16: =(V16*5%) -> 75 | X16: =SUM(V16+W16) -> 1575 | Y16: 2015-15
A17: 42166 | D17: 0.5 | E17: 1100 | F17: 0.5 | G17: 200 | I17: 150 | K17: 1 | L17: 1 | M17: 200 | O17: 0 | Q17: 0 | R17: =SUM(K17,I17,G17,E17) -> 1451 | S17: =(B17+C17)*D17 -> 0 | U17: =K17*J17 -> 0 | V17: =(D17*E17)+(F17*G17)+(H17*I17)+(J17*K17)+(L17*M17) -> 850 | W17: =(V17*5%) -> 42.5 | X17: =SUM(V17+W17) -> 892.5 | Y17: 2015-15
A18: 42167 | D18: 1 | E18: 1100 | F18: 1 | G18: 200 | I18: 150 | K18: 1 | L18: 1 | M18: 200 | O18: 0 | Q18: 0 | R18: =SUM(K18,I18,G18,E18) -> 1451 | S18: =(B18+C18)*D18 -> 0 | U18: =K18*J18 -> 0 | V18: =(D18*E18)+(F18*G18)+(H18*I18)+(J18*K18)+(L18*M18) -> 1500 | W18: =(V18*5%) -> 75 | X18: =SUM(V18+W18) -> 1575 | Y18: 2015-15
A19: 42168 | D19: 1 | E19: 1100 | F19: 1 | G19: 200 | I19: 150 | K19: 1 | L19: 1 | M19: 200 | O19: 0 | Q19: 0 | R19: =SUM(K19,I19,G19,E19) -> 1451 | S19: =(B19+C19)*D19 -> 0 | U19: =K19*J19 -> 0 | V19: =(D19*E19)+(F19*G19)+(H19*I19)+(J19*K19)+(L19*M19) -> 1500 | W19: =(V19*5%) -> 75 | X19: =SUM(V19+W19) -> 1575 | Y19: 2015-15
A20: 42169 | E20: 1100 | G20: 200 | I20: 150 | K20: 1 | L20: 1 | M20: 200 | O20: 0 | Q20: 0 | R20: =SUM(K20,I20,G20,E20) -> 1451 | S20: =(B20+C20)*D20 -> 0 | U20: =K20*J20 -> 0 | V20: =(D20*E20)+(F20*G20)+(H20*I20)+(J20*K20)+(L20*M20) -> 200 | W20: =(V20*5%) -> 10 | X20: =SUM(V20+W20) -> 210 | Y20: 2015-15
A21: 42170 | D21: 1 | E21: 1100 | F21: 1 | G21: 200 | I21: 150 | K21: 1 | L21: 1 | M21: 200 | O21: 0 | Q21: 0 | R21: =SUM(K21,I21,G21,E21) -> 1451 | S21: =(B21+C21)*D21 -> 0 | U21: =K21*J21 -> 0 | V21: =(D21*E21)+(F21*G21)+(H21*I21)+(J21*K21)+(L21*M21) -> 1500 | W21: =(V21*5%) -> 75 | X21: =SUM(V21+W21) -> 1575 | Y21: 2015-15
A22: 42171 | D22: 1 | E22: 1100 | F22: 1 | G22: 200 | I22: 150 | K22: 1 | L22: 1 | M22: 200 | O22: 0 | Q22: 0 | R22: =SUM(K22,I22,G22,E22) -> 1451 | S22: =(B22+C22)*D22 -> 0 | U22: =K22*J22 -> 0 | V22: =(D22*E22)+(F22*G22)+(H22*I22)+(J22*K22)+(L22*M22) -> 1500 | W22: =(V22*5%) -> 75 | X22: =SUM(V22+W22) -> 1575 | Y22: 2015-17
A23: 42172 | D23: 1 | E23: 1100 | F23: 1 | G23: 200 | H23: 1 | I23: 150 | K23: 1 | L23: 1 | M23: 200 | O23: 0 | Q23: 0 | R23: =SUM(K23,I23,G23,E23) -> 1451 | S23: =(B23+C23)*D23 -> 0 | U23: =K23*J23 -> 0 | V23: =(D23*E23)+(F23*G23)+(H23*I23)+(J23*K23)+(L23*M23) -> 1650 | W23: =(V23*5%) -> 82.5 | X23: =SUM(V23+W23) -> 1732.5 | Y23: 2015-17
A24: 42173 | D24: 1 | E24: 1100 | F24: 1 | G24: 200 | H24: 1 | I24: 150 | K24: 1 | L24: 1 | M24: 200 | O24: 0 | Q24: 0 | R24: =SUM(K24,I24,G24,E24) -> 1451 | S24: =(B24+C24)*D24 -> 0 | U24: =K24*J24 -> 0 | V24: =(D24*E24)+(F24*G24)+(H24*I24)+(J24*K24)+(L24*M24) -> 1650 | W24: =(V24*5%) -> 82.5 | X24: =SUM(V24+W24) -> 1732.5 | Y24: 2015-17 | Z24: =SUM(V22:V36) -> 19050
A25: 42174 | D25: 1 | E25: 1100 | F25: 1 | G25: 200 | I25: 150 | K25: 1 | L25: 1 | M25: 200 | O25: 0 | Q25: 0 | R25: =SUM(K25,I25,G25,E25) -> 1451 | S25: =(B25+C25)*D25 -> 0 | U25: =K25*J25 -> 0 | V25: =(D25*E25)+(F25*G25)+(H25*I25)+(J25*K25)+(L25*M25) -> 1500 | W25: =(V25*5%) -> 75 | X25: =SUM(V25+W25) -> 1575 | Y25: 2015-17
A26: 42175 | D26: 0.5 | E26: 1100 | F26: 0.5 | G26: 200 | I26: 150 | K26: 1 | L26: 1 | M26: 200 | O26: 0 | Q26: 0 | R26: =SUM(K26,I26,G26,E26) -> 1451 | S26: =(B26+C26)*D26 -> 0 | U26: =K26*J26 -> 0 | V26: =(D26*E26)+(F26*G26)+(H26*I26)+(J26*K26)+(L26*M26) -> 850 | W26: =(V26*5%) -> 42.5 | X26: =SUM(V26+W26) -> 892.5 | Y26: 2015-17
A27: 42176 | E27: 1100 | G27: 200 | I27: 150 | K27: 1 | L27: 1 | M27: 200 | O27: 0 | Q27: 0 | R27: =SUM(K27,I27,G27,E27) -> 1451 | S27: =(B27+C27)*D27 -> 0 | U27: =K27*J27 -> 0 | V27: =(D27*E27)+(F27*G27)+(H27*I27)+(J27*K27)+(L27*M27) -> 200 | W27: =(V27*5%) -> 10 | X27: =SUM(V27+W27) -> 210 | Y27: 2015-17
A28: 42177 | D28: 1 | E28: 1100 | F28: 1 | G28: 200 | H28: 1 | I28: 150 | K28: 1 | L28: 1 | M28: 200 | O28: 0 | Q28: 0 | R28: =SUM(K28,I28,G28,E28) -> 1451 | S28: =(B28+C28)*D28 -> 0 | U28: =K28*J28 -> 0 | V28: =(D28*E28)+(F28*G28)+(H28*I28)+(J28*K28)+(L28*M28) -> 1650 | W28: =(V28*5%) -> 82.5 | X28: =SUM(V28+W28) -> 1732.5 | Y28: 2015-17
A29: 42178 | D29: 1 | E29: 1100 | F29: 1 | G29: 200 | I29: 150 | K29: 1 | L29: 1 | M29: 200 | O29: 0 | Q29: 0 | R29: =SUM(K29,I29,G29,E29) -> 1451 | S29: =(B29+C29)*D29 -> 0 | U29: =K29*J29 -> 0 | V29: =(D29*E29)+(F29*G29)+(H29*I29)+(J29*K29)+(L29*M29) -> 1500 | W29: =(V29*5%) -> 75 | X29: =SUM(V29+W29) -> 1575 | Y29: 2015-17
A30: 42179 | D30: 1 | E30: 1100 | F30: 1 | G30: 200 | I30: 150 | K30: 1 | L30: 1 | M30: 200 | O30: 0 | Q30: 0 | R30: =SUM(K30,I30,G30,E30) -> 1451 | S30: =(B30+C30)*D30 -> 0 | U30: =K30*J30 -> 0 | V30: =(D30*E30)+(F30*G30)+(H30*I30)+(J30*K30)+(L30*M30) -> 1500 | W30: =(V30*5%) -> 75 | X30: =SUM(V30+W30) -> 1575 | Y30: 2015-17
A31: 42180 | D31: 1 | E31: 1100 | F31: 1 | G31: 200 | I31: 150 | K31: 1 | L31: 1 | M31: 200 | O31: 0 | Q31: 0 | R31: =SUM(K31,I31,G31,E31) -> 1451 | S31: =(B31+C31)*D31 -> 0 | U31: =K31*J31 -> 0 | V31: =(D31*E31)+(F31*G31)+(H31*I31)+(J31*K31)+(L31*M31) -> 1500 | W31: =(V31*5%) -> 75 | X31: =SUM(V31+W31) -> 1575 | Y31: 2015-17
A32: 42181 | D32: 0.5 | E32: 1100 | F32: .5 | G32: 200 | I32: 150 | K32: 1 | L32: 1 | M32: 200 | O32: 0 | Q32: 0 | R32: =SUM(K32,I32,G32,E32) -> 1451 | S32: =(B32+C32)*D32 -> 0 | U32: =K32*J32 -> 0 | V32: =(D32*E32)+(F32*G32)+(H32*I32)+(J32*K32)+(L32*M32) -> 850 | W32: =(V32*5%) -> 42.5 | X32: =SUM(V32+W32) -> 892.5 | Y32: 2015-17
A33: 42182 | D33: 1 | E33: 1100 | F33: 1 | G33: 200 | I33: 150 | K33: 1 | L33: 1 | M33: 200 | O33: 0 | Q33: 0 | R33: =SUM(K33,I33,G33,E33) -> 1451 | S33: =(B33+C33)*D33 -> 0 | U33: =K33*J33 -> 0 | V33: =(D33*E33)+(F33*G33)+(H33*I33)+(J33*K33)+(L33*M33) -> 1500 | W33: =(V33*5%) -> 75 | X33: =SUM(V33+W33) -> 1575 | Y33: 2015-17
A34: 42183 | E34: 1100 | G34: 200 | I34: 150 | K34: 1 | L34: 1 | M34: 200 | O34: 0 | Q34: 0 | R34: =SUM(K34,I34,G34,E34) -> 1451 | S34: =(B34+C34)*D34 -> 0 | U34: =K34*J34 -> 0 | V34: =(D34*E34)+(F34*G34)+(H34*I34)+(J34*K34)+(L34*M34) -> 200 | W34: =(V34*5%) -> 10 | X34: =SUM(V34+W34) -> 210 | Y34: 2015-17
A35: 42184 | D35: 1 | E35: 1100 | F35: 1 | G35: 200 | I35: 150 | K35: 1 | L35: 1 | M35: 200 | O35: 0 | Q35: 0 | R35: =SUM(K35,I35,G35,E35) -> 1451 | S35: =(B35+C35)*D35 -> 0 | U35: =K35*J35 -> 0 | V35: =(D35*E35)+(F35*G35)+(H35*I35)+(J35*K35)+(L35*M35) -> 1500 | W35: =(V35*5%) -> 75 | X35: =SUM(V35+W35) -> 1575 | Y35: 2015-17
A36: 42185 | D36: 1 | E36: 1100 | F36: 1 | G36: 200 | I36: 150 | K36: 1 | L36: 1 | M36: 200 | O36: 0 | Q36: 0 | R36: =SUM(K36,I36,G36,E36) -> 1451 | S36: =(B36+C36)*D36 -> 0 | U36: =K36*J36 -> 0 | V36: =(D36*E36)+(F36*G36)+(H36*I36)+(J36*K36)+(L36*M36) -> 1500 | W36: =(V36*5%) -> 75 | X36: =SUM(V36+W36) -> 1575 | Y36: 2015-17
A37: 42186 | D37: 1 | E37: 1100 | F37: 1 | G37: 200 | I37: 150 | K37: 1 | L37: 1 | M37: 200 | O37: 0 | Q37: 0 | R37: =SUM(K37,I37,G37,E37) -> 1451 | S37: =(B37+C37)*D37 -> 0 | U37: =K37*J37 -> 0 | V37: =(D37*E37)+(F37*G37)+(H37*I37)+(J37*K37)+(L37*M37) -> 1500 | W37: =(V37*5%) -> 75 | X37: =SUM(V37+W37) -> 1575 | Y37: 2015-18
A38: 42187 | D38: 1 | E38: 1100 | F38: 1 | G38: 200 | I38: 150 | K38: 1 | L38: 1 | M38: 200 | O38: 0 | Q38: 0 | R38: =SUM(K38,I38,G38,E38) -> 1451 | S38: =(B38+C38)*D38 -> 0 | U38: =K38*J38 -> 0 | V38: =(D38*E38)+(F38*G38)+(H38*I38)+(J38*K38)+(L38*M38) -> 1500 | W38: =(V38*5%) -> 75 | X38: =SUM(V38+W38) -> 1575 | Y38: 2015-18
A39: 42188 | D39: 1 | E39: 1100 | F39: 1 | G39: 200 | I39: 150 | K39: 1 | L39: 1 | M39: 200 | O39: 0 | Q39: 0 | R39: =SUM(K39,I39,G39,E39) -> 1451 | S39: =(B39+C39)*D39 -> 0 | U39: =K39*J39 -> 0 | V39: =(D39*E39)+(F39*G39)+(H39*I39)+(J39*K39)+(L39*M39) -> 1500 | W39: =(V39*5%) -> 75 | X39: =SUM(V39+W39) -> 1575 | Y39: 2015-18
A40: 42189 | D40: 1 | E40: 1100 | F40: 1 | G40: 200 | I40: 150 | K40: 1 | L40: 1 | M40: 200 | O40: 0 | Q40: 0 | R40: =SUM(K40,I40,G40,E40) -> 1451 | S40: =(B40+C40)*D40 -> 0 | U40: =K40*J40 -> 0 | V40: =(D40*E40)+(F40*G40)+(H40*I40)+(J40*K40)+(L40*M40) -> 1500 | W40: =(V40*5%) -> 75 | X40: =SUM(V40+W40) -> 1575 | Y40: 2015-18
A41: 42190 | E41: 1100 | G41: 200 | L41: 1 | M41: 200 | O41: 0 | Q41: 0 | R41: =SUM(K41,I41,G41,E41) -> 1300 | S41: =(B41+C41)*D41 -> 0 | U41: =K41*J41 -> 0 | V41: =(D41*E41)+(F41*G41)+(H41*I41)+(J41*K41)+(L41*M41) -> 200 | W41: =(V41*5%) -> 10 | X41: =SUM(V41+W41) -> 210 | Y41: 2015-18
A42: 42191 | D42: 1 | E42: 1100 | F42: 1 | G42: 200 | I42: 150 | K42: 1 | L42: 1 | M42: 200 | O42: 0 | Q42: 0 | R42: =SUM(K42,I42,G42,E42) -> 1451 | S42: =(B42+C42)*D42 -> 0 | U42: =K42*J42 -> 0 | V42: =(D42*E42)+(F42*G42)+(H42*I42)+(J42*K42)+(L42*M42) -> 1500 | W42: =(V42*5%) -> 75 | X42: =SUM(V42+W42) -> 1575 | Y42: 2015-18
...

Sheet Vendor #11
A2: Vendor #11
A4: Date | B4: Straight Hours Charged (ea.) | C4: Overtime Hours Charged (ea.) | D4: Vendor #11 | E4: Rate | F4: Truck | G4: Rate | H4: Km over 200 | I4: Rate | J4: Sub | K4: Rate | L4: Labourer class | M4: Rate | N4: Labourer class | O4: Rate | P4: Labourer class | Q4: Rate | R4: Total Labour Rate per hr | S4: Total Hours Charged | T4: Equipment Detail | U4: Km's Charged | V4: Subtotal | W4: GST | X4: LEM Amount | Y4: Affiliating Invoice | Z4: Approved By | AA4: SUM OF ALL LEM'S (before GST)
AA5: =SUM(V6:V221) -> 195250
A6: May 1-31 | E6: 1100 | G6: 200 | I6: 1 | K6: 175 | M6: 0 | O6: 0 | Q6: 0 | V6: 11250 | W6: =(V6*5%) -> 562.5 | X6: =SUM(V6+W6) -> 11812.5 | Y6: 48
A7: 42156 | B7: 1 | D7: 1 | E7: 1100 | F7: 1 | G7: 200 | I7: 1 | K7: 175 | M7: 0 | O7: 0 | Q7: 0 | R7: =(B7*#REF!)+(D7*E7)+(F7*G7) -> #REF! | U7: =H7*I7 -> 0 | V7: =(D7*E7)+(F7*G7)+(H7*I7)+(J7*K7) -> 1300 | W7: =(V7*5%) -> 65 | X7: =SUM(V7+W7) -> 1365 | Y7: 49
A8: 42157 | B8: 1 | D8: 1 | E8: 1100 | F8: 1 | G8: 200 | I8: 1 | K8: 175 | M8: 0 | O8: 0 | Q8: 0 | R8: =(B8*#REF!)+(D8*E8)+(F8*G8) -> #REF! | U8: =H8*I8 -> 0 | V8: =(D8*E8)+(F8*G8)+(H8*I8)+(J8*K8) -> 1300 | W8: =(V8*5%) -> 65 | X8: =SUM(V8+W8) -> 1365 | Y8: 49
A9: 42158 | B9: 1 | D9: 1 | E9: 1100 | F9: 1 | G9: 200 | I9: 1 | K9: 175 | M9: 0 | O9: 0 | Q9: 0 | R9: =(B9*#REF!)+(D9*E9)+(F9*G9) -> #REF! | U9: =H9*I9 -> 0 | V9: =(D9*E9)+(F9*G9)+(H9*I9)+(J9*K9) -> 1300 | W9: =(V9*5%) -> 65 | X9: =SUM(V9+W9) -> 1365 | Y9: 49
A10: 42159 | B10: 1 | D10: 1 | E10: 1100 | F10: 1 | G10: 200 | I10: 1 | K10: 175 | M10: 0 | O10: 0 | Q10: 0 | R10: =(B10*#REF!)+(D10*E10)+(F10*G10) -> #REF! | U10: =H10*I10 -> 0 | V10: =(D10*E10)+(F10*G10)+(H10*I10)+(J10*K10) -> 1300 | W10: =(V10*5%) -> 65 | X10: =SUM(V10+W10) -> 1365 | Y10: 49
A11: 42160 | B11: 1 | D11: 1 | E11: 1100 | F11: 1 | G11: 200 | I11: 1 | K11: 175 | M11: 0 | O11: 0 | Q11: 0 | R11: =(B11*#REF!)+(D11*E11)+(F11*G11) -> #REF! | U11: =H11*I11 -> 0 | V11: =(D11*E11)+(F11*G11)+(H11*I11)+(J11*K11) -> 1300 | W11: =(V11*5%) -> 65 | X11: =SUM(V11+W11) -> 1365 | Y11: 49
A12: 42161 | D12: 1 | E12: 1100 | F12: 1 | G12: 200 | I12: 1 | K12: 175 | U12: =H12*I12 -> 0 | V12: =(D12*E12)+(F12*G12)+(H12*I12)+(J12*K12) -> 1300 | W12: =(V12*5%) -> 65 | X12: =SUM(V12+W12) -> 1365 | Y12: 49
A13: 42162 | E13: 1100 | G13: 200 | I13: 1 | J13: 1 | K13: 175 | U13: =H13*I13 -> 0 | V13: =(D13*E13)+(F13*G13)+(H13*I13)+(J13*K13) -> 175 | W13: =(V13*5%) -> 8.75 | X13: =SUM(V13+W13) -> 183.75 | Y13: 49
A14: 42163 | B14: 1 | D14: 1 | E14: 1100 | F14: 1 | G14: 200 | I14: 1 | J14: 1 | K14: 175 | M14: 0 | O14: 0 | Q14: 0 | R14: =(B14*#REF!)+(D14*E14)+(F14*G14) -> #REF! | U14: =H14*I14 -> 0 | V14: =(D14*E14)+(F14*G14)+(H14*I14)+(J14*K14) -> 1475 | W14: =(V14*5%) -> 73.75 | X14: =SUM(V14+W14) -> 1548.75 | Y14: 49
A15: 42164 | B15: 1 | D15: 1 | E15: 1100 | F15: 1 | G15: 200 | I15: 1 | J15: 1 | K15: 175 | M15: 0 | O15: 0 | Q15: 0 | R15: =(B15*#REF!)+(D15*E15)+(F15*G15) -> #REF! | U15: =H15*I15 -> 0 | V15: =(D15*E15)+(F15*G15)+(H15*I15)+(J15*K15) -> 1475 | W15: =(V15*5%) -> 73.75 | X15: =SUM(V15+W15) -> 1548.75 | Y15: 49
A16: 42165 | B16: 1 | D16: 1 | E16: 1100 | F16: 1 | G16: 200 | I16: 1 | J16: 1 | K16: 175 | M16: 0 | O16: 0 | Q16: 0 | R16: =(B16*#REF!)+(D16*E16)+(F16*G16) -> #REF! | U16: =H16*I16 -> 0 | V16: =(D16*E16)+(F16*G16)+(H16*I16)+(J16*K16) -> 1475 | W16: =(V16*5%) -> 73.75 | X16: =SUM(V16+W16) -> 1548.75 | Y16: 49
A17: 42166 | B17: 1 | D17: 1 | E17: 1100 | F17: 1 | G17: 200 | I17: 1 | J17: 1 | K17: 175 | M17: 0 | O17: 0 | Q17: 0 | R17: =(B17*#REF!)+(D17*E17)+(F17*G17) -> #REF! | U17: =H17*I17 -> 0 | V17: =(D17*E17)+(F17*G17)+(H17*I17)+(J17*K17) -> 1475 | W17: =(V17*5%) -> 73.75 | X17: =SUM(V17+W17) -> 1548.75 | Y17: 49
A18: 42167 | B18: 1 | D18: 1 | E18: 1100 | F18: 1 | G18: 200 | I18: 1 | J18: 1 | K18: 175 | M18: 0 | O18: 0 | Q18: 0 | R18: =(B18*#REF!)+(D18*E18)+(F18*G18) -> #REF! | U18: =H18*I18 -> 0 | V18: =(D18*E18)+(F18*G18)+(H18*I18)+(J18*K18) -> 1475 | W18: =(V18*5%) -> 73.75 | X18: =SUM(V18+W18) -> 1548.75 | Y18: 49
A19: 42168 | B19: 1 | D19: 1 | E19: 1100 | F19: 1 | G19: 200 | I19: 1 | J19: 1 | K19: 175 | M19: 0 | O19: 0 | Q19: 0 | R19: =(B19*#REF!)+(D19*E19)+(F19*G19) -> #REF! | U19: =H19*I19 -> 0 | V19: =(D19*E19)+(F19*G19)+(H19*I19)+(J19*K19) -> 1475 | W19: =(V19*5%) -> 73.75 | X19: =SUM(V19+W19) -> 1548.75 | Y19: 49
A20: 42169 | B20: 0 | E20: 1100 | G20: 200 | I20: 1 | J20: 1 | K20: 175 | M20: 0 | O20: 0 | Q20: 0 | R20: =(B20*#REF!)+(D20*E20)+(F20*G20) -> #REF! | U20: =H20*I20 -> 0 | V20: =(D20*E20)+(F20*G20)+(H20*I20)+(J20*K20) -> 175 | W20: =(V20*5%) -> 8.75 | X20: =SUM(V20+W20) -> 183.75 | Y20: 49
A21: 42170 | B21: 1 | D21: 1 | E21: 1100 | F21: 1 | G21: 200 | I21: 1 | J21: 1 | K21: 175 | M21: 0 | O21: 0 | Q21: 0 | R21: =(B21*#REF!)+(D21*E21)+(F21*G21) -> #REF! | U21: =H21*I21 -> 0 | V21: =(D21*E21)+(F21*G21)+(H21*I21)+(J21*K21) -> 1475 | W21: =(V21*5%) -> 73.75 | X21: =SUM(V21+W21) -> 1548.75 | Y21: 49
A22: 42171 | B22: 1 | D22: 1 | E22: 1100 | F22: 1 | G22: 200 | I22: 1 | J22: 1 | K22: 175 | M22: 0 | O22: 0 | Q22: 0 | R22: =(B22*#REF!)+(D22*E22)+(F22*G22) -> #REF! | U22: =H22*I22 -> 0 | V22: =(D22*E22)+(F22*G22)+(H22*I22)+(J22*K22) -> 1475 | W22: =(V22*5%) -> 73.75 | X22: =SUM(V22+W22) -> 1548.75 | Y22: 49
A23: 42172 | D23: 1 | E23: 1100 | F23: 1 | G23: 200 | I23: 1 | J23: 1 | K23: 175 | M23: 0 | O23: 0 | Q23: 0 | R23: =(B23*#REF!)+(D23*E23)+(F23*G23) -> #REF! | U23: =H23*I23 -> 0 | V23: =(D23*E23)+(F23*G23)+(H23*I23)+(J23*K23) -> 1475 | W23: =(V23*5%) -> 73.75 | X23: =SUM(V23+W23) -> 1548.75 | Y23: 49
A24: 42173 | D24: 1 | E24: 1100 | F24: 1 | G24: 200 | I24: 1 | J24: 1 | K24: 175 | M24: 0 | O24: 0 | Q24: 0 | R24: =(B24*#REF!)+(D24*E24)+(F24*G24) -> #REF! | U24: =H24*I24 -> 0 | V24: =(D24*E24)+(F24*G24)+(H24*I24)+(J24*K24) -> 1475 | W24: =(V24*5%) -> 73.75 | X24: =SUM(V24+W24) -> 1548.75 | Y24: 49
A25: 42174 | D25: 1 | E25: 1100 | F25: 1 | G25: 200 | I25: 1 | J25: 1 | K25: 175 | M25: 0 | O25: 0 | Q25: 0 | R25: =(B25*#REF!)+(D25*E25)+(F25*G25) -> #REF! | U25: =H25*I25 -> 0 | V25: =(D25*E25)+(F25*G25)+(H25*I25)+(J25*K25) -> 1475 | W25: =(V25*5%) -> 73.75 | X25: =SUM(V25+W25) -> 1548.75 | Y25: 49
A26: 42175 | D26: 1 | E26: 1100 | F26: 1 | G26: 200 | I26: 1 | J26: 1 | K26: 175 | M26: 0 | O26: 0 | Q26: 0 | R26: =(B26*#REF!)+(D26*E26)+(F26*G26) -> #REF! | U26: =H26*I26 -> 0 | V26: =(D26*E26)+(F26*G26)+(H26*I26)+(J26*K26) -> 1475 | W26: =(V26*5%) -> 73.75 | X26: =SUM(V26+W26) -> 1548.75 | Y26: 49
A27: 42176 | E27: 1100 | G27: 200 | I27: 1 | J27: 1 | K27: 175 | M27: 0 | O27: 0 | Q27: 0 | R27: =(B27*#REF!)+(D27*E27)+(F27*G27) -> #REF! | U27: =H27*I27 -> 0 | V27: =(D27*E27)+(F27*G27)+(H27*I27)+(J27*K27) -> 175 | W27: =(V27*5%) -> 8.75 | X27: =SUM(V27+W27) -> 183.75 | Y27: 49
A28: 42177 | D28: 1 | E28: 1100 | F28: 1 | G28: 200 | I28: 1 | J28: 1 | K28: 175 | M28: 0 | O28: 0 | Q28: 0 | R28: =(B28*#REF!)+(D28*E28)+(F28*G28) -> #REF! | U28: =H28*I28 -> 0 | V28: =(D28*E28)+(F28*G28)+(H28*I28)+(J28*K28) -> 1475 | W28: =(V28*5%) -> 73.75 | X28: =SUM(V28+W28) -> 1548.75 | Y28: 49
A29: 42178 | D29: 1 | E29: 1100 | F29: 1 | G29: 200 | I29: 1 | J29: 1 | K29: 175 | M29: 0 | O29: 0 | Q29: 0 | R29: =(B29*#REF!)+(D29*E29)+(F29*G29) -> #REF! | U29: =H29*I29 -> 0 | V29: =(D29*E29)+(F29*G29)+(H29*I29)+(J29*K29) -> 1475 | W29: =(V29*5%) -> 73.75 | X29: =SUM(V29+W29) -> 1548.75 | Y29: 49
A30: 42179 | D30: 1 | E30: 1100 | F30: 1 | G30: 200 | I30: 1 | J30: 1 | K30: 175 | M30: 0 | O30: 0 | Q30: 0 | R30: =(B30*#REF!)+(D30*E30)+(F30*G30) -> #REF! | U30: =H30*I30 -> 0 | V30: =(D30*E30)+(F30*G30)+(H30*I30)+(J30*K30) -> 1475 | W30: =(V30*5%) -> 73.75 | X30: =SUM(V30+W30) -> 1548.75 | Y30: 49
A31: 42180 | D31: 1 | E31: 1100 | F31: 1 | G31: 200 | I31: 1 | J31: 1 | K31: 175 | M31: 0 | O31: 0 | Q31: 0 | R31: =(B31*#REF!)+(D31*E31)+(F31*G31) -> #REF! | U31: =H31*I31 -> 0 | V31: =(D31*E31)+(F31*G31)+(H31*I31)+(J31*K31) -> 1475 | W31: =(V31*5%) -> 73.75 | X31: =SUM(V31+W31) -> 1548.75 | Y31: 49
A32: 42181 | D32: 1 | E32: 1100 | F32: 1 | G32: 200 | I32: 1 | J32: 1 | K32: 175 | M32: 0 | O32: 0 | Q32: 0 | R32: =(B32*#REF!)+(D32*E32)+(F32*G32) -> #REF! | U32: =H32*I32 -> 0 | V32: =(D32*E32)+(F32*G32)+(H32*I32)+(J32*K32) -> 1475 | W32: =(V32*5%) -> 73.75 | X32: =SUM(V32+W32) -> 1548.75 | Y32: 49
A33: 42182 | D33: 1 | E33: 1100 | F33: 1 | G33: 200 | I33: 1 | J33: 1 | K33: 175 | M33: 0 | O33: 0 | Q33: 0 | R33: =SUM(K33,I33,G33,E33) -> 1476 | U33: =H33*I33 -> 0 | V33: =(D33*E33)+(F33*G33)+(H33*I33)+(J33*K33) -> 1475 | W33: =(V33*5%) -> 73.75 | X33: =SUM(V33+W33) -> 1548.75 | Y33: 49
A34: 42183 | E34: 1100 | G34: 200 | I34: 1 | J34: 1 | K34: 175 | M34: 0 | O34: 0 | Q34: 0 | R34: =SUM(K34,I34,G34,E34) -> 1476 | U34: =H34*I34 -> 0 | V34: =(D34*E34)+(F34*G34)+(H34*I34)+(J34*K34) -> 175 | W34: =(V34*5%) -> 8.75 | X34: =SUM(V34+W34) -> 183.75 | Y34: 49
A35: 42184 | D35: 1 | E35: 1100 | F35: 1 | G35: 200 | I35: 1 | J35: 1 | K35: 175 | U35: =H35*I35 -> 0 | V35: =(D35*E35)+(F35*G35)+(H35*I35)+(J35*K35) -> 1475 | W35: =(V35*5%) -> 73.75 | X35: =SUM(V35+W35) -> 1548.75 | Y35: 49
A36: 42185 | D36: 1 | E36: 1100 | F36: 1 | G36: 200 | I36: 1 | J36: 1 | K36: 175 | U36: =H36*I36 -> 0 | V36: =(D36*E36)+(F36*G36)+(H36*I36)+(J36*K36) -> 1475 | W36: =(V36*5%) -> 73.75 | X36: =SUM(V36+W36) -> 1548.75 | Y36: 49
A37: 42186 | D37: 1 | E37: 1100 | F37: 1 | G37: 200 | I37: 1 | J37: 1 | K37: 175 | U37: =H37*I37 -> 0 | V37: =(D37*E37)+(F37*G37)+(H37*I37)+(J37*K37) -> 1475 | W37: =(V37*5%) -> 73.75 | X37: =SUM(V37+W37) -> 1548.75 | Y37: 50
A38: 42187 | D38: 1 | E38: 1100 | F38: 1 | G38: 200 | I38: 1 | J38: 1 | K38: 175 | U38: =H38*I38 -> 0 | V38: =(D38*E38)+(F38*G38)+(H38*I38)+(J38*K38) -> 1475 | W38: =(V38*5%) -> 73.75 | X38: =SUM(V38+W38) -> 1548.75 | Y38: 50
A39: 42188 | D39: 1 | E39: 1100 | F39: 1 | G39: 200 | I39: 1 | J39: 1 | K39: 175 | U39: =H39*I39 -> 0 | V39: =(D39*E39)+(F39*G39)+(H39*I39)+(J39*K39) -> 1475 | W39: =(V39*5%) -> 73.75 | X39: =SUM(V39+W39) -> 1548.75 | Y39: 50
A40: 42189 | D40: 1 | E40: 1100 | F40: 1 | G40: 200 | I40: 1 | J40: 1 | K40: 175 | U40: =H40*I40 -> 0 | V40: =(D40*E40)+(F40*G40)+(H40*I40)+(J40*K40) -> 1475 | W40: =(V40*5%) -> 73.75 | X40: =SUM(V40+W40) -> 1548.75 | Y40: 50
A41: 42190 | J41: 1 | K41: 175 | U41: =H41*I41 -> 0 | V41: =(D41*E41)+(F41*G41)+(H41*I41)+(J41*K41) -> 175 | W41: =(V41*5%) -> 8.75 | X41: =SUM(V41+W41) -> 183.75 | Y41: 50
A42: 42191 | D42: 1 | E42: 1100 | F42: 1 | G42: 200 | I42: 1 | J42: 1 | K42: 175 | V42: =(D42*E42)+(F42*G42)+(H42*I42)+(J42*K42) -> 1475 | W42: =(V42*5%) -> 73.75 | X42: =SUM(V42+W42) -> 1548.75 | Y42: 50
...

Sheet Vendor #12
A2: Vendor #12
A4: Date | B4: LEM # | C4: Straight Hours Charged (ea.) | D4: Manpower | E4: Admin | F4: Rate | G4: Lead | H4: Rate | I4: KM | J4: Rate | K4: Build Spreadsheet | L4: Rate | M4: Titles | N4: Rate | O4: Pad Prep $105 | P4: Rate | Q4: Land title spin $32 | R4: Total Hours Charged | S4: Equipment Detail | T4: Km's Charged | U4: Subtotal | V4: GST | W4: LEM Amount | X4: Affiliating Invoice | Y4: SUM OF ALL LEM'S (before GST)
Y5: =SUM(U6:U74) -> 18298
A6: 42145 | B6: 5581 | C6: 8 | F6: 75 | G6: 8 | H6: 105 | I6: 70 | J6: 1 | L6: 0 | N6: 0 | P6: 0 | R6: =C6*F6 -> 600 | T6: =I6*J6 -> 70 | U6: =(E6*F6)+(G6*H6)+(I6*J6)+(K6*L6) -> 910 | V6: =(U6*5%) -> 45.5 | W6: =SUM(U6+V6) -> 955.5 | X6: 1192
A7: 42146 | B7: 5582 | C7: 2 | F7: 75 | G7: 2 | H7: 105 | I7: 20 | J7: 1 | L7: 0 | N7: 0 | P7: 0 | Q7: =SUM(N7,L7,J7,F7) -> 76 | R7: =C7*F7 -> 150 | T7: =I7*J7 -> 20 | U7: =(E7*F7)+(G7*H7)+(I7*J7)+(K7*L7) -> 230 | V7: =(U7*5%) -> 11.5 | W7: =SUM(U7+V7) -> 241.5 | X7: 1192
A8: 42149 | B8: 5421 | C8: 2 | E8: 2 | F8: 75 | H8: 105 | I8: 0 | J8: 1 | K8: 0.5 | L8: 75 | N8: 0 | P8: 0 | Q8: =SUM(N8,L8,J8,F8) -> 151 | R8: =(C8*F8)+(K8*L8) -> 187.5 | T8: =I8*J8 -> 0 | U8: =(E8*F8)+(G8*H8)+(I8*J8)+(K8*L8) -> 187.5 | V8: =(U8*5%) -> 9.375 | W8: =SUM(U8+V8) -> 196.875 | X8: 1192
A9: 42149 | B9: 5584 | C9: 2 | F9: 75 | G9: 2 | H9: 105 | I9: 0 | J9: 1 | L9: 0 | N9: 0 | P9: 0 | Q9: =SUM(N9,L9,J9,F9) -> 76 | R9: =C9*F9 -> 150 | T9: =I9*J9 -> 0 | U9: =(E9*F9)+(G9*H9)+(I9*J9)+(K9*L9) -> 210 | V9: =(U9*5%) -> 10.5 | W9: =SUM(U9+V9) -> 220.5 | X9: 1192
A10: 42150 | B10: 5370 | C10: 6 | E10: 6 | F10: 75 | H10: 105 | I10: 0 | J10: 1 | L10: 75 | N10: 0 | P10: 0 | Q10: =SUM(N10,L10,J10,F10) -> 151 | R10: =(C10*F10)+(K10*L10) -> 450 | T10: =I10*J10 -> 0 | U10: =(E10*F10)+(G10*H10)+(I10*J10)+(K10*L10) -> 450 | V10: =(U10*5%) -> 22.5 | W10: =SUM(U10+V10) -> 472.5 | X10: 1192
A11: 42150 | B11: 5372 | C11: 1.5 | E11: 1.5 | F11: 75 | H11: 105 | I11: 0 | J11: 1 | L11: 75 | N11: 0 | P11: 0 | Q11: =SUM(N11,L11,J11,F11) -> 151 | R11: =(C11*F11)+(K11*L11) -> 112.5 | T11: =I11*J11 -> 0 | U11: =(E11*F11)+(G11*H11)+(I11*J11)+(K11*L11) -> 112.5 | V11: =(U11*5%) -> 5.625 | W11: =SUM(U11+V11) -> 118.125 | X11: 1192
A12: 42150 | B12: 5426 | C12: 3 | E12: 3 | F12: 75 | H12: 105 | J12: 1 | K12: 1.5 | L12: 75 | N12: 0 | P12: 0 | Q12: =SUM(N12,L12,J12,F12) -> 151 | R12: =(C12*F12)+(K12*L12) -> 337.5 | T12: =I12*J12 -> 0 | U12: =(E12*F12)+(G12*H12)+(I12*J12)+(K12*L12) -> 337.5 | V12: =(U12*5%) -> 16.875 | W12: =SUM(U12+V12) -> 354.375 | X12: 1192
A13: 42151 | B13: 5427 | C13: 6 | E13: 6 | F13: 75 | H13: 105 | J13: 1 | L13: 75 | N13: 0 | P13: 0 | Q13: =SUM(N13,L13,J13,F13) -> 151 | R13: =(C13*F13)+(K13*L13) -> 450 | T13: =I13*J13 -> 0 | U13: =(E13*F13)+(G13*H13)+(I13*J13)+(K13*L13) -> 450 | V13: =(U13*5%) -> 22.5 | W13: =SUM(U13+V13) -> 472.5 | X13: 1192
A14: 42151 | B14: 5590 | C14: 6 | F14: 75 | G14: 6 | H14: 105 | I14: 22 | J14: 1 | L14: 75 | N14: 0 | P14: 0 | Q14: =SUM(N14,L14,J14,F14) -> 151 | R14: =(C14*F14)+(K14*L14) -> 450 | T14: =I14*J14 -> 22 | U14: =(E14*F14)+(G14*H14)+(I14*J14)+(K14*L14) -> 652 | V14: =(U14*5%) -> 32.6 | W14: =SUM(U14+V14) -> 684.6 | X14: 1192
A15: 42152 | B15: 5375 | C15: 4 | E15: 4 | F15: 75 | H15: 105 | J15: 1 | L15: 75 | N15: 140 | P15: 0 | Q15: =SUM(N15,L15,J15,F15) -> 291 | R15: =(C15*F15)+(K15*L15) -> 300 | T15: =I15*J15 -> 0 | U15: =(E15*F15)+(G15*H15)+(I15*J15)+(K15*L15) -> 300 | V15: =(U15*5%) -> 15 | W15: =SUM(U15+V15) -> 315 | X15: 1192
A16: 42153 | B16: 5376 | C16: 1 | E16: 1 | F16: 75 | H16: 105 | J16: 1 | L16: 75 | N16: 140 | P16: 0 | Q16: =SUM(N16,L16,J16,F16) -> 291 | R16: =(C16*F16)+(K16*L16) -> 75 | T16: =I16*J16 -> 0 | U16: =(E16*F16)+(G16*H16)+(I16*J16)+(K16*L16) -> 75 | V16: =(U16*5%) -> 3.75 | W16: =SUM(U16+V16) -> 78.75 | X16: 1192
A17: 42156 | B17: 5378 | C17: 0.5 | E17: 0.5 | F17: 75 | H17: 105 | J17: 1 | L17: 75 | N17: 140 | P17: 0 | Q17: =SUM(N17,L17,J17,F17) -> 291 | R17: =(C17*F17)+(K17*L17) -> 37.5 | T17: =I17*J17 -> 0 | U17: =(E17*F17)+(G17*H17)+(I17*J17)+(K17*L17) -> 37.5 | V17: =(U17*5%) -> 1.875 | W17: =SUM(U17+V17) -> 39.375 | X17: 1192
A18: 42157 | B18: 5380 | C18: 2 | E18: 2 | F18: 75 | H18: 105 | J18: 1 | L18: 75 | N18: 140 | P18: 0 | Q18: =SUM(N18,L18,J18,F18) -> 291 | R18: =(C18*F18)+(K18*L18) -> 150 | T18: =I18*J18 -> 0 | U18: =(E18*F18)+(G18*H18)+(I18*J18)+(K18*L18) -> 150 | V18: =(U18*5%) -> 7.5 | W18: =SUM(U18+V18) -> 157.5 | X18: 1192
A19: 42160 | B19: 5383 | C19: 3 | E19: 3 | F19: 75 | H19: 105 | J19: 1 | L19: 75 | N19: 140 | P19: 0 | Q19: =SUM(N19,L19,J19,F19) -> 291 | R19: =(C19*F19)+(K19*L19) -> 225 | T19: =I19*J19 -> 0 | U19: =(E19*F19)+(G19*H19)+(I19*J19)+(K19*L19) -> 225 | V19: =(U19*5%) -> 11.25 | W19: =SUM(U19+V19) -> 236.25 | X19: 1192
A20: 42163 | B20: 5386 | C20: 2 | E20: 2 | F20: 75 | H20: 105 | J20: 1 | L20: 75 | N20: 140 | P20: 0 | Q20: =SUM(N20,L20,J20,F20) -> 291 | R20: =(C20*F20)+(K20*L20) -> 150 | T20: =I20*J20 -> 0 | U20: =(E20*F20)+(G20*H20)+(I20*J20)+(K20*L20) -> 150 | V20: =(U20*5%) -> 7.5 | W20: =SUM(U20+V20) -> 157.5 | X20: 1192
A21: 42163 | B21: 5604 | C21: 5 | F21: 75 | G21: 5 | H21: 105 | I21: 123 | J21: 1 | L21: 75 | N21: 140 | P21: 0 | Q21: =SUM(N21,L21,J21,F21) -> 291 | R21: =(C21*F21)+(K21*L21) -> 375 | T21: =I21*J21 -> 123 | U21: =(E21*F21)+(G21*H21)+(I21*J21)+(K21*L21) -> 648 | V21: =(U21*5%) -> 32.4 | W21: =SUM(U21+V21) -> 680.4 | X21: 1192
A22: 42164 | B22: 5606 | C22: 9 | F22: 75 | G22: 9 | H22: 105 | I22: 167 | J22: 1 | L22: 75 | N22: 140 | P22: 0 | Q22: =SUM(N22,L22,J22,F22) -> 291 | R22: =(C22*F22)+(K22*L22) -> 675 | T22: =I22*J22 -> 167 | U22: =(E22*F22)+(G22*H22)+(I22*J22)+(K22*L22) -> 1112 | V22: =(U22*5%) -> 55.6 | W22: =SUM(U22+V22) -> 1167.6 | X22: 1192
A23: 42165 | B23: 5608 | C23: 4 | F23: 75 | G23: 4 | H23: 105 | I23: 93 | J23: 1 | L23: 75 | N23: 140 | U23: =(E23*F23)+(G23*H23)+(I23*J23)+(K23*L23)+(M23*N23) -> 513 | V23: =(U23*5%) -> 25.65 | W23: =SUM(U23+V23) -> 538.65 | X23: 1205
A24: 42166 | B24: 5390 | C24: 4 | E24: 4 | F24: 75 | H24: 105 | J24: 1 | L24: 75 | N24: 140 | P24: 0 | Q24: =SUM(N24,L24,J24,F24) -> 291 | R24: =(C24*F24)+(K24*L24) -> 300 | T24: =I24*J24 -> 0 | U24: =(E24*F24)+(G24*H24)+(I24*J24)+(K24*L24) -> 300 | V24: =(U24*5%) -> 15 | W24: =SUM(U24+V24) -> 315 | X24: 1194
A25: 42167 | B25: 5387 | C25: 4 | E25: 1 | F25: 75 | H25: 105 | J25: 1 | K25: 3 | L25: 75 | N25: 140 | P25: 0 | Q25: =SUM(N25,L25,J25,F25) -> 291 | R25: =(C25*F25)+(K25*L25) -> 525 | T25: =I25*J25 -> 0 | U25: =(E25*F25)+(G25*H25)+(I25*J25)+(K25*L25) -> 300 | V25: =(U25*5%) -> 15 | W25: =SUM(U25+V25) -> 315 | X25: 1194
A26: 42167 | B26: 5444 | C26: 1 | E26: 1 | F26: 75 | H26: 105 | J26: 1 | L26: 75 | N26: 140 | P26: 0 | Q26: =SUM(N26,L26,J26,F26) -> 291 | R26: =(C26*F26)+(K26*L26) -> 75 | T26: =I26*J26 -> 0 | U26: =(E26*F26)+(G26*H26)+(I26*J26)+(K26*L26) -> 75 | V26: =(U26*5%) -> 3.75 | W26: =SUM(U26+V26) -> 78.75 | X26: 1194
A27: 42167 | B27: 5613 | C27: 1.5 | F27: 75 | G27: 1.5 | H27: 105 | I27: 11 | J27: 1 | L27: 75 | N27: 140 | U27: =(E27*F27)+(G27*H27)+(I27*J27)+(K27*L27)+(M27*N27) -> 168.5 | V27: =(U27*5%) -> 8.425 | W27: =SUM(U27+V27) -> 176.925 | X27: 1205
A28: 42170 | B28: 5445 | C28: 2 | E28: 1 | F28: 75 | H28: 105 | J28: 1 | K28: 1 | L28: 75 | N28: 140 | P28: 0 | Q28: =SUM(N28,L28,J28,F28) -> 291 | R28: =(C28*F28)+(K28*L28) -> 225 | T28: =I28*J28 -> 0 | U28: =(E28*F28)+(G28*H28)+(I28*J28)+(K28*L28) -> 150 | V28: =(U28*5%) -> 7.5 | W28: =SUM(U28+V28) -> 157.5 | X28: 1194
A29: 42174 | B29: 5393 | C29: 2 | E29: 2 | F29: 75 | H29: 105 | J29: 1 | L29: 75 | M29: 1 | N29: 140 | U29: =(E29*F29)+(G29*H29)+(I29*J29)+(K29*L29)+(M29*N29) -> 290 | V29: =(U29*5%) -> 14.5 | W29: =SUM(U29+V29) -> 304.5 | X29: 1204
A30: 42177 | B30: 5397 | E30: 3 | F30: 75 | H30: 105 | J30: 1 | L30: 75 | N30: 140 | U30: =(E30*F30)+(G30*H30)+(I30*J30)+(K30*L30)+(M30*N30)+(105*O30) -> 225 | V30: =(U30*5%) -> 11.25 | W30: =SUM(U30+V30) -> 236.25 | X30: 1204
A31: 42177 | B31: 5615 | C31: 2 | F31: 75 | G31: 2 | H31: 105 | I31: 28 | J31: 1 | L31: 75 | N31: 140 | U31: =(E31*F31)+(G31*H31)+(I31*J31)+(K31*L31)+(M31*N31) -> 238 | V31: =(U31*5%) -> 11.9 | W31: =SUM(U31+V31) -> 249.9 | X31: 1205
