Workbook

Sheet Summary
A1: =G11 -> PIPELINE PROJECT
A3: Total Schedule C: | C3: CO | D3: Extra Work | F3: To | G3: 42505
F4: From | G4: 42491
A5: 1.0 Base Lay | B5: ='1.0 BaseLay'!I449 -> 205093.55 | C5: UPI Summary: | D5: =B45 -> 125158.18
A6: 2.1 | B6: ='2.1'!E230 -> 3271.42 | C6: CO 001 | D6: ='CO001'!I496 -> 4394.6202
A7: 2.2 | C7: CO 002 | E7: ='CO002'!C31 -> 50000
A8: 2.3 | B8: ='2.3'!F425 -> 66806.76 | C8: CO 012
A9: 2.11 | C9: CO 015 | D9: ='CO015'!C272 -> 2238.76 | F9: Contractor: | G9: Contractor
A10: 2.14 | C10: CO 017 | F10: Chief Inspector | G10: Construction Manager
A11: 2.18 | C11: CO 019 | F11: Project: | G11: PIPELINE PROJECT
A12: 2.22 | C12: CO 024
A13: 2.27 | C13: CO 027 | E13: ='2.27'!F29 -> 2751.84
A14: 2.29 | C14: CO 030
A15: 2.31 | C15: CO 033
A16: 2.35 | B16: ='2.35'!F32 -> 55080 | C16: CO 038 | D16: ='CO038'!C152 -> 1480.14
A17: 3.1.2-2A | C17: CO 039
A18: 3.2.2-2A | C18: CO 040
C19: CO 052 | D19: ='CO052'!C29 -> 325639.92
C20: CO 053 | D20: ='CO053'!C29 -> 13198.84
C21: CO 054 | D21: ='CO054'!C29 -> 5195.45
C22: CO 055 | D22: ='CO055'!C29 -> 69770.04
C23: CO 056
C24: CO 057
E28: 2770000
A31: Total | B31: =SUM(B5:B30) -> 330251.73 | C31: CO Total: | D31: =SUM(D6:D30) -> 421917.77
B34: Subtotal: | C34: =B31+D31 -> 752169.5
F42: Difference:
A44: 1) Base Lay Total: | B44: =B5 -> 205093.55 | F44: =B45-D45 -> 0
A45: 2) UPI Total: | B45: =SUM(B6:B17) -> 125158.18 | C45: UPI CO: | D45: =D5 -> 125158.18
A46: 3) Incremental LS Total: | B46: =SUM(B17:B18) -> 0
A47: 4) Extra Work Total: | B47: =D31 -> 421917.77
A49: Gross: | B49: =SUM(B44:B48) -> 752169.5
A50: Holdback: | B50: =B49*0.1 -> 75216.95
A51: Subtotal: | B51: =B49-B50 -> 676952.55
A52: GST | B52: =B51*0.05 -> 33847.628
A53: Total: | B53: =SUM(B51:B52) -> 710800.18
A58: Previous Billings To Date W/ COs: | B58: 44853184
A60: Total Accrual: | B60: =B58+B49 -> 45605354
A62: Previous Accrual: | B62: 47877000
A64: Difference For Week: | B64: =B60-B62 -> -2271646.1

Sheet 1.0 BaseLay
A1: PIPELINE PROJECT
A8: Schedule C
A9: 1.0 - BASE LAY PRICE
I10: Billing Date: | J10: 42323
C11: 69435 | D11: % | E11: 580.70546 | F11: Total To Date | G11: Previous | H11: This Period | I11: Amount This Period ($) | J11: Total Earned Previously ($) | K11: Amount Earned To Date ($)
A12: 1.1 | B12: Mobilization | C12: Per Lin. m | D12: 0.02 | E12: =$E$11*D12 -> 11.614109 | F12: =G12+H12 -> 34718 | H12: 34718 | I12: =H12*E12 -> 403218.64 | J12: =G12*E12 -> 0 | K12: =SUM(I12:J12) -> 403218.64
B13: Grade ROW | C13: Per Lin. m | D13: 0.08 | E13: =$E$11*D13 -> 46.456437 | F13: =G13+H13 -> 0 | I13: =H13*E13 -> 0 | J13: =G13*E13 -> 0 | K13: =SUM(I13:J13) -> 0
B14: Haul and String Ppipe | C14: Per Lin. m | D14: 0.07 | E14: =$E$11*D14 -> 40.649382 | F14: =G14+H14 -> 0 | I14: =H14*E14 -> 0 | J14: =G14*E14 -> 0 | K14: =SUM(I14:J14) -> 0
B15: Bending | C15: Per Lin. m | D15: 0.07 | E15: =$E$11*D15 -> 40.649382 | F15: =G15+H15 -> 0 | I15: =H15*E15 -> 0 | J15: =G15*E15 -> 0 | K15: =SUM(I15:J15) -> 0
B16: Welding | C16: Per Lin. m | D16: 0.17 | E16: =$E$11*D16 -> 98.719928 | F16: =G16+H16 -> 0 | I16: =H16*E16 -> 0 | J16: =G16*E16 -> 0 | K16: =SUM(I16:J16) -> 0
B17: Excavate Pipe Trench | C17: Per Lin. m | D17: 0.08 | E17: =$E$11*D17 -> 46.456437 | F17: =G17+H17 -> 0 | I17: =H17*E17 -> 0 | J17: =G17*E17 -> 0 | K17: =SUM(I17:J17) -> 0
B18: Lower-In Pipe | C18: Per Lin. m | D18: 0.07 | E18: =$E$11*D18 -> 40.649382 | F18: =G18+H18 -> 0 | I18: =H18*E18 -> 0 | J18: =G18*E18 -> 0 | K18: =SUM(I18:J18) -> 0
B19: Backfill | C19: Per Lin. m | D19: 0.08 | E19: =$E$11*D19 -> 46.456437 | F19: =G19+H19 -> 0 | I19: =H19*E19 -> 0 | J19: =G19*E19 -> 0 | K19: =SUM(I19:J19) -> 0
B20: Tie-Ins | C20: Per Lin. m | D20: 0.07 | E20: =$E$11*D20 -> 40.649382 | F20: =G20+H20 -> 0 | I20: =H20*E20 -> 0 | J20: =G20*E20 -> 0 | K20: =SUM(I20:J20) -> 0
B21: Testing | C21: Per Lin. m | D21: 0.07 | E21: =$E$11*D21 -> 40.649382 | F21: =G21+H21 -> 0 | I21: =H21*E21 -> 0 | J21: =G21*E21 -> 0 | K21: =SUM(I21:J21) -> 0
B22: Final Tie-Ins | C22: Per Lin. m | D22: 0.05 | E22: =$E$11*D22 -> 29.035273 | F22: =G22+H22 -> 0 | I22: =H22*E22 -> 0 | J22: =G22*E22 -> 0 | K22: =SUM(I22:J22) -> 0
B23: Cleanup/Reclamation/Seeding | C23: Per Lin. m | D23: 0.09 | E23: =$E$11*D23 -> 52.263491 | F23: =G23+H23 -> 0 | I23: =H23*E23 -> 0 | J23: =G23*E23 -> 0 | K23: =SUM(I23:J23) -> 0
B24: Demobilization | C24: Per Lin. m | D24: 0.02 | E24: =$E$11*D24 -> 11.614109 | F24: =G24+H24 -> 0 | I24: =H24*E24 -> 0 | J24: =G24*E24 -> 0 | K24: =SUM(I24:J24) -> 0
B25: Final Clean Up (one year later) | C25: Per Lin. m | D25: 0.06 | E25: =$E$11*D25 -> 34.842327 | F25: =G25+H25 -> 0 | I25: =H25*E25 -> 0 | J25: =G25*E25 -> 0 | K25: =SUM(I25:J25) -> 0
D26: =SUM(D12:D25) -> 1 | E26: =SUM(E12:E25) -> 580.70546 | H26: Total For Base Lay Price: | I26: =SUM(I12:I25) -> 403218.64 | J26: =SUM(J12:J25) -> 0 | K26: =SUM(K12:K25) -> 403218.64
A29: Contractor
I34: Chief Inspector
A36: PIPELINE PROJECT
A43: Schedule C
A44: 1.0 - BASE LAY PRICE
I45: Billing Date: | J45: 42338
C46: 69435 | D46: % | E46: 580.70546 | F46: Total To Date | G46: Previous | H46: This Period | I46: Amount This Period ($) | J46: Total Earned Previously ($) | K46: Amount Earned To Date ($)
A47: 1.1 | B47: Mobilization | C47: Per Lin. m | D47: 0.02 | E47: =$E$11*D47 -> 11.614109 | F47: =G47+H47 -> 69435 | G47: 34718 | H47: 34717 | I47: =H47*E47 -> 403207.03 | J47: =G47*E47 -> 403218.64 | K47: =SUM(I47:J47) -> 806425.67
B48: Grade ROW | C48: Per Lin. m | D48: 0.08 | E48: =$E$11*D48 -> 46.456437 | F48: =G48+H48 -> 5300 | H48: 5300 | I48: =H48*E48 -> 246219.11 | J48: =G48*E48 -> 0 | K48: =SUM(I48:J48) -> 246219.11
B49: Haul and String Ppipe | C49: Per Lin. m | D49: 0.07 | E49: =$E$11*D49 -> 40.649382 | F49: =G49+H49 -> 400 | H49: 400 | I49: =H49*E49 -> 16259.753 | J49: =G49*E49 -> 0 | K49: =SUM(I49:J49) -> 16259.753
B50: Bending | C50: Per Lin. m | D50: 0.07 | E50: =$E$11*D50 -> 40.649382 | F50: =G50+H50 -> 0 | I50: =H50*E50 -> 0 | J50: =G50*E50 -> 0 | K50: =SUM(I50:J50) -> 0
B51: Welding | C51: Per Lin. m | D51: 0.17 | E51: =$E$11*D51 -> 98.719928 | F51: =G51+H51 -> 0 | I51: =H51*E51 -> 0 | J51: =G51*E51 -> 0 | K51: =SUM(I51:J51) -> 0
B52: Excavate Pipe Trench | C52: Per Lin. m | D52: 0.08 | E52: =$E$11*D52 -> 46.456437 | F52: =G52+H52 -> 0 | I52: =H52*E52 -> 0 | J52: =G52*E52 -> 0 | K52: =SUM(I52:J52) -> 0
B53: Lower-In Pipe | C53: Per Lin. m | D53: 0.07 | E53: =$E$11*D53 -> 40.649382 | F53: =G53+H53 -> 0 | I53: =H53*E53 -> 0 | J53: =G53*E53 -> 0 | K53: =SUM(I53:J53) -> 0
B54: Backfill | C54: Per Lin. m | D54: 0.08 | E54: =$E$11*D54 -> 46.456437 | F54: =G54+H54 -> 0 | I54: =H54*E54 -> 0 | J54: =G54*E54 -> 0 | K54: =SUM(I54:J54) -> 0
B55: Tie-Ins | C55: Per Lin. m | D55: 0.07 | E55: =$E$11*D55 -> 40.649382 | F55: =G55+H55 -> 0 | I55: =H55*E55 -> 0 | J55: =G55*E55 -> 0 | K55: =SUM(I55:J55) -> 0
B56: Testing | C56: Per Lin. m | D56: 0.07 | E56: =$E$11*D56 -> 40.649382 | F56: =G56+H56 -> 0 | I56: =H56*E56 -> 0 | J56: =G56*E56 -> 0 | K56: =SUM(I56:J56) -> 0
B57: Final Tie-Ins | C57: Per Lin. m | D57: 0.05 | E57: =$E$11*D57 -> 29.035273 | F57: =G57+H57 -> 0 | I57: =H57*E57 -> 0 | J57: =G57*E57 -> 0 | K57: =SUM(I57:J57) -> 0
B58: Cleanup/Reclamation/Seeding | C58: Per Lin. m | D58: 0.09 | E58: =$E$11*D58 -> 52.263491 | F58: =G58+H58 -> 0 | I58: =H58*E58 -> 0 | J58: =G58*E58 -> 0 | K58: =SUM(I58:J58) -> 0
B59: Demobilization | C59: Per Lin. m | D59: 0.02 | E59: =$E$11*D59 -> 11.614109 | F59: =G59+H59 -> 0 | I59: =H59*E59 -> 0 | J59: =G59*E59 -> 0 | K59: =SUM(I59:J59) -> 0
...

Sheet 2.1
A1: =Summary!$G$11 -> PIPELINE PROJECT
A13: UNIT PRICE ITEM SUMMARY
A16: Schedule C | B16: Commercial Terms | D16: Date: | E16: 42353
A17: Item | B17: 2.1 Rock Trench
A19: Description | C19: per | E19: Amount
A20: 2.1 | B20: Rock Trench
B21: a) by mechanical methods, when requested by Company | C21: Cost Plus | E21: 36802.67
B22: b) by drill and blasting methods, when requestd by Company | C22: Cost Plus
B23: c) within the wetted perimeter of named watercourses in accordance with the Contract Documents, when requested by Company | C23: Cost Plus
D26: Total | E26: =SUM(E20:E25) -> 36802.67
A28: =Summary!$G$9 -> Contractor
C32: =Summary!$G$10 -> Construction Manager
A34: =Summary!$G$11 -> PIPELINE PROJECT
A47: UNIT PRICE ITEM SUMMARY
A50: Schedule C | B50: Commercial Terms | D50: Date: | E50: 42384
A51: Item | B51: 2.1 Rock Trench
A53: Description | C53: per | E53: Amount
A54: 2.1 | B54: Rock Trench
B55: a) by mechanical methods, when requested by Company | C55: Cost Plus | E55: 19134.69
B56: b) by drill and blasting methods, when requestd by Company | C56: Cost Plus
B57: c) within the wetted perimeter of named watercourses in accordance with the Contract Documents, when requested by Company | C57: Cost Plus
D60: Total | E60: =SUM(E54:E59) -> 19134.69
A62: =Summary!$G$9 -> Contractor
C66: =Summary!$G$10 -> Construction Manager
A68: =Summary!$G$11 -> PIPELINE PROJECT
A81: UNIT PRICE ITEM SUMMARY
A84: Schedule C | B84: Commercial Terms | D84: Date: | E84: 42400
A85: Item | B85: 2.1 Rock Trench
A87: Description | C87: per | E87: Amount
A88: 2.1 | B88: Rock Trench
B89: a) by mechanical methods, when requested by Company | C89: Cost Plus | E89: 1914.8
B90: b) by drill and blasting methods, when requestd by Company | C90: Cost Plus
B91: c) within the wetted perimeter of named watercourses in accordance with the Contract Documents, when requested by Company | C91: Cost Plus
D94: Total | E94: =SUM(E88:E93) -> 1914.8
A96: =Summary!$G$9 -> Contractor
C100: =Summary!$G$10 -> Construction Manager
A102: =Summary!$G$11 -> PIPELINE PROJECT
A115: UNIT PRICE ITEM SUMMARY
A118: Schedule C | B118: Commercial Terms | D118: Date: | E118: 42415
A119: Item | B119: 2.1 Rock Trench
...

Sheet 2.2
A1: =Summary!$G$11 -> PIPELINE PROJECT
A13: UNIT PRICE ITEM SUMMARY
A16: Schedule C | E16: Date: | F16: 42353
A17: Item | B17: 2.2 Rockshield
A19: Description | C19: per | D19: Unit Price | E19: Units | F19: Amount
A20: 2.2 | B20: Rockshield (NPS 16)
B21: a) Owner supply rockshield material | C21: per lin. M | D21: 51.48
B22: b) Contractor supply rockshield material | C22: per lin. M | D22: 71.48 | E22: 318.98 | F22: =E22*D22 -> 22800.69
E24: Total | F24: =SUM(F20:F23) -> 22800.69
A26: =Summary!$G$9 -> Contractor
C30: =Summary!$G$10 -> Construction Manager
B35: Locations (KPs): | C35: From | D35: To | E35: Metres
B36: SITE UPI Report 0552 Dec. 9: | C36: 51804 | D36: 51835 | E36: =ABS(C36-D36) -> 31
C37: 51967.5 | D37: 51978 | E37: =ABS(C37-D37) -> 10.5
C38: 52144.4 | D38: 52154.7 | E38: =ABS(C38-D38) -> 10.3
C39: 52233.1 | D39: 52269.3 | E39: =ABS(C39-D39) -> 36.2
C40: 52269.3 | D40: 52280 | E40: =ABS(C40-D40) -> 10.7
C41: 52307 | D41: 52338.2 | E41: =ABS(C41-D41) -> 31.2
C42: 52746.9 | D42: 52756.3 | E42: =ABS(C42-D42) -> 9.4
C43: 52904.6 | D43: 52923 | E43: =ABS(C43-D43) -> 18.4 | F43: =SUM(E36:E43) -> 157.7
B45: SITE UPI Report 0552 Dec 13: | C45: 53113 | D45: 53166 | E45: =ABS(C45-D45) -> 53
C46: 52545 | D46: 52617 | E46: =ABS(C46-D46) -> 72 | F46: =SUM(E45:E46) -> 125
B48: SITE UPI Report 0554 Dec 15: | C48: 54697.62 | D48: 54724.37 | E48: =ABS(C48-D48) -> 26.75
C49: 54229.8 | D49: 54239.33 | E49: =ABS(C49-D49) -> 9.53 | F49: =SUM(E48:E49) -> 36.28
D51: Total: | E51: =SUM(E35:E50) -> 318.98 | F51: =SUM(F43:F50) -> 318.98
A53: =Summary!$G$11 -> PIPELINE PROJECT
A65: UNIT PRICE ITEM SUMMARY
A68: Schedule C | E68: Date: | F68: 42369
A69: Item | B69: 2.2 Rockshield
A71: Description | C71: per | D71: Unit Price | E71: Units | F71: Amount
A72: 2.2 | B72: Rockshield (NPS 16)
B73: a) Owner supply rockshield material | C73: per lin. M | D73: 51.48
B74: b) Contractor supply rockshield material | C74: per lin. M | D74: 71.48 | E74: =E97 -> 292.61 | F74: =E74*D74 -> 20915.763
E76: Total | F76: =SUM(F72:F75) -> 20915.763
A78: =Summary!$G$9 -> Contractor
C82: =Summary!$G$10 -> Construction Manager
B87: Locations (KPs): | C87: From | D87: To | E87: Metres | H87: LEM
B88: 42723 | C88: 54463 | D88: 54538 | E88: =ABS(C88-D88) -> 75 | F88: 75 | G88: Tim Lay | H88: 0326 | J88: should be 54+539
B89: 42722 | C89: 57556 | D89: 57574.84 | E89: =ABS(C89-D89) -> 18.84 | F89: 18.84 | G89: Dwayne P | H89: 0555
B90: 42722 | C90: 57595.16 | D90: 57604.41 | E90: =ABS(C90-D90) -> 9.25 | F90: 9.25 | G90: Dwayne P | H90: 0555
...

Sheet 2.3
A1: =Summary!$G$11 -> PIPELINE PROJECT
A13: UNIT PRICE ITEM SUMMARY
A14: Sand Bedding/Padding
A16: Schedule C | E16: Date: | F16: 42353
A17: Item | B17: 2.3 Sand Bedding/Padding From Borrow Pits
A19: Description | C19: per | D19: Unit Price | E19: Units | F19: Amount
A20: 2.3 | B20: Sand Bedding/Padding From Borrow Pits (Supply, load, haul, unload, place) | J20: LEM | K20: From | L20: To
B21: a) Bedding | C21: Per Lin. m | D21: 89.6 | E21: 80 | F21: =E21*D21 -> 7168 | J21: #0165 | K21: 54+380 | L21: 54+460 | M21: 80 m | P21: 18.89 | Q21: 18.99
B22: b) Padding (Top) | C22: Per Lin. m | D22: 114.67 | F22: =E22*D22 -> 0 | P22: 18.9 | Q22: 19.03
B23: c) Bedding and Padding Placed As One Operation | C23: Per Lin. m | D23: 166.57 | E23: 180 | F23: =E23*D23 -> 29982.6 | J23: #0167 | K23: 54+200 | L23: 54+380 | M23: 180 m | P23: 18.95 | Q23: 19.27
B24: d) Hauling (The cost of hauling to the ROW) | C24: m3/km | D24: 2.8 | E24: 15430.75 | F24: =E24*D24 -> 43206.1 | P24: 9.6
P25: 19.19
P26: 18.88
E27: Total | F27: =SUM(F20:F26) -> 80356.7 | P27: 19.51
P28: =SUM(P21:P27) -> 123.92 | Q28: =SUM(Q21:Q27) -> 57.29
A29: =Summary!$G$9 -> Contractor
C32: =Summary!$G$10 -> Construction Manager
A34: =Summary!$G$11 -> PIPELINE PROJECT
A46: UNIT PRICE ITEM SUMMARY
A47: Sand Bedding/Padding
A49: Schedule C | E49: Date: | F49: 42384
A50: Item | B50: 2.3 Sand Bedding/Padding From Borrow Pits
A52: Description | C52: per | D52: Unit Price | E52: Units | F52: Amount
A53: 2.3 | B53: Sand Bedding/Padding From Borrow Pits (Supply, load, haul, unload, place)
B54: a) Bedding | C54: Per Lin. m | D54: 89.6 | E54: 10 | F54: =E54*D54 -> 896
B55: b) Padding (Top) | C55: Per Lin. m | D55: 114.67 | F55: =E55*D55 -> 0
B56: c) Bedding and Padding Placed As One Operation | C56: Per Lin. m | D56: 166.57 | F56: =E56*D56 -> 0
B57: d) Hauling (The cost of hauling to the ROW) | C57: m3/km | D57: 2.8 | E57: =E76 -> 3360 | F57: =E57*D57 -> 9408
E60: Total | F60: =SUM(F53:F59) -> 10304
A62: =Summary!$G$9 -> Contractor
C65: =Summary!$G$10 -> Construction Manager
H72: LEM
B73: 42373 | C73: 21 | D73: km one way | F73: Josh | G73: Haul sand | H73: 0456
B74: 42383 | C74: 21 | F74: Harvey | G74: Haul sand | H74: 0465
C76: =SUM(C73:C74) -> 42 | D76: 80 | E76: =C76*D76 -> 3360
A78: =Summary!$G$11 -> PIPELINE PROJECT
A90: UNIT PRICE ITEM SUMMARY
A91: Sand Bedding/Padding
A93: Schedule C | E93: Date: | F93: 42400
A94: Item | B94: 2.3 Sand Bedding/Padding From Borrow Pits
...

Sheet 2.11
A1: =Summary!$G$11 -> PIPELINE PROJECT
A13: UNIT PRICE ITEM SUMMARY
A16: Schedule C | D16: Date: | E16: 42475
A17: Item | B17: 2.11 Clean Washed Gravel
A19: Description | C19: Per | E19: Amount
A20: 2.11 | B20: Clean Washed Gravel
B21: To supply load and place well graded, clean, washed gravel with particle size between 25 mm and 50 mm from contractor sourced borrow pits and pre-approved by the company, as requested by Company. | C21: Cost Plus | E21: 7658.4 | I21: Ticket: 1468, 1469 | L21: =8876.4-1218 -> 7658.4
B22: Haul (The cost of hauling to the ROW. Pits and haul distance approved by the Company) | C22: Cost Plus | E22: 1218 | L22: 8876.4
D24: Total | E24: =SUM(E20:E23) -> 8876.4
A26: =Summary!$G$9 -> Contractor
C30: =Summary!G10 -> Construction Manager
A32: =Summary!$G$11 -> PIPELINE PROJECT
A44: UNIT PRICE ITEM SUMMARY
A47: Schedule C | D47: Date: | E47: =Summary!$G$3 -> 42505
A48: Item | B48: 2.11 Clean Washed Gravel
A50: Description | C50: Per | E50: Amount
A51: 2.11 | B51: Clean Washed Gravel
B52: To supply load and place well graded, clean, washed gravel with particle size between 25 mm and 50 mm from contractor sourced borrow pits and pre-approved by the company, as requested by Company. | C52: Cost Plus | E52: 0 | I52: Ticket:
B53: Haul (The cost of hauling to the ROW. Pits and haul distance approved by the Company) | C53: Cost Plus | E53: 0
D55: Total | E55: =SUM(E51:E54) -> 0
A57: =Summary!$G$9 -> Contractor
C61: =Summary!$G$10 -> Construction Manager

Sheet 2.14
A1: =Summary!$G$11 -> PIPELINE PROJECT
A13: UNIT PRICE ITEM SUMMARY
A16: Schedule C | E16: Billing Date: | F16: 42353
A17: Item | B17: 2.14 Install Pipe To Extra Depth
A19: Description | C19: per | D19: Unit Price | E19: Units | F19: Billing Amount
A20: 2.14 | B20: Install Pipe To Extra Depth
B21: a) 0.30 m total extra depth | C21: per lin. M. | D21: 10
B22: b) 0.60 m total extra depth | C22: per lin. M. | D22: 14 | E22: 60 | F22: =E22*D22 -> 840
B23: C) 0.90 m total extra depth | C23: per lin. M. | D23: 19
B24: d) 1.20 m total extra depth | C24: per lin. M. | D24: 24
B25: e) 1.50 m total extra depth | C25: per lin. M. | D25: 39
E29: Total | F29: =SUM(F20:F28) -> 840
A31: =Summary!$G$9 -> Contractor
C35: =Summary!$G$10 -> Construction Manager
A37: =Summary!$G$11 -> PIPELINE PROJECT
A49: UNIT PRICE ITEM SUMMARY
A52: Schedule C | E52: Billing Date: | F52: 42369
A53: Item | B53: 2.14 Install Pipe To Extra Depth
A55: Description | C55: per | D55: Unit Price | E55: Units | F55: Billing Amount
A56: 2.14 | B56: Install Pipe To Extra Depth
B57: a) 0.30 m total extra depth | C57: per lin. M. | D57: 10
B58: b) 0.60 m total extra depth | C58: per lin. M. | D58: 14
B59: C) 0.90 m total extra depth | C59: per lin. M. | D59: 19
B60: d) 1.20 m total extra depth | C60: per lin. M. | D60: 24
B61: e) 1.50 m total extra depth | C61: per lin. M. | D61: 39 | E61: 12 | F61: =E61*D61 -> 468
E65: Total | F65: =SUM(F56:F64) -> 468
A67: =Summary!$G$9 -> Contractor
C71: =Summary!$G$10 -> Construction Manager
A73: =Summary!$G$11 -> PIPELINE PROJECT
A85: UNIT PRICE ITEM SUMMARY
A88: Schedule C | E88: Billing Date: | F88: 42490
A89: Item | B89: 2.14 Install Pipe To Extra Depth
A91: Description | C91: per | D91: Unit Price | E91: Units | F91: Billing Amount
A92: 2.14 | B92: Install Pipe To Extra Depth
B93: a) 0.30 m total extra depth | C93: per lin. M. | D93: 10 | E93: =L93 -> 23.606 | F93: =E93*D93 -> 236.06 | H93: 5.99 | I93: 10.069 | J93: 3.447 | K93: 4.1 | L93: =SUM(H93:K93) -> 23.606
B94: b) 0.60 m total extra depth | C94: per lin. M. | D94: 14 | E94: =L94 -> 3.449 | F94: =E94*D94 -> 48.286 | H94: 1.259 | I94: 2.19 | L94: =SUM(H94:K94) -> 3.449
B95: C) 0.90 m total extra depth | C95: per lin. M. | D95: 19
B96: d) 1.20 m total extra depth | C96: per lin. M. | D96: 24
B97: e) 1.50 m total extra depth | C97: per lin. M. | D97: 39
D99: Total: | E99: =SUM(E93:E98) -> 27.055
...

Sheet 2.18
A1: =Summary!$G$11 -> PIPELINE PROJECT
A13: UNIT PRICE ITEM SUMMARY
A16: Schedule C | E16: Date: | F16: 42353
A17: Item | B17: 2.18 Vehicle & Equipment Wash Stations
A19: Description | C19: per | D19: Unit Price | E19: Units | F19: Amount
A20: 2.18 | B20: b) Winter Wash
B21: i) Operating the wash station (Hot Steamer) | C21: Per Day | D21: 1625 | E21: 5 | F21: =E21*D21 -> 8125
B22: ii) Installation of wash stations (load, haul, assemble) | C22: Per Station | D22: 7785 | E22: 0.333333 | F22: =E22*D22 -> 2594.9974
B23: iii) Removal of wash station (load, haul, take down) | C23: Per Station | D23: 3960 | F23: =E23*D23 -> 0
E26: Total | F26: =SUM(F20:F25) -> 10719.997
A28: =Summary!$G$9 -> Contractor
C32: =Summary!$G$10 -> Construction Manager
A38: =Summary!$G$11 -> PIPELINE PROJECT
A50: UNIT PRICE ITEM SUMMARY
A53: Schedule C | E53: Date: | F53: =Summary!$G$3 -> 42505
A54: Item | B54: 2.18 Vehicle & Equipment Wash Stations
A56: Description | C56: per | D56: Unit Price | E56: Units | F56: Amount
A57: 2.18 | B57: b) Winter Wash
B58: i) Operating the wash station (Hot Steamer) | C58: Per Day | D58: 1625 | F58: =E58*D58 -> 0
B59: ii) Installation of wash stations (load, haul, assemble) | C59: Per Station | D59: 7785 | F59: =E59*D59 -> 0
B60: iii) Removal of wash station (load, haul, take down) | C60: Per Station | D60: 3960 | F60: =E60*D60 -> 0
E63: Total | F63: =SUM(F57:F62) -> 0
A65: =Summary!$G$9 -> Contractor
C69: =Summary!$G$10 -> Construction Manager

Sheet 2.22
A1: =Summary!$G$11 -> PIPELINE PROJECT
A13: UNIT PRICE ITEM SUMMARY
A16: Schedule C | E16: Date: | F16: 42415
A17: Item | B17: 2.22 Cut Out And Replace Welds
A19: Description | C19: per | D19: Unit Price | E19: Units | F19: Billing Amount
A20: 2.22 | B20: To cut out and replace welds rings, including | C20: per weld | D20: 3890 | E20: 2 | F20: =E20*D20 -> 7780
B21: re-bevelling of two (2) pipe ends at request of
B22: Company
E29: Total | F29: =SUM(F20:F28) -> 7780
A31: =Summary!$G$9 -> Contractor
C35: =Summary!$G$10 -> Construction Manager
D38: UPI Report
C39: KP 26+027 | D39: 0563 | E39: Lorne
C40: KP 54+510 | D40: 1152 | E40: Cliff
A42: =Summary!$G$11 -> PIPELINE PROJECT
A54: UNIT PRICE ITEM SUMMARY
A57: Schedule C | E57: Date: | F57: 42429
A58: Item | B58: 2.22 Cut Out And Replace Welds
A60: Description | C60: per | D60: Unit Price | E60: Units | F60: Billing Amount
A61: 2.22 | B61: To cut out and replace welds rings, including | C61: per weld | D61: 3890 | E61: 1 | F61: =E61*D61 -> 3890 | I61: KP 46+890- TICKET 1302
B62: re-bevelling of two (2) pipe ends at request of
B63: Company
E70: Total | F70: =SUM(F61:F69) -> 3890
A72: =Summary!$G$9 -> Contractor
C76: =Summary!$G$10 -> Construction Manager
A78: =Summary!$G$11 -> PIPELINE PROJECT
A90: UNIT PRICE ITEM SUMMARY
A93: Schedule C | E93: Date: | F93: =Summary!$G$3 -> 42505
A94: Item | B94: 2.22 Cut Out And Replace Welds
A96: Description | C96: per | D96: Unit Price | E96: Units | F96: Billing Amount
A97: 2.22 | B97: To cut out and replace welds rings, including | C97: per weld | D97: 3890 | F97: =E97*D97 -> 0
B98: re-bevelling of two (2) pipe ends at request of
B99: Company
E106: Total | F106: =SUM(F97:F105) -> 0
A108: =Summary!$G$9 -> Contractor
C112: =Summary!$G$10 -> Construction Manager

Sheet 2.27
A1: =Summary!$G$11 -> PIPELINE PROJECT
A13: UNIT PRICE ITEM SUMMARY
A16: Schedule C | E16: Date: | F16: =Summary!$G$3 -> 42505
A17: Item | B17: 2.27 Erosion Control Mat
A19: Description | C19: per | D19: Unit Price | E19: Units | F19: Billing Amount
A20: 2.27 | B20: Supply & Install Erosion Control Mat When | C20: per m2 | D20: 13.23 | E20: 208 | F20: =E20*D20 -> 2751.84
B21: Requested By The Company
B23: SITE UPI Report# 0477
E29: Total | F29: =SUM(F20:F28) -> 2751.84
A31: =Summary!$G$9 -> Contractor
C35: =Summary!$G$10 -> Construction Manager

Sheet 2.29
A1: =Summary!$G$11 -> PIPELINE PROJECT
A13: UNIT PRICE ITEM SUMMARY
A16: Schedule C | E16: Date: | F16: 42369
A17: Item | B17: 2.29 Rig Mats
A19: Description | C19: per | D19: Unit Price | E19: Units | F19: Amount
A20: 2.29 | B20: Rig Mats | K20: 42735 | L20: 42379
B21: Oak Interlocking Mats | C21: per mat | D21: 4.5 | E21: 15876 | F21: =E21*D21 -> 71442 | K21: 15876 | L21: 21276
B22: Rig mats complete with metal frame (appox. 8' x 20') | C22: per mat | D22: 45 | F22: =E22*D22 -> 0
E26: Total | F26: =SUM(F20:F25) -> 71442
A28: =Summary!$G$9 -> Contractor
C32: =Summary!$G$10 -> Construction Manager
A34: =Summary!$G$11 -> PIPELINE PROJECT
A46: UNIT PRICE ITEM SUMMARY
A49: Schedule C | E49: Date: | F49: 42384 | K49: Need to enter the difference:
A50: Item | B50: 2.29 Rig Mats
A52: Description | C52: per | D52: Unit Price | E52: Units | F52: Amount | K52: Previous
A53: 2.29 | B53: Rig Mats | K53: 42735 | L53: 42384
B54: Oak Interlocking Mats | C54: per mat | D54: 4.5 | E54: 8100 | F54: =E54*D54 -> 36450 | K54: 15876 | L54: 8100
B55: Rig mats complete with metal frame (appox. 8' x 20') | C55: per mat | D55: 45 | F55: =E55*D55 -> 0
E59: Total | F59: =SUM(F53:F58) -> 36450
A61: =Summary!$G$9 -> Contractor
C65: =Summary!$G$10 -> Construction Manager
A67: =Summary!$G$11 -> PIPELINE PROJECT
A79: UNIT PRICE ITEM SUMMARY
A82: Schedule C | E82: Date: | F82: 42400 | K82: Need to enter the difference:
A83: Item | B83: 2.29 Rig Mats
A85: Description | C85: per | D85: Unit Price | E85: Units | F85: Amount | K85: Previous
A86: 2.29 | B86: Rig Mats | K86: 42735 | L86: 42384 | M86: 42400 | N86: 42415 | O86: To Date:
B87: Oak Interlocking Mats | C87: per mat | D87: 4.5 | E87: 8640 | F87: =E87*D87 -> 38880 | K87: 15876 | L87: 8100 | M87: 8640 | O87: =SUM(K87:N87) -> 32616
B88: Rig mats complete with metal frame (appox. 8' x 20') | C88: per mat | D88: 45 | F88: =E88*D88 -> 0 | K88: 71442 | L88: 36450 | M88: 38880 | O88: =SUM(K88:N88) -> 146772
E92: Total | F92: =SUM(F86:F91) -> 38880
A94: =Summary!$G$9 -> Contractor
C98: =Summary!$G$10 -> Construction Manager
A100: =Summary!$G$11 -> PIPELINE PROJECT
A112: UNIT PRICE ITEM SUMMARY
A115: Schedule C | E115: Date: | F115: 42415 | K115: Need to enter the difference:
A116: Item | B116: 2.29 Rig Mats
A118: Description | C118: per | D118: Unit Price | E118: Units | F118: Amount | K118: Previous
A119: 2.29 | B119: Rig Mats | K119: 42735 | L119: 42384 | M119: 42400 | N119: 42415 | O119: To Date:
B120: Oak Interlocking Mats | C120: per mat | D120: 4.5 | E120: 2700 | F120: =E120*D120 -> 12150 | K120: 15876 | L120: 8100 | M120: 8640 | N120: 2700 | O120: =SUM(K120:N120) -> 35316
...

Sheet 2.31
A1: =Summary!$G$11 -> PIPELINE PROJECT
A13: UNIT PRICE ITEM SUMMARY
A16: Schedule C | E16: Date: | F16: 42400
A17: Item | B17: 2.31 Move Around
A19: Description | C19: per | D19: Unit Price | E19: Units | F19: Amount
A20: 2.31 | B20: Move Around- Bending
B21: a) Within 10 km of ROW | C21: Crew | D21: 4500 | E21: 1 | F21: =E21*D21 -> 4500 | I21: 42716 | J21: 56+109- Bending Part crew move around so within 10 km of ROW used
B22: b) 10 to -25 km of ROW | C22: Crew | D22: 8200 | J22: KP 51+500 to 61+800 area
E29: Total | F29: =SUM(F20:F28) -> 4500
A31: =Summary!$G$9 -> Contractor
C35: =Summary!$G$10 -> Construction Manager
A37: =Summary!$G$11 -> PIPELINE PROJECT
A49: UNIT PRICE ITEM SUMMARY
A52: Schedule C | E52: Date: | F52: 42429
A53: Item | B53: 2.31 Move Around
I54: 42409 | J54: 48+800-Grade- Move Around Bear Den | N54: 0763 | P54: 3400
A55: Description | C55: per | D55: Unit Price | E55: Units | F55: Amount | I55: 42424 | J55: 48+800-Bending- Move Around Bear Den | N55: 0229/0229 | P55: 4500 | Q55: =P55 -> 4500
A56: 2.31 | B56: Move Around- Bending | I56: 42425 | J56: 48+800-Welding- Move Around Bear Den | P56: 11050 | Q56: =P56 -> 11050
B57: a) Within 10 km of ROW | C57: Crew | D57: 4500 | E57: 1 | F57: =E57*D57 -> 4500 | I57: 42426 | J57: 48+800-Coating- Move Around Bear Den | N57: 0281 | P57: 4500 | Q57: =P57 -> 4500
B58: b) 10 to -25 km of ROW | C58: Crew | D58: 8200 | F58: =E58*D58 -> 0 | I58: 42429 | J58: 48+800-Ditching- Move Around Bear Den | N58: 0765 | P58: 10500
B59: Move Around- Welding | I59: 42429 | J59: 48+800-Lower-In- Move Around Bear Den | N59: 0766 | P59: 9000
B60: a) Within 10 km of ROW | C60: Crew | D60: 11050 | E60: 1 | F60: =E60*D60 -> 11050 | I60: 42430 | J60: 48+800-Backfill- Move Around Bear Den | N60: 0144 | P60: 9000
B61: b) 10 to -25 km of ROW | C61: Crew | D61: 17600 | F61: =E61*D61 -> 0 | K61: test | P61: 4500
B62: Move Around- Coating | K62: Tie-ins | L62: 4 crew- 9,000 | P62: 27000
B63: a) Within 10 km of ROW | C63: Crew | D63: 4500 | E63: 1 | F63: =E63*D63 -> 4500 | K63: Initial clean up | P63: 12000
B64: b) 10 to -25 km of ROW | C64: Crew | D64: 8200 | F64: =E64*D64 -> 0 | K64: final Clean up | P64: 12000
E65: Total | F65: =SUM(F56:F64) -> 20050 | P65: =SUM(P54:P64) -> 107450 | Q65: =SUM(Q54:Q64) -> 20050
A67: =Summary!$G$9 -> Contractor
C71: =Summary!$G$10 -> Construction Manager
A73: =Summary!$G$11 -> PIPELINE PROJECT
A85: UNIT PRICE ITEM SUMMARY
A88: Schedule C | E88: Date: | F88: 42444
A89: Item | B89: 2.31 Move Around
I90: 42409 | J90: 48+800-Grade- Move Around Bear Den | N90: 0763 | P90: 3400 | Q90: 3400
A91: Description | C91: per | D91: Unit Price | E91: Units | F91: Amount | I91: 42424 | J91: 48+800-Bending- Move Around Bear Den | N91: 0229/0229 | P91: 4500 | R91: paid Feb 29
A92: 2.31 | B92: Move Around- Grading | I92: 42425 | J92: 48+800-Welding- Move Around Bear Den | P92: 11050 | R92: paid Feb 29
B93: a) Within 10 km of ROW | C93: Crew | D93: 10500 | E93: 0.3238094 | F93: =E93*D93 -> 3399.9987 | I93: 42426 | J93: 48+800-Coating- Move Around Bear Den | N93: 0281 | P93: 4500 | R93: paid Feb 29
B94: b) 10 to -25 km of ROW | C94: Crew | D94: 16400 | F94: =E94*D94 -> 0 | I94: 42429 | J94: 48+800-Ditching- Move Around Bear Den | N94: 0765 | P94: 10500 | Q94: 10500
B95: Move Around- Trenching | I95: 42429 | J95: 48+800-Lower-In- Move Around Bear Den | N95: 0766 | P95: 9000 | Q95: 9000
B96: a) Within 10 km of ROW | C96: Crew | D96: 10500 | E96: 1 | F96: =E96*D96 -> 10500 | I96: 42430 | J96: 48+800-Backfill- Move Around Bear Den | N96: 0144 | P96: 9000 | Q96: 9000
...

Sheet 2.35
A1: =Summary!$G$11 -> PIPELINE PROJECT
A13: UNIT PRICE ITEM SUMMARY
A16: Schedule C | E16: Date: | F16: =Summary!$G$3 -> 42505
A17: Item | B17: 2.35 Crossings Under Existing Buried Pipelines
A19: Description | C19: per | D19: Unit Price | E19: Units | F19: Amount
A20: 2.35 | B20: Crossings Under Existing Buried Pipelines
B21: Add per crossing | C21: Crossing | D21: 18360 | E21: 3 | F21: =E21*D21 -> 55080
E32: Total | F32: =SUM(F20:F31) -> 55080
A34: =Summary!$G$9 -> Contractor
C38: =Summary!$G$10 -> Construction Manager

Sheet 3.2.2-2A
A1: =Summary!G11 -> PIPELINE PROJECT
A13: 3.0 INCREMENTAL LUMP SUM
A15: Schedule C | F15: Billing Date: | G15: =Summary!G3 -> 42505
A16: Item | B16: HDD and Brored Crossing Lump Sum Prices for 12" Oil Line Segment
A18: Description | C18: per | D18: Unit Price | E18: Previous | F18: Units | G18: Billing Amount
A19: 2A-C.1 | B19: NPS 12 HDD Crossing Installation- Bow River | C19: Lump Sum | D19: 344650 | E19: 1 | G19: =F19*D19 -> 0
A20: 2A-C.2 | B20: NPS 12 HDD Crossing Installation- Irrigation Canal & Reservoir | C20: Lump Sum | D20: 286300 | E20: 1
A21: 2A-C.3 | B21: NPS 12 HDD Crossing Installation- Secondary Hwy 524 | C21: Lump Sum | D21: 18000 | E21: 1
A22: 2A-C.4 | B22: NPS 12 HDD Crossing Installation- Secondary Hwy 875 | C22: Lump Sum | D22: 18000 | E22: 1
A23: 2A-C.5 | B23: NPS 12 HDD Crossing Installation- Old Man River | C23: Lump Sum | D23: 386350 | E23: 1
F27: Total | G27: =SUM(G19:G26) -> 0
A29: =Summary!G9 -> Contractor
D33: =Summary!G10 -> Construction Manager

Sheet 3.1.2-2A
A1: =Summary!G11 -> PIPELINE PROJECT
A13: 3.0 INCREMENTAL LUMP SUM
A15: Schedule C | E15: Billing Date: | F15: =Summary!G3 -> 42505
A16: Item | B16: Fabricated Assembly Lump Sum Prices For 12" Oil Line Segment
A18: Description | C18: per | D18: Unit Price | E18: Previous | F18: Units | G18: Billing Amount
A19: 2A-B.1 | B19: Fabricate Test & Install NPS 12 Mainline Block Valve Assembly | C19: Lump Sum | D19: 25050 | E19: 1 | G19: =F19*D19 -> 0
A20: 2A-B.2 | B20: Fabricate Test & Install NPS 12 Mainline Block Valve & Check Valve Assembly | C20: Lump Sum | D20: 28650 | E20: 1 | G20: =F20*D20 -> 0
F27: Total | G27: =SUM(G19:G26) -> 0
A29: =Summary!G9 -> Contractor
D33: =Summary!G10 -> Construction Manager

Sheet 4.1
A1: =Summary!G11 -> PIPELINE PROJECT
A13: UNIT PRICE ITEM SUMMARY
A14: Topsoil Stripping & Replacement
A16: Schedule C | G16: Billing Date: | H16: =Summary!G3 -> 42505
A17: Item | B17: 4.1
A19: Description | C19: per | D19: Unit Price | E19: Units Stripped | F19: Units Replaced | G19: Total Units | H19: Amount This Period
A20: 4.1 | B20: Topsoil Stripping And Replacement
A21: 4.1.1 | B21: Removal and restoration of topsoil over trench area (blade width stripping)
B22: a) 0 to 40 cm in depth | C22: Per Lin. m | D22: 3.5 | G22: =SUM(E22:F22) -> 0 | H22: =(F22*D22/2)+(E22*D22/2) -> 0
B23: b) 40 cm and greater | C23: Per Lin. m | D23: 4.5 | G23: =SUM(E23:F23) -> 0 | H23: =(F23*D23/2)+(E23*D23/2) -> 0
A24: 4.1.2 | B24: Removal and restoration of topsoil over trench and spoil side area
B25: a) 0 to 40 cm in depth | C25: Per Lin. m | D25: 6.5 | G25: =SUM(E25:F25) -> 0 | H25: =(F25*D25/2)+(E25*D25/2) -> 0
B26: b) 40 cm and greater | C26: Per Lin. m | D26: 9.5 | G26: =SUM(E26:F26) -> 0 | H26: =(F26*D26/2)+(E26*D26/2) -> 0
A27: 4.1.3 | B27: Removal and restoration of topsoil over the entire Construction Right of Way
B28: a) 0 to 40 cm in depth | C28: Per Lin. m | D28: 9.5 | G28: =SUM(E28:F28) -> 0 | H28: =(F28*D28/2)+(E28*D28/2) -> 0
B29: b) 40 cm and greater | C29: Per Lin. m | D29: 12.5 | G29: =SUM(E29:F29) -> 0 | H29: =(F29*D29/2)+(E29*D29/2) -> 0
E31: Total | G31: =SUM(G20:G30) -> 0 | H31: =SUM(H20:H30) -> 0
A33: =Summary!G9 -> Contractor
E36: =Summary!G10 -> Construction Manager

Sheet RFI's
A1: RFI Log
A3: Expansion Pipeline Project | F3: Date: | G3: =Summary!G3 -> 42505
A4: Request for Information (RFI)
A5: RFI # | B5: Description | C5: Originator | D5: Date Issued | E5: Reply Date Required | F5: Status | G5: Cost Impact | H5: Change Order Request | I5: Change Order (if applicable) | J5: RFI Complete
A6: W2K-RFI-0001 | B6: Additional HDD Location | C6: Mark Ringrose | D6: 42311 | E6: 42311 | F6: Approved | J6: Complete
A7: W2K-RFI-0002 | B7: Harvest Crossing and Road Use Agreements | C7: Mark Ringrose | D7: 42311 | E7: 42317 | F7: Approved | J7: Complete
A8: W2K-RFI-0003 | B8: Road Allowance Workspace | C8: Mark Ringrose | D8: 42312 | E8: 42318 | F8: Approved | J8: Complete
A9: W2K-RFI-0004 | B9: Corinthian Access Roads & Pipeline Crossings- Crossing & Proximity Agreements | C9: Mark Ringrose | D9: 42312 | E9: 42324 | F9: Approved | J9: Complete
A10: W2K-RFI-0005 | B10: Depth of Cover at Ephemeral Draws and Intermittent Creek Crossings | C10: Mark Ringrose | D10: 42314 | E10: 42318 | F10: Approved | J10: Complete
A11: W2K-RFI-0006 | B11: Slashing Standby | C11: Kendall O'Regan | D11: 42314 | E11: 42317 | F11: N/A | G11: 12805 | J11: Complete
A12: W2K-RFI-0007 | B12: Purchase Of Two-Way Radios | C12: Kendall O'Regan | D12: 42314 | E12: 42317 | F12: Approved | G12: 6751 | I12: CO2 | J12: Complete
A13: W2K-RFI-0008 | B13: Weather Conditions & Winter Welding | C13: Andrew Elash | D13: 42314 | E13: 42318 | F13: Not Approved | J13: Complete
A14: W2K-RFI-0009 | B14: Typical Construction Drawings | C14: Andrew Elash | D14: 42314 | E14: 42318 | F14: Approved | J14: Complete
A15: W2K-RFI-0010 | B15: Additional TFA For ROW Access | C15: Mark Ringrose | D15: 42314 | E15: 42318 | F15: Approved | J15: Complete
A16: W2K-RFI-0011 | B16: Welder Testing- Line Up Clamps | C16: Andrew Elash | D16: 42314 | E16: 42318 | F16: Approved | J16: Complete
A17: W2K-RFI-0012R1 | B17: Removal Of Pipe Clamps During Hot Pass | C17: Andrew Elash | D17: 42361 | E17: 42369 | F17: Responded | J17: Complete
A18: W2K-RFI-0013 | B18: Minimum Tie Install Temperature | C18: Andrew Elash | D18: 42314 | E18: 42318 | F18: Approved | J18: Complete
A19: W2K-RFI-0014 | B19: Pipe & Bend MTRs | C19: Andrew Elash | D19: 42314 | E19: 42318 | F19: Approved | J19: Complete
A20: W2K-RFI-0015R3 | B20: Project Delay Indirect Costs, Equipment Costs & Foremen Retention | C20: Kendall O'Regan | D20: 42318 | E20: 42320 | F20: Approved | G20: 555229.22 | I20: CO5 | J20: Complete
A21: W2K-RFI-0016 | B21: Combine Typical Drills #6 (38+390) & #7 (38+606) | C21: Andrew Elash | D21: 42319 | E21: 42324 | F21: Approved | J21: Complete
A22: W2K-RFI-0017R1 | B22: Extend Bore At KP 22+821 | C22: Andrew Elash | D22: 42319 | E22: 42324 | F22: Approved | J22: Complete
A23: W2K-RFI-0018 | B23: Extra Work Space Required For HDD At KP 26+759 | C23: Andrew Elash | D23: 42319 | E23: 42324 | F23: Approved | J23: Complete
A24: W2K-RFI-0019R1 | B24: Husky Road Use Agreement Required For Husky Roads | C24: Andrew Elash | D24: 42320 | E24: 42324 | F24: Approved | J24: Complete
A25: W2K-RFI-0020 | B25: Clearing Support: Change Request CR-0001 Proposal | C25: Mark Ringrose | D25: 42327 | E25: 42329 | F25: Approved | I25: CO3 | J25: Complete
A26: W2K-RFI-0021 | B26: Sand Blasting Abrasive | C26: Andrew Elash | D26: 42327 | E26: 42328 | F26: Approved | J26: Complete
A27: W2K-RFI-0022 | B27: Hydro Test Pressure | C27: Andrew Elash | D27: 42327 | E27: 42328 | F27: Approved | J27: Complete
A28: W2K-RFI-0023 | B28: CNRL Pipeline Crossings | C28: Kristen Jones | D28: 42327 | E28: 42332 | F28: Approved | J28: Complete
A29: W2K-RFI-0024 | B29: Hauling Of Stripped Topsoil | C29: Mark Ringrose | D29: 42328 | E29: 42332 | F29: Not Approved | G29: 34974.24 | J29: Complete
A30: W2K-RFI-0025 | B30: Extended Bore KP 57+204 | C30: Mark Ringrose | D30: 42328 | E30: 42332 | F30: Approved | J30: Complete
A31: W2K-RFI-0026R1 | B31: 24Hr Medic Coverage | C31: Mark Ringrose | D31: 42331 | E31: 42333 | F31: Approved | G31: 103635 | I31: CO4 | J31: Complete
A32: W2K-RFI-0027
A33: W2K-RFI-0028 | B33: River Pull Back (Over Bend Radius) | C33: Mark Ringrose | D33: 42331 | E33: 42333 | F33: Approved | J33: Complete
A34: W2K-RFI-0029 | B34: Approval To Use Methanol For HDD Pre-Tests | C34: Mark Ringrose | D34: 42331 | E34: 42333 | F34: Approved | J34: Complete
A35: W2K-RFI-0030R1 | B35: Atco Power Pole At 8+221 | C35: Mark Ringrose | D35: 42331 | E35: 42333 | F35: Approved | J35: Complete
A36: W2K-RFI-0031 | B36: Removal Of USM & Topsoil | C36: Mark Ringrose | D36: 42331 | E36: 42333 | F36: Approved | J36: Complete
A37: W2K-RFI-0032 | B37: Sump Pit Excavation- Test Holes | C37: Mark Ringrose | D37: 42334 | E37: 42335 | F37: Approved | G37: 20000 | I37: CO9 | J37: Complete
A38: W2K-RFI-0033 | B38: Minimum Separation During HDD | C38: Mark Ringrose | D38: 42338 | E38: 42339 | F38: Reviewed | J38: Complete
A39: W2K-RFI-0034 | B39: Trucking Mats To Cutbank HDD | C39: Mark Ringrose | D39: 42339 | E39: 42341 | F39: Approved | G39: 76820 | I39: CO10 | J39: Complete
A40: W2K-RFI-0035 | B40: Atco Power Pole At 14+157 | C40: Mark Ringrose | D40: 42339 | E40: 42342 | F40: Approved | J40: Complete
A41: W2K-RFI-0036 | B41: Proposed Ditch Line KP 52+445 | C41: Mark Ringrose | D41: 42340 | E41: 42341 | F41: Approved | J41: Complete
...

Sheet SI Log
D1: SI Log
A2: Expansion Pipeline Project | D2: Energy Services | I2: Progress Period | J2: =Summary!G4 -> 42491 | K2: To | L2: =Summary!G3 -> 42505
B5: CO | C5: Description | D5: Type | E5: Approved | F5: Forecast | G5: Date | H5: Change | I5: Work
A6: SI | B6: Number | D6: SI | E6: Value | F6: Value | G6: Approved | H6: Order | I6: Status
A7: Number | B7: If Applic. | D7: Change Request | E7: $ | F7: $ | H7: Status | J7: This | K7: Previous | L7: To Date
D8: Change Order | J8: Period
A10: 1 | E10: 0 | F10: 0 | J10: 0 | K10: 0 | L10: =J10+K10 -> 0
A11: 2 | C11: Overnight Hold on Welds | D11: SI | E11: 0 | F11: 0 | J11: 0 | K11: 0 | L11: =J11+K11 -> 0
A12: 3 | C12: Theoretical Road Crossing Depth | D12: SI | E12: 0 | F12: 0 | J12: 0 | K12: 0 | L12: =J12+K12 -> 0
A13: 4 | C13: Minimum Depth Of Cover For Watercourses | D13: SI | E13: 0 | F13: 0 | J13: 0 | K13: 0 | L13: =J13+K13 -> 0
A14: 5 | E14: 0 | F14: 0 | J14: 0 | K14: 0 | L14: =J14+K14 -> 0
A15: 6 | E15: 0 | F15: 0 | J15: 0 | K15: 0 | L15: =J15+K15 -> 0
A16: 7 | E16: 0 | F16: 0 | J16: 0 | K16: 0 | L16: =J16+K16 -> 0
A17: 8 | E17: 0 | F17: 0 | J17: 0 | K17: 0 | L17: =J17+K17 -> 0
A18: 9 | E18: 0 | F18: 0 | J18: 0 | K18: 0 | L18: =J18+K18 -> 0
A19: 10 | E19: 0 | F19: 0 | J19: 0 | K19: 0 | L19: =J19+K19 -> 0
A20: 11 | E20: 0 | F20: 0 | J20: 0 | K20: 0 | L20: =J20+K20 -> 0
A21: 12 | E21: 0 | F21: 0 | J21: 0 | K21: 0 | L21: =J21+K21 -> 0
A22: 13 | E22: 0 | F22: 0 | J22: 0 | K22: 0 | L22: =J22+K22 -> 0
A23: 14 | E23: 0 | F23: 0 | J23: 0 | K23: 0 | L23: =J23+K23 -> 0
A24: 15 | E24: 0 | F24: 0 | J24: 0 | K24: 0 | L24: =J24+K24 -> 0
A25: 16 | E25: 0 | F25: 0 | J25: 0 | K25: 0 | L25: =J25+K25 -> 0
... A39: 30 | E39: 0 | F39: 0 | J39: 0 | K39: 0 | L39: =J39+K39 -> 0
E40: 0 | F40: 0 | J40: 0 | K40: 0 | L40: =J40+K40 -> 0
E41: =J41*1.11 -> 0 | F41: =K41*1.11 -> 0 | J41: 0 | K41: 0 | L41: =J41+K41 -> 0
E42: 0 | F42: 0 | J42: 0 | K42: 0 | L42: =J42+K42 -> 0
C43: Accumulated Value | E43: =SUM(E10:E42) -> 0 | F43: =SUM(F10:F42) -> 0 | I43: Subtotal: | J43: =SUM(J10:J42) -> 0 | K43: =SUM(K10:K42) -> 0 | L43: =SUM(L10:L42) -> 0
I44: Total: | J44: =SUM(J43:J43) -> 0 | K44: =SUM(K43:K43) -> 0 | L44: =SUM(L43:L43) -> 0

Sheet CO Log
D1: Change Order Log
A2: Expansion Pipeline Project | D2: Contractor | I2: Progress Period | J2: =Summary!G4 -> 42491 | K2: To | L2: =Summary!G3 -> 42505
A5: Change | B5: RFI | C5: Description | D5: Type | E5: Approved | F5: Forecast | G5: Date | H5: Change | I5: Work
A6: Order | B6: Number | D6: RFI | E6: Value | F6: Value | G6: Approved | H6: Order | I6: Status
A7: Number | B7: If Applic. | D7: Change Request | E7: $ | F7: $ | H7: Status | J7: This | K7: Previous | L7: To Date
D8: Change Order | J8: Period | N8: 40321283 | R8: If Negative then CO is Over | S8: Pending | T8: Difference
A10: 1 | B10: N/A | C10: Additional Right-of-Way Stripping (Add $12.44 To Base Lay Price) | D10: Change Order | E10: 863980 | F10: 863980 | G10: 42313 | H10: Executed | I10: Ongoing | J10: 4394.62 | K10: 790957.11 | L10: =J10+K10 -> 795351.73 | N10: =E10+N8 -> 41185263 | R10: =F10-L10 -> 68628.27
A11: 2 | B11: 007 | C11: Additional Two Way Radios For Inspection | D11: Change Order | E11: 7088.55 | F11: 7088.55 | G11: 42317 | H11: Executed | I11: Ongoing | J11: 0 | K11: 0 | L11: =J11+K11 -> 0 | N11: =E11+N10 -> 41192352 | R11: =F11-L11 -> 7088.55
A12: 3 | B12: 020 | C12: Clearing Support | D12: Change Order | E12: 670085.52 | F12: 438132.84 | G12: 42340 | H12: Executed | I12: Complete | J12: 0 | K12: 438132.84 | L12: =J12+K12 -> 438132.84 | N12: =E12+N11 -> 41862437 | R12: =F12-L12 -> 0
A13: 4 | B13: 026R1 | C13: 24Hr Medic Coverage | D13: Change Order | E13: 103635 | F13: 103635 | G13: 42340 | H13: Executed | I13: Complete | J13: 0 | K13: 103635 | L13: =J13+K13 -> 103635 | N13: =E13+N12 -> 41966072 | R13: =F13-L13 -> 0
A14: 5 | B14: 015R3 | C14: Delayed Start Due To Weather- Cost Impacts | D14: Change Order | E14: 555229.22 | F14: 555229.22 | G14: 42345 | H14: Executed | I14: Complete | J14: 0 | K14: 555229.22 | L14: =J14+K14 -> 555229.22 | N14: =E14+N13 -> 42521302 | R14: =F14-L14 -> 0
A15: 6 | B15: N/A | C15: UPIs For Progress Payments Dec 15 & Dec 31 2015 | D15: Change Order | E15: 244345.82 | F15: =L15 -> 244345.82 | G15: 42373 | H15: Executed | I15: Complete | J15: 0 | K15: 244345.82 | L15: =J15+K15 -> 244345.82 | N15: =E15+N14 -> 42765647 | O15: PO added 3 cents On CO 6. | R15: =F15-L15 -> 0
A16: 7 | B16: N/A | C16: UPIs For Progress Payment Jan 15 2016 | D16: Change Order | E16: 86343.77 | F16: 86343.77 | G16: 42388 | H16: Executed | I16: Complete | J16: 0 | K16: 86343.77 | L16: =J16+K16 -> 86343.77 | N16: =E16+N15 -> 42851991 | R16: =F16-L16 -> 0
A17: 8 | B17: N/A | C17: VOID | D17: VOID | E17: 0 | F17: 0 | I17: Complete | J17: 0 | K17: 0 | L17: =J17+K17 -> 0 | N17: =E17+N16 -> 42851991 | R17: =F17-L17 -> 0
A18: 9 | B18: 032 | C18: Digging Test Holes | D18: Change Order | E18: 20000 | F18: 18809.25 | G18: 42390 | H18: Executed | I18: Complete | J18: 0 | K18: 18809.25 | L18: =J18+K18 -> 18809.25 | N18: =E18+N17 -> 42871991 | R18: =F18-L18 -> 0
A19: 10 | B19: 034 | C19: Installation/Removal & Trucking Of Access Mats To The River | D19: Change Order | E19: 80000 | F19: 80000 | G19: 42390 | H19: Executed | I19: Complete | J19: 0 | K19: 80000 | L19: =J19+K19 -> 80000 | N19: =E19+N18 -> 42951991 | R19: =F19-L19 -> 0
A20: 11 | B20: 042 | C20: Digging Sumps | D20: Change Order | E20: 60000 | F20: 59756.38 | G20: 42390 | H20: Executed | I20: Complete | J20: 0 | K20: 59756.38 | L20: =J20+K20 -> 59756.38 | N20: =E20+N19 -> 43011991 | R20: =F20-L20 -> 0
A21: 12 | B21: 046 | C21: Performance Vac- Mud Disposal | D21: Change Order | E21: 25000 | F21: 25000 | G21: 42390 | H21: Executed | I21: Ongoing | J21: 0 | K21: 0 | L21: =J21+K21 -> 0 | N21: =E21+N20 -> 43036991 | R21: =F21-L21 -> 25000
A22: 13 | B22: 048 | C22: Rework Due To Survey Error | D22: Change Order | E22: 4250.2 | F22: 3397.2 | G22: 42390 | H22: Executed | I22: Complete | J22: 0 | K22: 3397.2 | L22: =J22+K22 -> 3397.2 | N22: =E22+N21 -> 43041241 | R22: =F22-L22 -> 0
A23: 14 | B23: 050 | C23: Paragon Soils Test Holes & Repair Factory Holidays | D23: Change Order | E23: 2070.78 | F23: 686.9 | G23: 42390 | H23: Executed | I23: Complete | J23: 0 | K23: 686.9 | L23: =J23+K23 -> 686.9 | N23: =E23+N22 -> 43043312 | R23: =F23-L23 -> 0
A24: 15 | B24: N/A | C24: Miscellaneous Additional Costs | D24: Change Order | E24: 50000 | F24: 50000 | G24: 42390 | H24: Executed | I24: Ongoing | J24: 2238.76 | K24: 29808.89 | L24: =J24+K24 -> 32047.65 | N24: =E24+N23 -> 43093312 | R24: =F24-L24 -> 17952.35
A25: 16 | B25: N/A | C25: Damage To Irrigation Pipe | D25: Change Order | E25: 5991.3 | F25: 5991.3 | G25: 42390 | H25: Executed | I25: Complete | J25: 0 | K25: 5991.3 | L25: =J25+K25 -> 5991.3 | N25: =E25+N24 -> 43099304 | R25: =F25-L25 -> 0
A26: 17 | B26: 044 | C26: Unloading Mats | D26: Change Order | E26: 19408 | F26: 19410 | G26: 42395 | H26: Executed | I26: Ongoing | J26: 0 | K26: 5958.87 | L26: =J26+K26 -> 5958.87 | N26: =E26+N25 -> 43118712 | R26: =F26-L26 -> 13451.13
A27: 18 | B27: 059 | C27: Haul Water For ROW Freezing | D27: Change Order | E27: 23684.06 | F27: 23684.06 | G27: 42396 | H27: Executed | I27: Complete | J27: 0 | K27: 23684.06 | L27: =J27+K27 -> 23684.06 | N27: =E27+N26 -> 43142396 | R27: =F27-L27 -> 0
A28: 19 | B28: 062 | C28: Consultant For Long Run Crossing | D28: Change Order | E28: 5040 | F28: 4410 | G28: 42396 | H28: Executed | I28: Complete | J28: 0 | K28: 4410 | L28: =J28+K28 -> 4410 | N28: =E28+N27 -> 43147436 | R28: =F28-L28 -> 0
A29: 20 | B29: 067 | C29: Drilling Support- Extended Schedule At River | D29: Change Order | E29: 88667.52 | F29: 88667.52 | G29: 42396 | H29: Executed | I29: Complete | J29: 0 | K29: 88667.52 | L29: =J29+K29 -> 88667.52 | N29: =E29+N28 -> 43236103 | R29: =F29-L29 -> 0
... A33: 24 | B33: 071 & 072 | C33: Additional Tie-In Support And HDD Support Crews | D33: Change Order | E33: 1964511.4 | F33: 1964511.4 | G33: 42403 | H33: Executed | I33: Complete | J33: 0 | K33: 1964511.4 | L33: =J33+K33 -> 1964511.4 | N33: =E33+N32 -> 45842231 | R33: =F33-L33 -> 0
A34: 25 | B34: N/A | C34: VOID | D34: VOID | E34: 0 | F34: 0 | I34: Complete | J34: 0 | K34: 0 | L34: =J34+K34 -> 0 | N34: =E34+N33 -> 45842231 | R34: =F34-L34 -> 0
A35: 26 | B35: N/A | C35: UPIs For Progress Payment Jan 31 2016 | D35: Change Order | E35: 85583.22 | F35: 85583.22 | G35: 42403 | H35: Executed | I35: Complete | J35: 0 | K35: 85583.22 | L35: =J35+K35 -> 85583.22 | N35: =E35+N34 -> 45927814 | R35: =F35-L35 -> 0
A36: 27 | B36: N/A | C36: Existing Piping Removal At Station | D36: Change Order | E36: 200000 | F36: 85020.86 | G36: 42416 | H36: Executed | I36: Complete | J36: 0 | K36: 85020.86 | L36: =J36+K36 -> 85020.86 | N36: =E36+N35 -> 46127814 | R36: =F36-L36 -> 0
A37: 28 | B37: N/A | C37: UPIs For Progress Payment Feb 15 2016 | D37: Change Order | E37: 131183 | F37: 131183 | G37: 42422 | H37: Executed | I37: Complete | J37: 0 | K37: 131183 | L37: =J37+K37 -> 131183 | N37: =E37+N36 -> 46258997 | R37: =F37-L37 -> 0
A38: 29 | B38: 094 | C38: Stumping & Grubbing Not Completed By Clearing Contractor | D38: Change Order | E38: 22069.31 | F38: 22059.31 | G38: 42424 | H38: Executed | I38: Complete | J38: 0 | K38: 22059.31 | L38: =J38+K38 -> 22059.31 | N38: =E38+N37 -> 46281067 | R38: =F38-L38 -> 0
A39: 30 | B39: 093 | C39: 24Hr Medic Coverage (Additional To C004) | D39: Change Order | E39: 150785.25 | F39: 137550 | G39: 42424 | H39: Executed | I39: Complete | J39: 0 | K39: 137550 | L39: =J39+K39 -> 137550 | N39: =E39+N38 -> 46431852 | R39: =F39-L39 -> 0
A40: 31 | B40: 034 | C40: Installation/Removal & Trucking Of Access Mats To The Cutbank River (Addit. To C010) | D40: Change Order | E40: 2965.6 | F40: 2965.6 | G40: 42424 | H40: Executed | I40: Complete | J40: 0 | K40: 2965.6 | L40: =J40+K40 -> 2965.6 | N40: =E40+N39 -> 46434818 | R40: =F40-L40 -> 0
A41: 32 | B41: N/A | C41: Additional Force Account Equipment Rates | D41: Change Order | E41: 0 | F41: 0 | G41: 42424 | H41: Executed | I41: Complete | J41: 0 | K41: 0 | L41: =J41+K41 -> 0 | N41: =E41+N40 -> 46434818 | R41: =F41-L41 -> 0
A42: 33 | B42: 092 | C42: Mix And Backfill HDD Mud Sump Pits | D42: Change Order | E42: 165080.96 | F42: 165041.2 | G42: 42424 | H42: Executed | I42: Complete | J42: 0 | K42: 165041.2 | L42: =J42+K42 -> 165041.2 | N42: =E42+N41 -> 46599899 | R42: =F42-L42 -> 0 | S42: 137519.85 | T42: =S42-R42 -> 137519.85
A43: 34 | B43: N/A | C43: Remove Merchantable Timber When Mills Were Closed | D43: Change Order | E43: 5512.5 | F43: 5512.5 | G43: 42438 | H43: Executed | I43: Complete | J43: 0 | K43: 5512.5 | L43: =J43+K43 -> 5512.5 | N43: =E43+N42 -> 46605411 | R43: =F43-L43 -> 0
A44: 35 | B44: N/A | C44: UPIs For Progress Payment Feb 29 2016 | D44: Change Order | E44: 645875.24 | F44: 645875.24 | G44: 42438 | H44: Executed | I44: Complete | J44: 0 | K44: 645875.24 | L44: =J44+K44 -> 645875.24 | N44: =E44+N43 -> 47251286 | R44: =F44-L44 -> 0
A45: 36 | B45: N/A | C45: UPIs For Progress Payment Mar 15 2016 | D45: Change Order | E45: 284494.98 | F45: 284494.98 | G45: 42452 | H45: Executed | I45: Complete | J45: 0 | K45: 284494.98 | L45: =J45+K45 -> 284494.98 | N45: =E45+N44 -> 47535781 | R45: =F45-L45 -> 0
A46: 37 | B46: 091 | C46: Water Trucks To Support HDD Rigs | D46: Change Order | E46: 67500 | F46: 42875.6 | G46: 42452 | H46: Executed | I46: Complete | J46: 0 | K46: 42875.6 | L46: =J46+K46 -> 42875.6 | N46: =E46+N45 -> 47603281 | R46: =F46-L46 -> 0
...

Sheet CO001
A1: WAPITI EXPANSION PIPELINE PROJECT
A6: EXTRA WORK SUMMARY
A7: CO# | B7: 001
A9: Item | B9: Additional Right-Of-Way Stripping: Add $12.44/m To Base Lay Price
I10: Billing Date: | J10: 42323
C11: 69435 | D11: % | E11: 12.443004 | F11: Total To Date | G11: Previous | H11: This Period | I11: Amount This Period ($) | J11: Total Earned Previously ($) | K11: Amount Earned To Date ($)
A12: 1.1 | B12: Mobilization | C12: Per Lin. m | D12: 0.02 | E12: =$E$11*D12 -> 0.24886008 | F12: =G12+H12 -> 34718 | H12: 34718 | I12: =H12*E12 -> 8639.9244 | J12: =G12*E12 -> 0 | K12: =SUM(I12:J12) -> 8639.9244
B13: Grade ROW | C13: Per Lin. m | D13: 0.08 | E13: =$E$11*D13 -> 0.99544034 | F13: =G13+H13 -> 0 | I13: =H13*E13 -> 0 | J13: =G13*E13 -> 0 | K13: =SUM(I13:J13) -> 0
B14: Haul and String Ppipe | C14: Per Lin. m | D14: 0.07 | E14: =$E$11*D14 -> 0.8710103 | F14: =G14+H14 -> 0 | I14: =H14*E14 -> 0 | J14: =G14*E14 -> 0 | K14: =SUM(I14:J14) -> 0
B15: Bending | C15: Per Lin. m | D15: 0.07 | E15: =$E$11*D15 -> 0.8710103 | F15: =G15+H15 -> 0 | I15: =H15*E15 -> 0 | J15: =G15*E15 -> 0 | K15: =SUM(I15:J15) -> 0
B16: Welding | C16: Per Lin. m | D16: 0.17 | E16: =$E$11*D16 -> 2.1153107 | F16: =G16+H16 -> 0 | I16: =H16*E16 -> 0 | J16: =G16*E16 -> 0 | K16: =SUM(I16:J16) -> 0
B17: Excavate Pipe Trench | C17: Per Lin. m | D17: 0.08 | E17: =$E$11*D17 -> 0.99544034 | F17: =G17+H17 -> 0 | I17: =H17*E17 -> 0 | J17: =G17*E17 -> 0 | K17: =SUM(I17:J17) -> 0
B18: Lower-In Pipe | C18: Per Lin. m | D18: 0.07 | E18: =$E$11*D18 -> 0.8710103 | F18: =G18+H18 -> 0 | I18: =H18*E18 -> 0 | J18: =G18*E18 -> 0 | K18: =SUM(I18:J18) -> 0
B19: Backfill | C19: Per Lin. m | D19: 0.08 | E19: =$E$11*D19 -> 0.99544034 | F19: =G19+H19 -> 0 | I19: =H19*E19 -> 0 | J19: =G19*E19 -> 0 | K19: =SUM(I19:J19) -> 0
B20: Tie-Ins | C20: Per Lin. m | D20: 0.07 | E20: =$E$11*D20 -> 0.8710103 | F20: =G20+H20 -> 0 | I20: =H20*E20 -> 0 | J20: =G20*E20 -> 0 | K20: =SUM(I20:J20) -> 0
B21: Testing | C21: Per Lin. m | D21: 0.07 | E21: =$E$11*D21 -> 0.8710103 | F21: =G21+H21 -> 0 | I21: =H21*E21 -> 0 | J21: =G21*E21 -> 0 | K21: =SUM(I21:J21) -> 0
B22: Final Tie-Ins | C22: Per Lin. m | D22: 0.05 | E22: =$E$11*D22 -> 0.62215021 | F22: =G22+H22 -> 0 | I22: =H22*E22 -> 0 | J22: =G22*E22 -> 0 | K22: =SUM(I22:J22) -> 0
B23: Cleanup/Reclamation/Seeding | C23: Per Lin. m | D23: 0.09 | E23: =$E$11*D23 -> 1.1198704 | F23: =G23+H23 -> 0 | I23: =H23*E23 -> 0 | J23: =G23*E23 -> 0 | K23: =SUM(I23:J23) -> 0
B24: Demobilization | C24: Per Lin. m | D24: 0.02 | E24: =$E$11*D24 -> 0.24886008 | F24: =G24+H24 -> 0 | I24: =H24*E24 -> 0 | J24: =G24*E24 -> 0 | K24: =SUM(I24:J24) -> 0
B25: Final Clean Up (one year later) | C25: Per Lin. m | D25: 0.06 | E25: =$E$11*D25 -> 0.74658025 | F25: =G25+H25 -> 0 | I25: =H25*E25 -> 0 | J25: =G25*E25 -> 0 | K25: =SUM(I25:J25) -> 0
D26: =SUM(D12:D25) -> 1 | E26: =SUM(E12:E25) -> 12.443004 | H26: Total For Base Lay Price: | I26: =SUM(I12:I25) -> 8639.9244 | J26: =SUM(J12:J25) -> 0 | K26: =SUM(K12:K25) -> 8639.9244
A29: Contractor
I33: Chief Inspector
H37: Approved CO Value ($) | J37: CO To Date ($)
H38: 863980 | J38: =K26 -> 8639.9244
A41: WAPITI EXPANSION PIPELINE PROJECT
A46: EXTRA WORK SUMMARY
A47: CO# | B47: 001
A49: Item | B49: Additional Right-Of-Way Stripping: Add $12.44/m To Base Lay Price
I50: Billing Date: | J50: 42338
C51: 69435 | D51: % | E51: 12.443004 | F51: Total To Date | G51: Previous | H51: This Period | I51: Amount This Period ($) | J51: Total Earned Previously ($) | K51: Amount Earned To Date ($)
A52: 1.1 | B52: Mobilization | C52: Per Lin. m | D52: 0.02 | E52: =$E$51*D52 -> 0.24886008 | F52: =G52+H52 -> 69435 | G52: 34718 | H52: 34717 | I52: =H52*E52 -> 8639.6756 | J52: =G52*E52 -> 8639.9244 | K52: 17279.6
B53: Grade ROW | C53: Per Lin. m | D53: 0.08 | E53: =$E$51*D53 -> 0.99544034 | F53: =G53+H53 -> 5300 | H53: 5300 | I53: =H53*E53 -> 5275.8338 | J53: =G53*E53 -> 0 | K53: 5275.83
B54: Haul and String Pipe | C54: Per Lin. m | D54: 0.07 | E54: =$E$51*D54 -> 0.8710103 | F54: =G54+H54 -> 400 | H54: 400 | I54: =H54*E54 -> 348.40412 | J54: =G54*E54 -> 0 | K54: 348.4
B55: Bending | C55: Per Lin. m | D55: 0.07 | E55: =$E$51*D55 -> 0.8710103 | F55: =G55+H55 -> 0 | I55: =H55*E55 -> 0 | J55: =G55*E55 -> 0 | K55: =SUM(I55:J55) -> 0
B56: Welding | C56: Per Lin. m | D56: 0.17 | E56: =$E$51*D56 -> 2.1153107 | F56: =G56+H56 -> 0 | I56: =H56*E56 -> 0 | J56: =G56*E56 -> 0 | K56: =SUM(I56:J56) -> 0
B57: Excavate Pipe Trench | C57: Per Lin. m | D57: 0.08 | E57: =$E$51*D57 -> 0.99544034 | F57: =G57+H57 -> 0 | I57: =H57*E57 -> 0 | J57: =G57*E57 -> 0 | K57: =SUM(I57:J57) -> 0
B58: Lower-In Pipe | C58: Per Lin. m | D58: 0.07 | E58: =$E$51*D58 -> 0.8710103 | F58: =G58+H58 -> 0 | I58: =H58*E58 -> 0 | J58: =G58*E58 -> 0 | K58: =SUM(I58:J58) -> 0
B59: Backfill | C59: Per Lin. m | D59: 0.08 | E59: =$E$51*D59 -> 0.99544034 | F59: =G59+H59 -> 0 | I59: =H59*E59 -> 0 | J59: =G59*E59 -> 0 | K59: =SUM(I59:J59) -> 0
B60: Tie-Ins | C60: Per Lin. m | D60: 0.07 | E60: =$E$51*D60 -> 0.8710103 | F60: =G60+H60 -> 0 | I60: =H60*E60 -> 0 | J60: =G60*E60 -> 0 | K60: =SUM(I60:J60) -> 0
...

Sheet CO002
A1: =Summary!G11 -> PIPELINE PROJECT
A13: EXTRA WORK SUMMARY
A14: CO# | B14: 002
D16: Billing Date: | E16: =Summary!G3 -> 42505
A17: Item | B17: Additional Two Way Radios For Inspection
A19: Date | B19: Description | C19: This Period | D19: Previous | E19: Total To Date
E20: =C20+D20 -> 0
C21: 25000 | E21: =C21+D21 -> 25000
C22: 25000 | E22: =C22+D22 -> 25000
E23: =C23+D23 -> 0
E24: =C24+D24 -> 0
E25: =C25+D25 -> 0
E26: =C26+D26 -> 0
E27: =C27+D27 -> 0
E28: =C28+D28 -> 0
E29: =C29+D29 -> 0
E30: =C30+D30 -> 0
B31: Total | C31: =SUM(C20:C30) -> 50000 | D31: =SUM(D20:D30) -> 0 | E31: =SUM(E20:E30) -> 50000
A33: =Summary!G9 -> Contractor
C37: =Summary!G10 -> Construction Manager
D42: Approved CO Value ($) | E42: CO To Date ($)
D43: 7088.55 | E43: =E31 -> 50000

Sheet CO003
A1: =Summary!$G$11 -> PIPELINE PROJECT
A13: EXTRA WORK SUMMARY
A14: CO# | B14: C03
D16: Date: | E16: 42384
A17: Item | B17: Clearing Support
A19: Date | B19: Description | C19: This Period | D19: Previous | E19: Total To Date | J19: Dec 4- Dec 15 | K19: 8590.84 | L19: 12 | N19: =K19*L19 -> 103090.08
A20: Nov 25- Dec 15 | B20: Support Crew #2 & #3 (30 Days) | C20: 257725.2 | E20: =C20+D20 -> 257725.2 | J20: Nov 25-Dec 13 | K20: 8590.84 | L20: 18 | N20: =K20*L20 -> 154635.12
A21: Dec 16- Dec 21 | B21: Support Crew #2 (6 Days) | C21: 51545.04 | E21: =C21+D21 -> 51545.04 | J21: Dec 16- Dec 21 | K21: 8590.84 | L21: 6 | N21: =K21*L21 -> 51545.04
A22: Jan 3- Jan 12 | B22: Support Crew (9 Days) | C22: 77317.56 | E22: =C22+D22 -> 77317.56 | J22: Jan 3- Jan 12 | K22: 8590.84 | L22: 9 | N22: =K22*L22 -> 77317.56
N23: =SUM(N19:N22) -> 386587.8
B29: Total | C29: =SUM(C20:C28) -> 386587.8 | D29: =SUM(D20:D28) -> 0 | E29: =SUM(E20:E28) -> 386587.8
A31: =Summary!$G$9 -> Contractor
C35: =Summary!$G$10 -> Construction Manager
D42: Approved CO Value ($) | E42: CO To Date ($)
D43: 670085.52 | E43: =E29 -> 386587.8
A45: =Summary!$G$11 -> PIPELINE PROJECT
A57: EXTRA WORK SUMMARY
A58: CO# | B58: C03
D60: Date: | E60: 42400
A61: Item | B61: Clearing Support
A63: Date | B63: Description | C63: This Period | D63: Previous | E63: Total To Date | J63: Dec 4- Dec 15 | K63: 8590.84 | L63: 12 | N63: =K63*L63 -> 103090.08
A64: Nov 25- Dec 15 | B64: Support Crew #2 & #3 (30 Days) | D64: 257725.2 | E64: =C64+D64 -> 257725.2 | J64: Nov 25-Dec 13 | K64: 8590.84 | L64: 18 | N64: =K64*L64 -> 154635.12
A65: Dec 16- Dec 21 | B65: Support Crew #2 (6 Days) | D65: 51545.04 | E65: =C65+D65 -> 51545.04 | J65: Dec 16- Dec 21 | K65: 8590.84 | L65: 6 | N65: =K65*L65 -> 51545.04
A66: Jan 3- Jan 12 | B66: Support Crew (9 Days) | D66: 77317.56 | E66: =C66+D66 -> 77317.56 | J66: Jan 3- Jan 12 | K66: 8590.84 | L66: 9 | N66: =K66*L66 -> 77317.56
A67: Jan 14- Jan 21 | B67: Support Crew (6 Days) | C67: 51545.04 | E67: =C67+D67 -> 51545.04 | J67: Jan 14- Jan 21 | K67: 8590.84 | L67: 6 | N67: =K67*L67 -> 51545.04
N69: =SUM(N63:N68) -> 438132.84
B73: Total | C73: =SUM(C64:C72) -> 51545.04 | D73: =SUM(D64:D72) -> 386587.8 | E73: =SUM(E64:E72) -> 438132.84
A75: =Summary!$G$9 -> Contractor
C79: =Summary!$G$10 -> Construction Manager
D86: Approved CO Value ($) | E86: CO To Date ($)
D87: 670085.52 | E87: =E73 -> 438132.84
A89: =Summary!$G$11 -> PIPELINE PROJECT
A101: EXTRA WORK SUMMARY
A102: CO# | B102: C03
D104: Date: | E104: =Summary!$G$3 -> 42505
A105: Item | B105: Clearing Support
A107: Date | B107: Description | C107: This Period | D107: Previous | E107: Total To Date
A108: Nov 25- Dec 15 | B108: Support Crew #2 & #3 (30 Days) | D108: 257725.2 | E108: =C108+D108 -> 257725.2
A109: Dec 16- Dec 21 | B109: Support Crew #2 (6 Days) | D109: 51545.04 | E109: =C109+D109 -> 51545.04
A110: Jan 3- Jan 12 | B110: Support Crew (9 Days) | D110: 77317.56 | E110: =C110+D110 -> 77317.56
...

Sheet CO004
A1: =Summary!$G$11 -> PIPELINE PROJECT
A13: EXTRA WORK SUMMARY
A14: CO# | B14: C04
D16: Date: | E16: 42353
A17: Item | B17: 24 Hour Medic Coverage
A19: Date | B19: Description | C19: This Period | D19: Previous | E19: Total To Date
A21: 42353 | B21: 24 Hour Medic for HDD & Burning Crew | C21: 25357.5 | E21: =C21+D21 -> 25357.5
B29: Total | C29: =SUM(C20:C28) -> 25357.5 | D29: =SUM(D20:D28) -> 0 | E29: =SUM(E20:E28) -> 25357.5
A31: =Summary!$G$9 -> Contractor
C35: =Summary!$G$10 -> Construction Manager
A37: =Summary!$G$11 -> PIPELINE PROJECT
A49: EXTRA WORK SUMMARY
A50: CO# | B50: C04
D52: Date: | E52: 42369
A53: Item | B53: 24 Hour Medic Coverage
A55: Date | B55: Description | C55: This Period | D55: Previous | E55: Total To Date
A57: 42353 | B57: 24 Hour Medic for HDD & Burning Crew | D57: 25357.5 | E57: =C57+D57 -> 25357.5
A58: =E52 -> 42369 | B58: 25 Hour Medic for HDD & Burning Crew | C58: 8820 | E58: =C58+D58 -> 8820
B65: Total | C65: =SUM(C56:C64) -> 8820 | D65: =SUM(D56:D64) -> 25357.5 | E65: =SUM(E56:E64) -> 34177.5
A67: =Summary!$G$9 -> Contractor
C71: =Summary!$G$10 -> Construction Manager
D78: Approved CO Value ($) | E78: CO To Date ($)
D79: 103635 | E79: =E65 -> 34177.5
A81: =Summary!$G$11 -> PIPELINE PROJECT
A93: EXTRA WORK SUMMARY
A94: CO# | B94: C04
D96: Date: | E96: 42384
A97: Item | B97: 24 Hour Medic Coverage
A99: Date | B99: Description | C99: This Period | D99: Previous | E99: Total To Date
A101: 42353 | B101: 24 Hour Medic for HDD & Burning Crew (Nov 25-Dec 15) | D101: 25357.5 | E101: =C101+D101 -> 25357.5
A102: 42369 | B102: 25 Hour Medic for HDD & Burning Crew (Dec 16-31) | D102: 8820 | E102: =C102+D102 -> 8820
