Workbook

Sheet Field Log (50)
J1: Date:
G6: Field Log ID: | J6: Status:
A7: Address: | G7: Account #: | J7: Account:
G8: Foreman:
A10: Employee ID | B10: Labor Type | C10: Employee | D10: RT Hours | E10: RT Rate | F10: OT Hours | G10: OT Rate | H10: DT Hours | I10: DT Rate | J10: Sub. | K10: Total | M10: Additional Hours
B11: =VLOOKUP($C$11:$C$24,Personnel!$A$1:$B$1234,2,FALSE) -> 0 | E11: =VLOOKUP($B$11:$B$24,'Constr. Wage Rate Calculations'!$A$19:$Z$288,22,FALSE) -> 0 | G11: =VLOOKUP($B$11:$B$24,'Constr. Wage Rate Calculations'!$A$19:$Z$288,23,FALSE) -> 0 | I11: =VLOOKUP($B$11:$B$24,'Constr. Wage Rate Calculations'!$A$19:$Z$288,24,FALSE) -> 0 | J11: =VLOOKUP($B$11:$B$25,'Constr. Wage Rate Calculations'!$A$19:$Z$288,25,FALSE) -> 0 | K11: =IF($D11>=1,$J11+(D11*E11)+(F11*G11)+(H11*I11),IF($F11>=1,$J11+(D11*E11)+(F11*G11)+(H11*I11),IF($H11>=1,$J11+(D11*E11)+(F11*G11)+(H11*I11),"")))
B12: =VLOOKUP($C$11:$C$24,Personnel!$A$1:$B$1234,2,FALSE) -> 0 | E12: =VLOOKUP($B$11:$B$24,'Constr. Wage Rate Calculations'!$A$19:$Z$288,22,FALSE) -> 0 | G12: =VLOOKUP($B$11:$B$24,'Constr. Wage Rate Calculations'!$A$19:$Z$288,23,FALSE) -> 0 | I12: =VLOOKUP($B$11:$B$24,'Constr. Wage Rate Calculations'!$A$19:$Z$288,24,FALSE) -> 0 | J12: =VLOOKUP($B$11:$B$25,'Constr. Wage Rate Calculations'!$A$19:$Z$288,25,FALSE) -> 0 | K12: =IF($D12>=1,$J12+(D12*E12)+(F12*G12)+(H12*I12),IF($F12>=1,$J12+(D12*E12)+(F12*G12)+(H12*I12),IF($H12>=1,$J12+(D12*E12)+(F12*G12)+(H12*I12),"")))
B13: =VLOOKUP($C$11:$C$24,Personnel!$A$1:$B$1234,2,FALSE) -> 0 | E13: =VLOOKUP($B$11:$B$24,'Constr. Wage Rate Calculations'!$A$19:$Z$288,22,FALSE) -> 0 | G13: =VLOOKUP($B$11:$B$24,'Constr. Wage Rate Calculations'!$A$19:$Z$288,23,FALSE) -> 0 | I13: =VLOOKUP($B$11:$B$24,'Constr. Wage Rate Calculations'!$A$19:$Z$288,24,FALSE) -> 0 | J13: =VLOOKUP($B$11:$B$25,'Constr. Wage Rate Calculations'!$A$19:$Z$288,25,FALSE) -> 0 | K13: =IF($D13>=1,$J13+(D13*E13)+(F13*G13)+(H13*I13),IF($F13>=1,$J13+(D13*E13)+(F13*G13)+(H13*I13),IF($H13>=1,$J13+(D13*E13)+(F13*G13)+(H13*I13),"")))
B14: =VLOOKUP($C$11:$C$24,Personnel!$A$1:$B$1234,2,FALSE) -> 0 | E14: =VLOOKUP($B$11:$B$24,'Constr. Wage Rate Calculations'!$A$19:$Z$288,22,FALSE) -> 0 | G14: =VLOOKUP($B$11:$B$24,'Constr. Wage Rate Calculations'!$A$19:$Z$288,23,FALSE) -> 0 | I14: =VLOOKUP($B$11:$B$24,'Constr. Wage Rate Calculations'!$A$19:$Z$288,24,FALSE) -> 0 | J14: =VLOOKUP($B$11:$B$25,'Constr. Wage Rate Calculations'!$A$19:$Z$288,25,FALSE) -> 0 | K14: =IF($D14>=1,$J14+(D14*E14)+(F14*G14)+(H14*I14),IF($F14>=1,$J14+(D14*E14)+(F14*G14)+(H14*I14),IF($H14>=1,$J14+(D14*E14)+(F14*G14)+(H14*I14),"")))
B15: =VLOOKUP($C$11:$C$24,Personnel!$A$1:$B$1234,2,FALSE) -> 0 | E15: =VLOOKUP($B$11:$B$24,'Constr. Wage Rate Calculations'!$A$19:$Z$288,22,FALSE) -> 0 | G15: =VLOOKUP($B$11:$B$24,'Constr. Wage Rate Calculations'!$A$19:$Z$288,23,FALSE) -> 0 | I15: =VLOOKUP($B$11:$B$24,'Constr. Wage Rate Calculations'!$A$19:$Z$288,24,FALSE) -> 0 | J15: =VLOOKUP($B$11:$B$25,'Constr. Wage Rate Calculations'!$A$19:$Z$288,25,FALSE) -> 0 | K15: =IF($D15>=1,$J15+(D15*E15)+(F15*G15)+(H15*I15),IF($F15>=1,$J15+(D15*E15)+(F15*G15)+(H15*I15),IF($H15>=1,$J15+(D15*E15)+(F15*G15)+(H15*I15),"")))
B16: =VLOOKUP($C$11:$C$24,Personnel!$A$1:$B$1234,2,FALSE) -> 0 | E16: =VLOOKUP($B$11:$B$24,'Constr. Wage Rate Calculations'!$A$19:$Z$288,22,FALSE) -> 0 | G16: =VLOOKUP($B$11:$B$24,'Constr. Wage Rate Calculations'!$A$19:$Z$288,23,FALSE) -> 0 | I16: =VLOOKUP($B$11:$B$24,'Constr. Wage Rate Calculations'!$A$19:$Z$288,24,FALSE) -> 0 | J16: =VLOOKUP($B$11:$B$25,'Constr. Wage Rate Calculations'!$A$19:$Z$288,25,FALSE) -> 0 | K16: =IF($D16>=1,$J16+(D16*E16)+(F16*G16)+(H16*I16),IF($F16>=1,$J16+(D16*E16)+(F16*G16)+(H16*I16),IF($H16>=1,$J16+(D16*E16)+(F16*G16)+(H16*I16),"")))
B17: =VLOOKUP($C$11:$C$24,Personnel!$A$1:$B$1234,2,FALSE) -> 0 | E17: =VLOOKUP($B$11:$B$24,'Constr. Wage Rate Calculations'!$A$19:$Z$288,22,FALSE) -> 0 | G17: =VLOOKUP($B$11:$B$24,'Constr. Wage Rate Calculations'!$A$19:$Z$288,23,FALSE) -> 0 | I17: =VLOOKUP($B$11:$B$24,'Constr. Wage Rate Calculations'!$A$19:$Z$288,24,FALSE) -> 0 | J17: =VLOOKUP($B$11:$B$25,'Constr. Wage Rate Calculations'!$A$19:$Z$288,25,FALSE) -> 0 | K17: =IF($D17>=1,$J17+(D17*E17)+(F17*G17)+(H17*I17),IF($F17>=1,$J17+(D17*E17)+(F17*G17)+(H17*I17),IF($H17>=1,$J17+(D17*E17)+(F17*G17)+(H17*I17),"")))
B18: =VLOOKUP($C$11:$C$24,Personnel!$A$1:$B$1234,2,FALSE) -> 0 | E18: =VLOOKUP($B$11:$B$24,'Constr. Wage Rate Calculations'!$A$19:$Z$288,22,FALSE) -> 0 | G18: =VLOOKUP($B$11:$B$24,'Constr. Wage Rate Calculations'!$A$19:$Z$288,23,FALSE) -> 0 | I18: =VLOOKUP($B$11:$B$24,'Constr. Wage Rate Calculations'!$A$19:$Z$288,24,FALSE) -> 0 | J18: =VLOOKUP($B$11:$B$25,'Constr. Wage Rate Calculations'!$A$19:$Z$288,25,FALSE) -> 0 | K18: =IF($D18>=1,$J18+(D18*E18)+(F18*G18)+(H18*I18),IF($F18>=1,$J18+(D18*E18)+(F18*G18)+(H18*I18),IF($H18>=1,$J18+(D18*E18)+(F18*G18)+(H18*I18),"")))
B19: =VLOOKUP($C$11:$C$24,Personnel!$A$1:$B$1234,2,FALSE) -> 0 | E19: =VLOOKUP($B$11:$B$24,'Constr. Wage Rate Calculations'!$A$19:$Z$288,22,FALSE) -> 0 | G19: =VLOOKUP($B$11:$B$24,'Constr. Wage Rate Calculations'!$A$19:$Z$288,23,FALSE) -> 0 | I19: =VLOOKUP($B$11:$B$24,'Constr. Wage Rate Calculations'!$A$19:$Z$288,24,FALSE) -> 0 | J19: =VLOOKUP($B$11:$B$25,'Constr. Wage Rate Calculations'!$A$19:$Z$288,25,FALSE) -> 0 | K19: =IF($D19>=1,$J19+(D19*E19)+(F19*G19)+(H19*I19),IF($F19>=1,$J19+(D19*E19)+(F19*G19)+(H19*I19),IF($H19>=1,$J19+(D19*E19)+(F19*G19)+(H19*I19),"")))
B20: =VLOOKUP($C$11:$C$24,Personnel!$A$1:$B$1234,2,FALSE) -> 0 | E20: =VLOOKUP($B$11:$B$24,'Constr. Wage Rate Calculations'!$A$19:$Z$288,22,FALSE) -> 0 | G20: =VLOOKUP($B$11:$B$24,'Constr. Wage Rate Calculations'!$A$19:$Z$288,23,FALSE) -> 0 | I20: =VLOOKUP($B$11:$B$24,'Constr. Wage Rate Calculations'!$A$19:$Z$288,24,FALSE) -> 0 | J20: =VLOOKUP($B$11:$B$25,'Constr. Wage Rate Calculations'!$A$19:$Z$288,25,FALSE) -> 0 | K20: =IF($D20>=1,$J20+(D20*E20)+(F20*G20)+(H20*I20),IF($F20>=1,$J20+(D20*E20)+(F20*G20)+(H20*I20),IF($H20>=1,$J20+(D20*E20)+(F20*G20)+(H20*I20),"")))
B21: =VLOOKUP($C$11:$C$24,Personnel!$A$1:$B$1234,2,FALSE) -> 0 | E21: =VLOOKUP($B$11:$B$24,'Constr. Wage Rate Calculations'!$A$19:$Z$288,22,FALSE) -> 0 | G21: =VLOOKUP($B$11:$B$24,'Constr. Wage Rate Calculations'!$A$19:$Z$288,23,FALSE) -> 0 | I21: =VLOOKUP($B$11:$B$24,'Constr. Wage Rate Calculations'!$A$19:$Z$288,24,FALSE) -> 0 | J21: =VLOOKUP($B$11:$B$25,'Constr. Wage Rate Calculations'!$A$19:$Z$288,25,FALSE) -> 0 | K21: =IF($D21>=1,$J21+(D21*E21)+(F21*G21)+(H21*I21),IF($F21>=1,$J21+(D21*E21)+(F21*G21)+(H21*I21),IF($H21>=1,$J21+(D21*E21)+(F21*G21)+(H21*I21),"")))
B22: =VLOOKUP($C$11:$C$24,Personnel!$A$1:$B$1234,2,FALSE) -> 0 | E22: =VLOOKUP($B$11:$B$24,'Constr. Wage Rate Calculations'!$A$19:$Z$288,22,FALSE) -> 0 | G22: =VLOOKUP($B$11:$B$24,'Constr. Wage Rate Calculations'!$A$19:$Z$288,23,FALSE) -> 0 | I22: =VLOOKUP($B$11:$B$24,'Constr. Wage Rate Calculations'!$A$19:$Z$288,24,FALSE) -> 0 | J22: =VLOOKUP($B$11:$B$25,'Constr. Wage Rate Calculations'!$A$19:$Z$288,25,FALSE) -> 0 | K22: =IF($D22>=1,$J22+(D22*E22)+(F22*G22)+(H22*I22),IF($F22>=1,$J22+(D22*E22)+(F22*G22)+(H22*I22),IF($H22>=1,$J22+(D22*E22)+(F22*G22)+(H22*I22),"")))
B23: =VLOOKUP($C$11:$C$24,Personnel!$A$1:$B$1234,2,FALSE) -> 0 | E23: =VLOOKUP($B$11:$B$24,'Constr. Wage Rate Calculations'!$A$19:$Z$288,22,FALSE) -> 0 | G23: =VLOOKUP($B$11:$B$24,'Constr. Wage Rate Calculations'!$A$19:$Z$288,23,FALSE) -> 0 | I23: =VLOOKUP($B$11:$B$24,'Constr. Wage Rate Calculations'!$A$19:$Z$288,24,FALSE) -> 0 | J23: =VLOOKUP($B$11:$B$25,'Constr. Wage Rate Calculations'!$A$19:$Z$288,25,FALSE) -> 0 | K23: =IF($D23>=1,$J23+(D23*E23)+(F23*G23)+(H23*I23),IF($F23>=1,$J23+(D23*E23)+(F23*G23)+(H23*I23),IF($H23>=1,$J23+(D23*E23)+(F23*G23)+(H23*I23),"")))
B24: =VLOOKUP($C$11:$C$24,Personnel!$A$1:$B$1234,2,FALSE) -> 0 | E24: =VLOOKUP($B$11:$B$24,'Constr. Wage Rate Calculations'!$A$19:$Z$288,22,FALSE) -> 0 | G24: =VLOOKUP($B$11:$B$24,'Constr. Wage Rate Calculations'!$A$19:$Z$288,23,FALSE) -> 0 | I24: =VLOOKUP($B$11:$B$24,'Constr. Wage Rate Calculations'!$A$19:$Z$288,24,FALSE) -> 0 | J24: =VLOOKUP($B$11:$B$25,'Constr. Wage Rate Calculations'!$A$19:$Z$288,25,FALSE) -> 0 | K24: =IF($D24>=1,$J24+(D24*E24)+(F24*G24)+(H24*I24),IF($F24>=1,$J24+(D24*E24)+(F24*G24)+(H24*I24),IF($H24>=1,$J24+(D24*E24)+(F24*G24)+(H24*I24),""))) | M24: =SUM(M11:M23) -> 0
I25: TOTAL LABOUR | K25: =SUM(K11:K24) -> 0 | M25: =SUMIFS(D11:D24,D11:D24,"<3",D11:D24,"<5") -> 0 | N25: =SUMIFS(D11:D24,D11:D24,">3",D11:D24,">5") -> 0 | O25: =SUM(F11:F24,H11:H24,M25,N25)-M24 -> 0
A27: Equipment ID | B27: Equipment | H27: Days | I27: Hrs. | J27: Rate | K27: Total
B28: =VLOOKUP($C$28:$C$49,Equipment!$A$1:$B$2322,2,FALSE) -> 0 | J28: =VLOOKUP($B$28:$B$49,'Alberta Equip. Rates Year 3'!$B$13:$K$314,10,FALSE) -> 0 | K28: =(H28+I28)*J28 -> 0
B29: =VLOOKUP($C$28:$C$49,Equipment!$A$1:$B$2322,2,FALSE) -> 0 | J29: =VLOOKUP($B$28:$B$49,'Alberta Equip. Rates Year 3'!$B$13:$K$314,10,FALSE) -> 0 | K29: =(H29+I29)*J29 -> 0
B30: =VLOOKUP($C$28:$C$49,Equipment!$A$1:$B$2322,2,FALSE) -> 0 | J30: =VLOOKUP($B$28:$B$49,'Alberta Equip. Rates Year 3'!$B$13:$K$314,10,FALSE) -> 0 | K30: =(H30+I30)*J30 -> 0
B31: =VLOOKUP($C$28:$C$49,Equipment!$A$1:$B$2322,2,FALSE) -> 0 | J31: =VLOOKUP($B$28:$B$49,'Alberta Equip. Rates Year 3'!$B$13:$K$314,10,FALSE) -> 0 | K31: =(H31+I31)*J31 -> 0
B32: =VLOOKUP($C$28:$C$49,Equipment!$A$1:$B$2322,2,FALSE) -> 0 | J32: =VLOOKUP($B$28:$B$49,'Alberta Equip. Rates Year 3'!$B$13:$K$314,10,FALSE) -> 0 | K32: =(H32+I32)*J32 -> 0
B33: =VLOOKUP($C$28:$C$49,Equipment!$A$1:$B$2322,2,FALSE) -> 0 | J33: =VLOOKUP($B$28:$B$49,'Alberta Equip. Rates Year 3'!$B$13:$K$314,10,FALSE) -> 0 | K33: =(H33+I33)*J33 -> 0
B34: =VLOOKUP($C$28:$C$49,Equipment!$A$1:$B$2322,2,FALSE) -> 0 | J34: =VLOOKUP($B$28:$B$49,'Alberta Equip. Rates Year 3'!$B$13:$K$314,10,FALSE) -> 0 | K34: =(H34+I34)*J34 -> 0
B35: =VLOOKUP($C$28:$C$49,Equipment!$A$1:$B$2322,2,FALSE) -> 0 | J35: =VLOOKUP($B$28:$B$49,'Alberta Equip. Rates Year 3'!$B$13:$K$314,10,FALSE) -> 0 | K35: =(H35+I35)*J35 -> 0
B36: =VLOOKUP($C$28:$C$49,Equipment!$A$1:$B$2322,2,FALSE) -> 0 | J36: =VLOOKUP($B$28:$B$49,'Alberta Equip. Rates Year 3'!$B$13:$K$314,10,FALSE) -> 0 | K36: =(H36+I36)*J36 -> 0
B37: =VLOOKUP($C$28:$C$49,Equipment!$A$1:$B$2322,2,FALSE) -> 0 | J37: =VLOOKUP($B$28:$B$49,'Alberta Equip. Rates Year 3'!$B$13:$K$314,10,FALSE) -> 0 | K37: =(H37+I37)*J37 -> 0
B38: =VLOOKUP($C$28:$C$49,Equipment!$A$1:$B$2322,2,FALSE) -> 0 | J38: =VLOOKUP($B$28:$B$49,'Alberta Equip. Rates Year 3'!$B$13:$K$314,10,FALSE) -> 0 | K38: =(H38+I38)*J38 -> 0
B39: =VLOOKUP($C$28:$C$49,Equipment!$A$1:$B$2322,2,FALSE) -> 0 | J39: =VLOOKUP($B$28:$B$49,'Alberta Equip. Rates Year 3'!$B$13:$K$314,10,FALSE) -> 0 | K39: =(H39+I39)*J39 -> 0
... B49: =VLOOKUP($C$28:$C$49,Equipment!$A$1:$B$2322,2,FALSE) -> 0 | J49: =VLOOKUP($B$28:$B$49,'Alberta Equip. Rates Year 3'!$B$13:$K$314,10,FALSE) -> 0 | K49: =(H49+I49)*J49 -> 0
I50: TOTAL EQUIPMENT | K50: =SUM(K28:K49) -> 0
A52: Scope of Work: | I52: LABOUR | K52: =K25 -> 0
I53: EQUIPMENT | K53: =K50 -> 0
I54: SMALL TOOLS | K54: =(O25)*14.15 -> 0
I55: MATERIALS
I56: TRUCKING
...

Sheet Field Log (49)
J1: Date:
G6: Field Log ID: | J6: Status:
A7: Address: | G7: Account #: | J7: Account:
G8: Foreman:
A10: Employee ID | B10: Labor Type | C10: Employee | D10: RT Hours | E10: RT Rate | F10: OT Hours | G10: OT Rate | H10: DT Hours | I10: DT Rate | J10: Sub. | K10: Total | M10: Additional Hours
B11: =VLOOKUP($C$11:$C$24,Personnel!$A$1:$B$1234,2,FALSE) -> 0 | E11: =VLOOKUP($B$11:$B$24,'Constr. Wage Rate Calculations'!$A$19:$Z$288,22,FALSE) -> 0 | G11: =VLOOKUP($B$11:$B$24,'Constr. Wage Rate Calculations'!$A$19:$Z$288,23,FALSE) -> 0 | I11: =VLOOKUP($B$11:$B$24,'Constr. Wage Rate Calculations'!$A$19:$Z$288,24,FALSE) -> 0 | J11: =VLOOKUP($B$11:$B$25,'Constr. Wage Rate Calculations'!$A$19:$Z$288,25,FALSE) -> 0 | K11: =IF($D11>=1,$J11+(D11*E11)+(F11*G11)+(H11*I11),IF($F11>=1,$J11+(D11*E11)+(F11*G11)+(H11*I11),IF($H11>=1,$J11+(D11*E11)+(F11*G11)+(H11*I11),"")))
B12: =VLOOKUP($C$11:$C$24,Personnel!$A$1:$B$1234,2,FALSE) -> 0 | E12: =VLOOKUP($B$11:$B$24,'Constr. Wage Rate Calculations'!$A$19:$Z$288,22,FALSE) -> 0 | G12: =VLOOKUP($B$11:$B$24,'Constr. Wage Rate Calculations'!$A$19:$Z$288,23,FALSE) -> 0 | I12: =VLOOKUP($B$11:$B$24,'Constr. Wage Rate Calculations'!$A$19:$Z$288,24,FALSE) -> 0 | J12: =VLOOKUP($B$11:$B$25,'Constr. Wage Rate Calculations'!$A$19:$Z$288,25,FALSE) -> 0 | K12: =IF($D12>=1,$J12+(D12*E12)+(F12*G12)+(H12*I12),IF($F12>=1,$J12+(D12*E12)+(F12*G12)+(H12*I12),IF($H12>=1,$J12+(D12*E12)+(F12*G12)+(H12*I12),"")))
B13: =VLOOKUP($C$11:$C$24,Personnel!$A$1:$B$1234,2,FALSE) -> 0 | E13: =VLOOKUP($B$11:$B$24,'Constr. Wage Rate Calculations'!$A$19:$Z$288,22,FALSE) -> 0 | G13: =VLOOKUP($B$11:$B$24,'Constr. Wage Rate Calculations'!$A$19:$Z$288,23,FALSE) -> 0 | I13: =VLOOKUP($B$11:$B$24,'Constr. Wage Rate Calculations'!$A$19:$Z$288,24,FALSE) -> 0 | J13: =VLOOKUP($B$11:$B$25,'Constr. Wage Rate Calculations'!$A$19:$Z$288,25,FALSE) -> 0 | K13: =IF($D13>=1,$J13+(D13*E13)+(F13*G13)+(H13*I13),IF($F13>=1,$J13+(D13*E13)+(F13*G13)+(H13*I13),IF($H13>=1,$J13+(D13*E13)+(F13*G13)+(H13*I13),"")))
B14: =VLOOKUP($C$11:$C$24,Personnel!$A$1:$B$1234,2,FALSE) -> 0 | E14: =VLOOKUP($B$11:$B$24,'Constr. Wage Rate Calculations'!$A$19:$Z$288,22,FALSE) -> 0 | G14: =VLOOKUP($B$11:$B$24,'Constr. Wage Rate Calculations'!$A$19:$Z$288,23,FALSE) -> 0 | I14: =VLOOKUP($B$11:$B$24,'Constr. Wage Rate Calculations'!$A$19:$Z$288,24,FALSE) -> 0 | J14: =VLOOKUP($B$11:$B$25,'Constr. Wage Rate Calculations'!$A$19:$Z$288,25,FALSE) -> 0 | K14: =IF($D14>=1,$J14+(D14*E14)+(F14*G14)+(H14*I14),IF($F14>=1,$J14+(D14*E14)+(F14*G14)+(H14*I14),IF($H14>=1,$J14+(D14*E14)+(F14*G14)+(H14*I14),"")))
B15: =VLOOKUP($C$11:$C$24,Personnel!$A$1:$B$1234,2,FALSE) -> 0 | E15: =VLOOKUP($B$11:$B$24,'Constr. Wage Rate Calculations'!$A$19:$Z$288,22,FALSE) -> 0 | G15: =VLOOKUP($B$11:$B$24,'Constr. Wage Rate Calculations'!$A$19:$Z$288,23,FALSE) -> 0 | I15: =VLOOKUP($B$11:$B$24,'Constr. Wage Rate Calculations'!$A$19:$Z$288,24,FALSE) -> 0 | J15: =VLOOKUP($B$11:$B$25,'Constr. Wage Rate Calculations'!$A$19:$Z$288,25,FALSE) -> 0 | K15: =IF($D15>=1,$J15+(D15*E15)+(F15*G15)+(H15*I15),IF($F15>=1,$J15+(D15*E15)+(F15*G15)+(H15*I15),IF($H15>=1,$J15+(D15*E15)+(F15*G15)+(H15*I15),"")))
B16: =VLOOKUP($C$11:$C$24,Personnel!$A$1:$B$1234,2,FALSE) -> 0 | E16: =VLOOKUP($B$11:$B$24,'Constr. Wage Rate Calculations'!$A$19:$Z$288,22,FALSE) -> 0 | G16: =VLOOKUP($B$11:$B$24,'Constr. Wage Rate Calculations'!$A$19:$Z$288,23,FALSE) -> 0 | I16: =VLOOKUP($B$11:$B$24,'Constr. Wage Rate Calculations'!$A$19:$Z$288,24,FALSE) -> 0 | J16: =VLOOKUP($B$11:$B$25,'Constr. Wage Rate Calculations'!$A$19:$Z$288,25,FALSE) -> 0 | K16: =IF($D16>=1,$J16+(D16*E16)+(F16*G16)+(H16*I16),IF($F16>=1,$J16+(D16*E16)+(F16*G16)+(H16*I16),IF($H16>=1,$J16+(D16*E16)+(F16*G16)+(H16*I16),"")))
B17: =VLOOKUP($C$11:$C$24,Personnel!$A$1:$B$1234,2,FALSE) -> 0 | E17: =VLOOKUP($B$11:$B$24,'Constr. Wage Rate Calculations'!$A$19:$Z$288,22,FALSE) -> 0 | G17: =VLOOKUP($B$11:$B$24,'Constr. Wage Rate Calculations'!$A$19:$Z$288,23,FALSE) -> 0 | I17: =VLOOKUP($B$11:$B$24,'Constr. Wage Rate Calculations'!$A$19:$Z$288,24,FALSE) -> 0 | J17: =VLOOKUP($B$11:$B$25,'Constr. Wage Rate Calculations'!$A$19:$Z$288,25,FALSE) -> 0 | K17: =IF($D17>=1,$J17+(D17*E17)+(F17*G17)+(H17*I17),IF($F17>=1,$J17+(D17*E17)+(F17*G17)+(H17*I17),IF($H17>=1,$J17+(D17*E17)+(F17*G17)+(H17*I17),"")))
B18: =VLOOKUP($C$11:$C$24,Personnel!$A$1:$B$1234,2,FALSE) -> 0 | E18: =VLOOKUP($B$11:$B$24,'Constr. Wage Rate Calculations'!$A$19:$Z$288,22,FALSE) -> 0 | G18: =VLOOKUP($B$11:$B$24,'Constr. Wage Rate Calculations'!$A$19:$Z$288,23,FALSE) -> 0 | I18: =VLOOKUP($B$11:$B$24,'Constr. Wage Rate Calculations'!$A$19:$Z$288,24,FALSE) -> 0 | J18: =VLOOKUP($B$11:$B$25,'Constr. Wage Rate Calculations'!$A$19:$Z$288,25,FALSE) -> 0 | K18: =IF($D18>=1,$J18+(D18*E18)+(F18*G18)+(H18*I18),IF($F18>=1,$J18+(D18*E18)+(F18*G18)+(H18*I18),IF($H18>=1,$J18+(D18*E18)+(F18*G18)+(H18*I18),"")))
B19: =VLOOKUP($C$11:$C$24,Personnel!$A$1:$B$1234,2,FALSE) -> 0 | E19: =VLOOKUP($B$11:$B$24,'Constr. Wage Rate Calculations'!$A$19:$Z$288,22,FALSE) -> 0 | G19: =VLOOKUP($B$11:$B$24,'Constr. Wage Rate Calculations'!$A$19:$Z$288,23,FALSE) -> 0 | I19: =VLOOKUP($B$11:$B$24,'Constr. Wage Rate Calculations'!$A$19:$Z$288,24,FALSE) -> 0 | J19: =VLOOKUP($B$11:$B$25,'Constr. Wage Rate Calculations'!$A$19:$Z$288,25,FALSE) -> 0 | K19: =IF($D19>=1,$J19+(D19*E19)+(F19*G19)+(H19*I19),IF($F19>=1,$J19+(D19*E19)+(F19*G19)+(H19*I19),IF($H19>=1,$J19+(D19*E19)+(F19*G19)+(H19*I19),"")))
B20: =VLOOKUP($C$11:$C$24,Personnel!$A$1:$B$1234,2,FALSE) -> 0 | E20: =VLOOKUP($B$11:$B$24,'Constr. Wage Rate Calculations'!$A$19:$Z$288,22,FALSE) -> 0 | G20: =VLOOKUP($B$11:$B$24,'Constr. Wage Rate Calculations'!$A$19:$Z$288,23,FALSE) -> 0 | I20: =VLOOKUP($B$11:$B$24,'Constr. Wage Rate Calculations'!$A$19:$Z$288,24,FALSE) -> 0 | J20: =VLOOKUP($B$11:$B$25,'Constr. Wage Rate Calculations'!$A$19:$Z$288,25,FALSE) -> 0 | K20: =IF($D20>=1,$J20+(D20*E20)+(F20*G20)+(H20*I20),IF($F20>=1,$J20+(D20*E20)+(F20*G20)+(H20*I20),IF($H20>=1,$J20+(D20*E20)+(F20*G20)+(H20*I20),"")))
B21: =VLOOKUP($C$11:$C$24,Personnel!$A$1:$B$1234,2,FALSE) -> 0 | E21: =VLOOKUP($B$11:$B$24,'Constr. Wage Rate Calculations'!$A$19:$Z$288,22,FALSE) -> 0 | G21: =VLOOKUP($B$11:$B$24,'Constr. Wage Rate Calculations'!$A$19:$Z$288,23,FALSE) -> 0 | I21: =VLOOKUP($B$11:$B$24,'Constr. Wage Rate Calculations'!$A$19:$Z$288,24,FALSE) -> 0 | J21: =VLOOKUP($B$11:$B$25,'Constr. Wage Rate Calculations'!$A$19:$Z$288,25,FALSE) -> 0 | K21: =IF($D21>=1,$J21+(D21*E21)+(F21*G21)+(H21*I21),IF($F21>=1,$J21+(D21*E21)+(F21*G21)+(H21*I21),IF($H21>=1,$J21+(D21*E21)+(F21*G21)+(H21*I21),"")))
B22: =VLOOKUP($C$11:$C$24,Personnel!$A$1:$B$1234,2,FALSE) -> 0 | E22: =VLOOKUP($B$11:$B$24,'Constr. Wage Rate Calculations'!$A$19:$Z$288,22,FALSE) -> 0 | G22: =VLOOKUP($B$11:$B$24,'Constr. Wage Rate Calculations'!$A$19:$Z$288,23,FALSE) -> 0 | I22: =VLOOKUP($B$11:$B$24,'Constr. Wage Rate Calculations'!$A$19:$Z$288,24,FALSE) -> 0 | J22: =VLOOKUP($B$11:$B$25,'Constr. Wage Rate Calculations'!$A$19:$Z$288,25,FALSE) -> 0 | K22: =IF($D22>=1,$J22+(D22*E22)+(F22*G22)+(H22*I22),IF($F22>=1,$J22+(D22*E22)+(F22*G22)+(H22*I22),IF($H22>=1,$J22+(D22*E22)+(F22*G22)+(H22*I22),"")))
B23: =VLOOKUP($C$11:$C$24,Personnel!$A$1:$B$1234,2,FALSE) -> 0 | E23: =VLOOKUP($B$11:$B$24,'Constr. Wage Rate Calculations'!$A$19:$Z$288,22,FALSE) -> 0 | G23: =VLOOKUP($B$11:$B$24,'Constr. Wage Rate Calculations'!$A$19:$Z$288,23,FALSE) -> 0 | I23: =VLOOKUP($B$11:$B$24,'Constr. Wage Rate Calculations'!$A$19:$Z$288,24,FALSE) -> 0 | J23: =VLOOKUP($B$11:$B$25,'Constr. Wage Rate Calculations'!$A$19:$Z$288,25,FALSE) -> 0 | K23: =IF($D23>=1,$J23+(D23*E23)+(F23*G23)+(H23*I23),IF($F23>=1,$J23+(D23*E23)+(F23*G23)+(H23*I23),IF($H23>=1,$J23+(D23*E23)+(F23*G23)+(H23*I23),"")))
B24: =VLOOKUP($C$11:$C$24,Personnel!$A$1:$B$1234,2,FALSE) -> 0 | E24: =VLOOKUP($B$11:$B$24,'Constr. Wage Rate Calculations'!$A$19:$Z$288,22,FALSE) -> 0 | G24: =VLOOKUP($B$11:$B$24,'Constr. Wage Rate Calculations'!$A$19:$Z$288,23,FALSE) -> 0 | I24: =VLOOKUP($B$11:$B$24,'Constr. Wage Rate Calculations'!$A$19:$Z$288,24,FALSE) -> 0 | J24: =VLOOKUP($B$11:$B$25,'Constr. Wage Rate Calculations'!$A$19:$Z$288,25,FALSE) -> 0 | K24: =IF($D24>=1,$J24+(D24*E24)+(F24*G24)+(H24*I24),IF($F24>=1,$J24+(D24*E24)+(F24*G24)+(H24*I24),IF($H24>=1,$J24+(D24*E24)+(F24*G24)+(H24*I24),""))) | M24: =SUM(M11:M23) -> 0
I25: TOTAL LABOUR | K25: =SUM(K11:K24) -> 0 | M25: =SUMIFS(D11:D24,D11:D24,"<3",D11:D24,"<5") -> 0 | N25: =SUMIFS(D11:D24,D11:D24,">3",D11:D24,">5") -> 0 | O25: =SUM(F11:F24,H11:H24,M25,N25)-M24 -> 0
A27: Equipment ID | B27: Equipment | H27: Days | I27: Hrs. | J27: Rate | K27: Total
B28: =VLOOKUP($C$28:$C$49,Equipment!$A$1:$B$2322,2,FALSE) -> 0 | J28: =VLOOKUP($B$28:$B$49,'Alberta Equip. Rates Year 3'!$B$13:$K$314,10,FALSE) -> 0 | K28: =(H28+I28)*J28 -> 0
B29: =VLOOKUP($C$28:$C$49,Equipment!$A$1:$B$2322,2,FALSE) -> 0 | J29: =VLOOKUP($B$28:$B$49,'Alberta Equip. Rates Year 3'!$B$13:$K$314,10,FALSE) -> 0 | K29: =(H29+I29)*J29 -> 0
B30: =VLOOKUP($C$28:$C$49,Equipment!$A$1:$B$2322,2,FALSE) -> 0 | J30: =VLOOKUP($B$28:$B$49,'Alberta Equip. Rates Year 3'!$B$13:$K$314,10,FALSE) -> 0 | K30: =(H30+I30)*J30 -> 0
B31: =VLOOKUP($C$28:$C$49,Equipment!$A$1:$B$2322,2,FALSE) -> 0 | J31: =VLOOKUP($B$28:$B$49,'Alberta Equip. Rates Year 3'!$B$13:$K$314,10,FALSE) -> 0 | K31: =(H31+I31)*J31 -> 0
B32: =VLOOKUP($C$28:$C$49,Equipment!$A$1:$B$2322,2,FALSE) -> 0 | J32: =VLOOKUP($B$28:$B$49,'Alberta Equip. Rates Year 3'!$B$13:$K$314,10,FALSE) -> 0 | K32: =(H32+I32)*J32 -> 0
B33: =VLOOKUP($C$28:$C$49,Equipment!$A$1:$B$2322,2,FALSE) -> 0 | J33: =VLOOKUP($B$28:$B$49,'Alberta Equip. Rates Year 3'!$B$13:$K$314,10,FALSE) -> 0 | K33: =(H33+I33)*J33 -> 0
B34: =VLOOKUP($C$28:$C$49,Equipment!$A$1:$B$2322,2,FALSE) -> 0 | J34: =VLOOKUP($B$28:$B$49,'Alberta Equip. Rates Year 3'!$B$13:$K$314,10,FALSE) -> 0 | K34: =(H34+I34)*J34 -> 0
B35: =VLOOKUP($C$28:$C$49,Equipment!$A$1:$B$2322,2,FALSE) -> 0 | J35: =VLOOKUP($B$28:$B$49,'Alberta Equip. Rates Year 3'!$B$13:$K$314,10,FALSE) -> 0 | K35: =(H35+I35)*J35 -> 0
B36: =VLOOKUP($C$28:$C$49,Equipment!$A$1:$B$2322,2,FALSE) -> 0 | J36: =VLOOKUP($B$28:$B$49,'Alberta Equip. Rates Year 3'!$B$13:$K$314,10,FALSE) -> 0 | K36: =(H36+I36)*J36 -> 0
B37: =VLOOKUP($C$28:$C$49,Equipment!$A$1:$B$2322,2,FALSE) -> 0 | J37: =VLOOKUP($B$28:$B$49,'Alberta Equip. Rates Year 3'!$B$13:$K$314,10,FALSE) -> 0 | K37: =(H37+I37)*J37 -> 0
B38: =VLOOKUP($C$28:$C$49,Equipment!$A$1:$B$2322,2,FALSE) -> 0 | J38: =VLOOKUP($B$28:$B$49,'Alberta Equip. Rates Year 3'!$B$13:$K$314,10,FALSE) -> 0 | K38: =(H38+I38)*J38 -> 0
B39: =VLOOKUP($C$28:$C$49,Equipment!$A$1:$B$2322,2,FALSE) -> 0 | J39: =VLOOKUP($B$28:$B$49,'Alberta Equip. Rates Year 3'!$B$13:$K$314,10,FALSE) -> 0 | K39: =(H39+I39)*J39 -> 0
... B49: =VLOOKUP($C$28:$C$49,Equipment!$A$1:$B$2322,2,FALSE) -> 0 | J49: =VLOOKUP($B$28:$B$49,'Alberta Equip. Rates Year 3'!$B$13:$K$314,10,FALSE) -> 0 | K49: =(H49+I49)*J49 -> 0
I50: TOTAL EQUIPMENT | K50: =SUM(K28:K49) -> 0
A52: Scope of Work: | I52: LABOUR | K52: =K25 -> 0
I53: EQUIPMENT | K53: =K50 -> 0
I54: SMALL TOOLS | K54: =(O25)*14.15 -> 0
I55: MATERIALS
I56: TRUCKING
...

Sheet Field Log (48)
J1: Date:
G6: Field Log ID: | J6: Status:
A7: Address: | G7: Account #: | J7: Account:
G8: Foreman:
A10: Employee ID | B10: Labor Type | C10: Employee | D10: RT Hours | E10: RT Rate | F10: OT Hours | G10: OT Rate | H10: DT Hours | I10: DT Rate | J10: Sub. | K10: Total | M10: Additional Hours
B11: =VLOOKUP($C$11:$C$24,Personnel!$A$1:$B$1234,2,FALSE) -> 0 | E11: =VLOOKUP($B$11:$B$24,'Constr. Wage Rate Calculations'!$A$19:$Z$288,22,FALSE) -> 0 | G11: =VLOOKUP($B$11:$B$24,'Constr. Wage Rate Calculations'!$A$19:$Z$288,23,FALSE) -> 0 | I11: =VLOOKUP($B$11:$B$24,'Constr. Wage Rate Calculations'!$A$19:$Z$288,24,FALSE) -> 0 | J11: =VLOOKUP($B$11:$B$25,'Constr. Wage Rate Calculations'!$A$19:$Z$288,25,FALSE) -> 0 | K11: =IF($D11>=1,$J11+(D11*E11)+(F11*G11)+(H11*I11),IF($F11>=1,$J11+(D11*E11)+(F11*G11)+(H11*I11),IF($H11>=1,$J11+(D11*E11)+(F11*G11)+(H11*I11),"")))
B12: =VLOOKUP($C$11:$C$24,Personnel!$A$1:$B$1234,2,FALSE) -> 0 | E12: =VLOOKUP($B$11:$B$24,'Constr. Wage Rate Calculations'!$A$19:$Z$288,22,FALSE) -> 0 | G12: =VLOOKUP($B$11:$B$24,'Constr. Wage Rate Calculations'!$A$19:$Z$288,23,FALSE) -> 0 | I12: =VLOOKUP($B$11:$B$24,'Constr. Wage Rate Calculations'!$A$19:$Z$288,24,FALSE) -> 0 | J12: =VLOOKUP($B$11:$B$25,'Constr. Wage Rate Calculations'!$A$19:$Z$288,25,FALSE) -> 0 | K12: =IF($D12>=1,$J12+(D12*E12)+(F12*G12)+(H12*I12),IF($F12>=1,$J12+(D12*E12)+(F12*G12)+(H12*I12),IF($H12>=1,$J12+(D12*E12)+(F12*G12)+(H12*I12),"")))
B13: =VLOOKUP($C$11:$C$24,Personnel!$A$1:$B$1234,2,FALSE) -> 0 | E13: =VLOOKUP($B$11:$B$24,'Constr. Wage Rate Calculations'!$A$19:$Z$288,22,FALSE) -> 0 | G13: =VLOOKUP($B$11:$B$24,'Constr. Wage Rate Calculations'!$A$19:$Z$288,23,FALSE) -> 0 | I13: =VLOOKUP($B$11:$B$24,'Constr. Wage Rate Calculations'!$A$19:$Z$288,24,FALSE) -> 0 | J13: =VLOOKUP($B$11:$B$25,'Constr. Wage Rate Calculations'!$A$19:$Z$288,25,FALSE) -> 0 | K13: =IF($D13>=1,$J13+(D13*E13)+(F13*G13)+(H13*I13),IF($F13>=1,$J13+(D13*E13)+(F13*G13)+(H13*I13),IF($H13>=1,$J13+(D13*E13)+(F13*G13)+(H13*I13),"")))
B14: =VLOOKUP($C$11:$C$24,Personnel!$A$1:$B$1234,2,FALSE) -> 0 | E14: =VLOOKUP($B$11:$B$24,'Constr. Wage Rate Calculations'!$A$19:$Z$288,22,FALSE) -> 0 | G14: =VLOOKUP($B$11:$B$24,'Constr. Wage Rate Calculations'!$A$19:$Z$288,23,FALSE) -> 0 | I14: =VLOOKUP($B$11:$B$24,'Constr. Wage Rate Calculations'!$A$19:$Z$288,24,FALSE) -> 0 | J14: =VLOOKUP($B$11:$B$25,'Constr. Wage Rate Calculations'!$A$19:$Z$288,25,FALSE) -> 0 | K14: =IF($D14>=1,$J14+(D14*E14)+(F14*G14)+(H14*I14),IF($F14>=1,$J14+(D14*E14)+(F14*G14)+(H14*I14),IF($H14>=1,$J14+(D14*E14)+(F14*G14)+(H14*I14),"")))
B15: =VLOOKUP($C$11:$C$24,Personnel!$A$1:$B$1234,2,FALSE) -> 0 | E15: =VLOOKUP($B$11:$B$24,'Constr. Wage Rate Calculations'!$A$19:$Z$288,22,FALSE) -> 0 | G15: =VLOOKUP($B$11:$B$24,'Constr. Wage Rate Calculations'!$A$19:$Z$288,23,FALSE) -> 0 | I15: =VLOOKUP($B$11:$B$24,'Constr. Wage Rate Calculations'!$A$19:$Z$288,24,FALSE) -> 0 | J15: =VLOOKUP($B$11:$B$25,'Constr. Wage Rate Calculations'!$A$19:$Z$288,25,FALSE) -> 0 | K15: =IF($D15>=1,$J15+(D15*E15)+(F15*G15)+(H15*I15),IF($F15>=1,$J15+(D15*E15)+(F15*G15)+(H15*I15),IF($H15>=1,$J15+(D15*E15)+(F15*G15)+(H15*I15),"")))
B16: =VLOOKUP($C$11:$C$24,Personnel!$A$1:$B$1234,2,FALSE) -> 0 | E16: =VLOOKUP($B$11:$B$24,'Constr. Wage Rate Calculations'!$A$19:$Z$288,22,FALSE) -> 0 | G16: =VLOOKUP($B$11:$B$24,'Constr. Wage Rate Calculations'!$A$19:$Z$288,23,FALSE) -> 0 | I16: =VLOOKUP($B$11:$B$24,'Constr. Wage Rate Calculations'!$A$19:$Z$288,24,FALSE) -> 0 | J16: =VLOOKUP($B$11:$B$25,'Constr. Wage Rate Calculations'!$A$19:$Z$288,25,FALSE) -> 0 | K16: =IF($D16>=1,$J16+(D16*E16)+(F16*G16)+(H16*I16),IF($F16>=1,$J16+(D16*E16)+(F16*G16)+(H16*I16),IF($H16>=1,$J16+(D16*E16)+(F16*G16)+(H16*I16),"")))
B17: =VLOOKUP($C$11:$C$24,Personnel!$A$1:$B$1234,2,FALSE) -> 0 | E17: =VLOOKUP($B$11:$B$24,'Constr. Wage Rate Calculations'!$A$19:$Z$288,22,FALSE) -> 0 | G17: =VLOOKUP($B$11:$B$24,'Constr. Wage Rate Calculations'!$A$19:$Z$288,23,FALSE) -> 0 | I17: =VLOOKUP($B$11:$B$24,'Constr. Wage Rate Calculations'!$A$19:$Z$288,24,FALSE) -> 0 | J17: =VLOOKUP($B$11:$B$25,'Constr. Wage Rate Calculations'!$A$19:$Z$288,25,FALSE) -> 0 | K17: =IF($D17>=1,$J17+(D17*E17)+(F17*G17)+(H17*I17),IF($F17>=1,$J17+(D17*E17)+(F17*G17)+(H17*I17),IF($H17>=1,$J17+(D17*E17)+(F17*G17)+(H17*I17),"")))
B18: =VLOOKUP($C$11:$C$24,Personnel!$A$1:$B$1234,2,FALSE) -> 0 | E18: =VLOOKUP($B$11:$B$24,'Constr. Wage Rate Calculations'!$A$19:$Z$288,22,FALSE) -> 0 | G18: =VLOOKUP($B$11:$B$24,'Constr. Wage Rate Calculations'!$A$19:$Z$288,23,FALSE) -> 0 | I18: =VLOOKUP($B$11:$B$24,'Constr. Wage Rate Calculations'!$A$19:$Z$288,24,FALSE) -> 0 | J18: 0 | K18: =IF($D18>=1,$J18+(D18*E18)+(F18*G18)+(H18*I18),IF($F18>=1,$J18+(D18*E18)+(F18*G18)+(H18*I18),IF($H18>=1,$J18+(D18*E18)+(F18*G18)+(H18*I18),"")))
B19: =VLOOKUP($C$11:$C$24,Personnel!$A$1:$B$1234,2,FALSE) -> 0 | E19: =VLOOKUP($B$11:$B$24,'Constr. Wage Rate Calculations'!$A$19:$Z$288,22,FALSE) -> 0 | G19: =VLOOKUP($B$11:$B$24,'Constr. Wage Rate Calculations'!$A$19:$Z$288,23,FALSE) -> 0 | I19: =VLOOKUP($B$11:$B$24,'Constr. Wage Rate Calculations'!$A$19:$Z$288,24,FALSE) -> 0 | J19: =VLOOKUP($B$11:$B$25,'Constr. Wage Rate Calculations'!$A$19:$Z$288,25,FALSE) -> 0 | K19: =IF($D19>=1,$J19+(D19*E19)+(F19*G19)+(H19*I19),IF($F19>=1,$J19+(D19*E19)+(F19*G19)+(H19*I19),IF($H19>=1,$J19+(D19*E19)+(F19*G19)+(H19*I19),"")))
B20: =VLOOKUP($C$11:$C$24,Personnel!$A$1:$B$1234,2,FALSE) -> 0 | E20: =VLOOKUP($B$11:$B$24,'Constr. Wage Rate Calculations'!$A$19:$Z$288,22,FALSE) -> 0 | G20: =VLOOKUP($B$11:$B$24,'Constr. Wage Rate Calculations'!$A$19:$Z$288,23,FALSE) -> 0 | I20: =VLOOKUP($B$11:$B$24,'Constr. Wage Rate Calculations'!$A$19:$Z$288,24,FALSE) -> 0 | J20: =VLOOKUP($B$11:$B$25,'Constr. Wage Rate Calculations'!$A$19:$Z$288,25,FALSE) -> 0 | K20: =IF($D20>=1,$J20+(D20*E20)+(F20*G20)+(H20*I20),IF($F20>=1,$J20+(D20*E20)+(F20*G20)+(H20*I20),IF($H20>=1,$J20+(D20*E20)+(F20*G20)+(H20*I20),"")))
B21: =VLOOKUP($C$11:$C$24,Personnel!$A$1:$B$1234,2,FALSE) -> 0 | E21: =VLOOKUP($B$11:$B$24,'Constr. Wage Rate Calculations'!$A$19:$Z$288,22,FALSE) -> 0 | G21: =VLOOKUP($B$11:$B$24,'Constr. Wage Rate Calculations'!$A$19:$Z$288,23,FALSE) -> 0 | I21: =VLOOKUP($B$11:$B$24,'Constr. Wage Rate Calculations'!$A$19:$Z$288,24,FALSE) -> 0 | J21: =VLOOKUP($B$11:$B$25,'Constr. Wage Rate Calculations'!$A$19:$Z$288,25,FALSE) -> 0 | K21: =IF($D21>=1,$J21+(D21*E21)+(F21*G21)+(H21*I21),IF($F21>=1,$J21+(D21*E21)+(F21*G21)+(H21*I21),IF($H21>=1,$J21+(D21*E21)+(F21*G21)+(H21*I21),"")))
B22: =VLOOKUP($C$11:$C$24,Personnel!$A$1:$B$1234,2,FALSE) -> 0 | E22: =VLOOKUP($B$11:$B$24,'Constr. Wage Rate Calculations'!$A$19:$Z$288,22,FALSE) -> 0 | G22: =VLOOKUP($B$11:$B$24,'Constr. Wage Rate Calculations'!$A$19:$Z$288,23,FALSE) -> 0 | I22: =VLOOKUP($B$11:$B$24,'Constr. Wage Rate Calculations'!$A$19:$Z$288,24,FALSE) -> 0 | J22: =VLOOKUP($B$11:$B$25,'Constr. Wage Rate Calculations'!$A$19:$Z$288,25,FALSE) -> 0 | K22: =IF($D22>=1,$J22+(D22*E22)+(F22*G22)+(H22*I22),IF($F22>=1,$J22+(D22*E22)+(F22*G22)+(H22*I22),IF($H22>=1,$J22+(D22*E22)+(F22*G22)+(H22*I22),"")))
B23: =VLOOKUP($C$11:$C$24,Personnel!$A$1:$B$1234,2,FALSE) -> 0 | E23: =VLOOKUP($B$11:$B$24,'Constr. Wage Rate Calculations'!$A$19:$Z$288,22,FALSE) -> 0 | G23: =VLOOKUP($B$11:$B$24,'Constr. Wage Rate Calculations'!$A$19:$Z$288,23,FALSE) -> 0 | I23: =VLOOKUP($B$11:$B$24,'Constr. Wage Rate Calculations'!$A$19:$Z$288,24,FALSE) -> 0 | J23: =VLOOKUP($B$11:$B$25,'Constr. Wage Rate Calculations'!$A$19:$Z$288,25,FALSE) -> 0 | K23: =IF($D23>=1,$J23+(D23*E23)+(F23*G23)+(H23*I23),IF($F23>=1,$J23+(D23*E23)+(F23*G23)+(H23*I23),IF($H23>=1,$J23+(D23*E23)+(F23*G23)+(H23*I23),"")))
B24: =VLOOKUP($C$11:$C$24,Personnel!$A$1:$B$1234,2,FALSE) -> 0 | E24: =VLOOKUP($B$11:$B$24,'Constr. Wage Rate Calculations'!$A$19:$Z$288,22,FALSE) -> 0 | G24: =VLOOKUP($B$11:$B$24,'Constr. Wage Rate Calculations'!$A$19:$Z$288,23,FALSE) -> 0 | I24: =VLOOKUP($B$11:$B$24,'Constr. Wage Rate Calculations'!$A$19:$Z$288,24,FALSE) -> 0 | J24: =VLOOKUP($B$11:$B$25,'Constr. Wage Rate Calculations'!$A$19:$Z$288,25,FALSE) -> 0 | K24: =IF($D24>=1,$J24+(D24*E24)+(F24*G24)+(H24*I24),IF($F24>=1,$J24+(D24*E24)+(F24*G24)+(H24*I24),IF($H24>=1,$J24+(D24*E24)+(F24*G24)+(H24*I24),""))) | M24: =SUM(M11:M23) -> 0
I25: TOTAL LABOUR | K25: =SUM(K11:K24) -> 0 | M25: =SUMIFS(D11:D24,D11:D24,"<3",D11:D24,"<5") -> 0 | N25: =SUMIFS(D11:D24,D11:D24,">3",D11:D24,">5") -> 0 | O25: =SUM(F11:F24,H11:H24,M25,N25)-M24 -> 0
A27: Equipment ID | B27: Equipment | H27: Days | I27: Hrs. | J27: Rate | K27: Total
B28: =VLOOKUP($C$28:$C$49,Equipment!$A$1:$B$2322,2,FALSE) -> 0 | J28: =VLOOKUP($B$28:$B$49,'Alberta Equip. Rates Year 3'!$B$13:$K$314,10,FALSE) -> 0 | K28: =(H28+I28)*J28 -> 0
B29: =VLOOKUP($C$28:$C$49,Equipment!$A$1:$B$2322,2,FALSE) -> 0 | J29: =VLOOKUP($B$28:$B$49,'Alberta Equip. Rates Year 3'!$B$13:$K$314,10,FALSE) -> 0 | K29: =(H29+I29)*J29 -> 0
B30: =VLOOKUP($C$28:$C$49,Equipment!$A$1:$B$2322,2,FALSE) -> 0 | J30: =VLOOKUP($B$28:$B$49,'Alberta Equip. Rates Year 3'!$B$13:$K$314,10,FALSE) -> 0 | K30: =(H30+I30)*J30 -> 0
B31: =VLOOKUP($C$28:$C$49,Equipment!$A$1:$B$2322,2,FALSE) -> 0 | J31: =VLOOKUP($B$28:$B$49,'Alberta Equip. Rates Year 3'!$B$13:$K$314,10,FALSE) -> 0 | K31: =(H31+I31)*J31 -> 0
B32: =VLOOKUP($C$28:$C$49,Equipment!$A$1:$B$2322,2,FALSE) -> 0 | J32: =VLOOKUP($B$28:$B$49,'Alberta Equip. Rates Year 3'!$B$13:$K$314,10,FALSE) -> 0 | K32: =(H32+I32)*J32 -> 0
B33: =VLOOKUP($C$28:$C$49,Equipment!$A$1:$B$2322,2,FALSE) -> 0 | J33: =VLOOKUP($B$28:$B$49,'Alberta Equip. Rates Year 3'!$B$13:$K$314,10,FALSE) -> 0 | K33: =(H33+I33)*J33 -> 0
B34: =VLOOKUP($C$28:$C$49,Equipment!$A$1:$B$2322,2,FALSE) -> 0 | J34: =VLOOKUP($B$28:$B$49,'Alberta Equip. Rates Year 3'!$B$13:$K$314,10,FALSE) -> 0 | K34: =(H34+I34)*J34 -> 0
B35: =VLOOKUP($C$28:$C$49,Equipment!$A$1:$B$2322,2,FALSE) -> 0 | J35: =VLOOKUP($B$28:$B$49,'Alberta Equip. Rates Year 3'!$B$13:$K$314,10,FALSE) -> 0 | K35: =(H35+I35)*J35 -> 0
B36: =VLOOKUP($C$28:$C$49,Equipment!$A$1:$B$2322,2,FALSE) -> 0 | J36: =VLOOKUP($B$28:$B$49,'Alberta Equip. Rates Year 3'!$B$13:$K$314,10,FALSE) -> 0 | K36: =(H36+I36)*J36 -> 0
B37: =VLOOKUP($C$28:$C$49,Equipment!$A$1:$B$2322,2,FALSE) -> 0 | J37: =VLOOKUP($B$28:$B$49,'Alberta Equip. Rates Year 3'!$B$13:$K$314,10,FALSE) -> 0 | K37: =(H37+I37)*J37 -> 0
B38: =VLOOKUP($C$28:$C$49,Equipment!$A$1:$B$2322,2,FALSE) -> 0 | J38: =VLOOKUP($B$28:$B$49,'Alberta Equip. Rates Year 3'!$B$13:$K$314,10,FALSE) -> 0 | K38: =(H38+I38)*J38 -> 0
B39: =VLOOKUP($C$28:$C$49,Equipment!$A$1:$B$2322,2,FALSE) -> 0 | J39: =VLOOKUP($B$28:$B$49,'Alberta Equip. Rates Year 3'!$B$13:$K$314,10,FALSE) -> 0 | K39: =(H39+I39)*J39 -> 0
... B49: =VLOOKUP($C$28:$C$49,Equipment!$A$1:$B$2322,2,FALSE) -> 0 | J49: =VLOOKUP($B$28:$B$49,'Alberta Equip. Rates Year 3'!$B$13:$K$314,10,FALSE) -> 0 | K49: =(H49+I49)*J49 -> 0
I50: TOTAL EQUIPMENT | K50: =SUM(K28:K49) -> 0
A52: Scope of Work: | I52: LABOUR | K52: =K25 -> 0
I53: EQUIPMENT | K53: =K50 -> 0
I54: SMALL TOOLS | K54: =(O25)*14.15 -> 0
I55: MATERIALS
I56: TRUCKING
...

Sheet Field Log (47)
J1: Date:
G6: Field Log ID: | J6: Status:
A7: Address: | G7: Account #: | J7: Account:
G8: Foreman:
A10: Employee ID | B10: Labor Type | C10: Employee | D10: RT Hours | E10: RT Rate | F10: OT Hours | G10: OT Rate | H10: DT Hours | I10: DT Rate | J10: Sub. | K10: Total | M10: Additional Hours
B11: =VLOOKUP($C$11:$C$24,Personnel!$A$1:$B$1234,2,FALSE) -> 0 | E11: =VLOOKUP($B$11:$B$24,'Constr. Wage Rate Calculations'!$A$19:$Z$288,22,FALSE) -> 0 | G11: =VLOOKUP($B$11:$B$24,'Constr. Wage Rate Calculations'!$A$19:$Z$288,23,FALSE) -> 0 | I11: =VLOOKUP($B$11:$B$24,'Constr. Wage Rate Calculations'!$A$19:$Z$288,24,FALSE) -> 0 | J11: =VLOOKUP($B$11:$B$25,'Constr. Wage Rate Calculations'!$A$19:$Z$288,25,FALSE) -> 0 | K11: =IF($D11>=1,$J11+(D11*E11)+(F11*G11)+(H11*I11),IF($F11>=1,$J11+(D11*E11)+(F11*G11)+(H11*I11),IF($H11>=1,$J11+(D11*E11)+(F11*G11)+(H11*I11),"")))
B12: =VLOOKUP($C$11:$C$24,Personnel!$A$1:$B$1234,2,FALSE) -> 0 | E12: =VLOOKUP($B$11:$B$24,'Constr. Wage Rate Calculations'!$A$19:$Z$288,22,FALSE) -> 0 | G12: =VLOOKUP($B$11:$B$24,'Constr. Wage Rate Calculations'!$A$19:$Z$288,23,FALSE) -> 0 | I12: =VLOOKUP($B$11:$B$24,'Constr. Wage Rate Calculations'!$A$19:$Z$288,24,FALSE) -> 0 | J12: =VLOOKUP($B$11:$B$25,'Constr. Wage Rate Calculations'!$A$19:$Z$288,25,FALSE) -> 0 | K12: =IF($D12>=1,$J12+(D12*E12)+(F12*G12)+(H12*I12),IF($F12>=1,$J12+(D12*E12)+(F12*G12)+(H12*I12),IF($H12>=1,$J12+(D12*E12)+(F12*G12)+(H12*I12),"")))
B13: =VLOOKUP($C$11:$C$24,Personnel!$A$1:$B$1234,2,FALSE) -> 0 | E13: =VLOOKUP($B$11:$B$24,'Constr. Wage Rate Calculations'!$A$19:$Z$288,22,FALSE) -> 0 | G13: =VLOOKUP($B$11:$B$24,'Constr. Wage Rate Calculations'!$A$19:$Z$288,23,FALSE) -> 0 | I13: =VLOOKUP($B$11:$B$24,'Constr. Wage Rate Calculations'!$A$19:$Z$288,24,FALSE) -> 0 | J13: =VLOOKUP($B$11:$B$25,'Constr. Wage Rate Calculations'!$A$19:$Z$288,25,FALSE) -> 0 | K13: =IF($D13>=1,$J13+(D13*E13)+(F13*G13)+(H13*I13),IF($F13>=1,$J13+(D13*E13)+(F13*G13)+(H13*I13),IF($H13>=1,$J13+(D13*E13)+(F13*G13)+(H13*I13),"")))
B14: =VLOOKUP($C$11:$C$24,Personnel!$A$1:$B$1234,2,FALSE) -> 0 | E14: =VLOOKUP($B$11:$B$24,'Constr. Wage Rate Calculations'!$A$19:$Z$288,22,FALSE) -> 0 | G14: =VLOOKUP($B$11:$B$24,'Constr. Wage Rate Calculations'!$A$19:$Z$288,23,FALSE) -> 0 | I14: =VLOOKUP($B$11:$B$24,'Constr. Wage Rate Calculations'!$A$19:$Z$288,24,FALSE) -> 0 | J14: =VLOOKUP($B$11:$B$25,'Constr. Wage Rate Calculations'!$A$19:$Z$288,25,FALSE) -> 0 | K14: =IF($D14>=1,$J14+(D14*E14)+(F14*G14)+(H14*I14),IF($F14>=1,$J14+(D14*E14)+(F14*G14)+(H14*I14),IF($H14>=1,$J14+(D14*E14)+(F14*G14)+(H14*I14),"")))
B15: =VLOOKUP($C$11:$C$24,Personnel!$A$1:$B$1234,2,FALSE) -> 0 | E15: =VLOOKUP($B$11:$B$24,'Constr. Wage Rate Calculations'!$A$19:$Z$288,22,FALSE) -> 0 | G15: =VLOOKUP($B$11:$B$24,'Constr. Wage Rate Calculations'!$A$19:$Z$288,23,FALSE) -> 0 | I15: =VLOOKUP($B$11:$B$24,'Constr. Wage Rate Calculations'!$A$19:$Z$288,24,FALSE) -> 0 | J15: =VLOOKUP($B$11:$B$25,'Constr. Wage Rate Calculations'!$A$19:$Z$288,25,FALSE) -> 0 | K15: =IF($D15>=1,$J15+(D15*E15)+(F15*G15)+(H15*I15),IF($F15>=1,$J15+(D15*E15)+(F15*G15)+(H15*I15),IF($H15>=1,$J15+(D15*E15)+(F15*G15)+(H15*I15),"")))
B16: =VLOOKUP($C$11:$C$24,Personnel!$A$1:$B$1234,2,FALSE) -> 0 | E16: =VLOOKUP($B$11:$B$24,'Constr. Wage Rate Calculations'!$A$19:$Z$288,22,FALSE) -> 0 | G16: =VLOOKUP($B$11:$B$24,'Constr. Wage Rate Calculations'!$A$19:$Z$288,23,FALSE) -> 0 | I16: =VLOOKUP($B$11:$B$24,'Constr. Wage Rate Calculations'!$A$19:$Z$288,24,FALSE) -> 0 | J16: =VLOOKUP($B$11:$B$25,'Constr. Wage Rate Calculations'!$A$19:$Z$288,25,FALSE) -> 0 | K16: =IF($D16>=1,$J16+(D16*E16)+(F16*G16)+(H16*I16),IF($F16>=1,$J16+(D16*E16)+(F16*G16)+(H16*I16),IF($H16>=1,$J16+(D16*E16)+(F16*G16)+(H16*I16),"")))
B17: =VLOOKUP($C$11:$C$24,Personnel!$A$1:$B$1234,2,FALSE) -> 0 | E17: =VLOOKUP($B$11:$B$24,'Constr. Wage Rate Calculations'!$A$19:$Z$288,22,FALSE) -> 0 | G17: =VLOOKUP($B$11:$B$24,'Constr. Wage Rate Calculations'!$A$19:$Z$288,23,FALSE) -> 0 | I17: =VLOOKUP($B$11:$B$24,'Constr. Wage Rate Calculations'!$A$19:$Z$288,24,FALSE) -> 0 | J17: =VLOOKUP($B$11:$B$25,'Constr. Wage Rate Calculations'!$A$19:$Z$288,25,FALSE) -> 0 | K17: =IF($D17>=1,$J17+(D17*E17)+(F17*G17)+(H17*I17),IF($F17>=1,$J17+(D17*E17)+(F17*G17)+(H17*I17),IF($H17>=1,$J17+(D17*E17)+(F17*G17)+(H17*I17),"")))
B18: =VLOOKUP($C$11:$C$24,Personnel!$A$1:$B$1234,2,FALSE) -> 0 | E18: =VLOOKUP($B$11:$B$24,'Constr. Wage Rate Calculations'!$A$19:$Z$288,22,FALSE) -> 0 | G18: =VLOOKUP($B$11:$B$24,'Constr. Wage Rate Calculations'!$A$19:$Z$288,23,FALSE) -> 0 | I18: =VLOOKUP($B$11:$B$24,'Constr. Wage Rate Calculations'!$A$19:$Z$288,24,FALSE) -> 0 | J18: =VLOOKUP($B$11:$B$25,'Constr. Wage Rate Calculations'!$A$19:$Z$288,25,FALSE) -> 0 | K18: =IF($D18>=1,$J18+(D18*E18)+(F18*G18)+(H18*I18),IF($F18>=1,$J18+(D18*E18)+(F18*G18)+(H18*I18),IF($H18>=1,$J18+(D18*E18)+(F18*G18)+(H18*I18),"")))
B19: =VLOOKUP($C$11:$C$24,Personnel!$A$1:$B$1234,2,FALSE) -> 0 | E19: =VLOOKUP($B$11:$B$24,'Constr. Wage Rate Calculations'!$A$19:$Z$288,22,FALSE) -> 0 | G19: =VLOOKUP($B$11:$B$24,'Constr. Wage Rate Calculations'!$A$19:$Z$288,23,FALSE) -> 0 | I19: =VLOOKUP($B$11:$B$24,'Constr. Wage Rate Calculations'!$A$19:$Z$288,24,FALSE) -> 0 | J19: =VLOOKUP($B$11:$B$25,'Constr. Wage Rate Calculations'!$A$19:$Z$288,25,FALSE) -> 0 | K19: =IF($D19>=1,$J19+(D19*E19)+(F19*G19)+(H19*I19),IF($F19>=1,$J19+(D19*E19)+(F19*G19)+(H19*I19),IF($H19>=1,$J19+(D19*E19)+(F19*G19)+(H19*I19),"")))
B20: =VLOOKUP($C$11:$C$24,Personnel!$A$1:$B$1234,2,FALSE) -> 0 | E20: =VLOOKUP($B$11:$B$24,'Constr. Wage Rate Calculations'!$A$19:$Z$288,22,FALSE) -> 0 | G20: =VLOOKUP($B$11:$B$24,'Constr. Wage Rate Calculations'!$A$19:$Z$288,23,FALSE) -> 0 | I20: =VLOOKUP($B$11:$B$24,'Constr. Wage Rate Calculations'!$A$19:$Z$288,24,FALSE) -> 0 | J20: =VLOOKUP($B$11:$B$25,'Constr. Wage Rate Calculations'!$A$19:$Z$288,25,FALSE) -> 0 | K20: =IF($D20>=1,$J20+(D20*E20)+(F20*G20)+(H20*I20),IF($F20>=1,$J20+(D20*E20)+(F20*G20)+(H20*I20),IF($H20>=1,$J20+(D20*E20)+(F20*G20)+(H20*I20),"")))
B21: =VLOOKUP($C$11:$C$24,Personnel!$A$1:$B$1234,2,FALSE) -> 0 | E21: =VLOOKUP($B$11:$B$24,'Constr. Wage Rate Calculations'!$A$19:$Z$288,22,FALSE) -> 0 | G21: =VLOOKUP($B$11:$B$24,'Constr. Wage Rate Calculations'!$A$19:$Z$288,23,FALSE) -> 0 | I21: =VLOOKUP($B$11:$B$24,'Constr. Wage Rate Calculations'!$A$19:$Z$288,24,FALSE) -> 0 | J21: =VLOOKUP($B$11:$B$25,'Constr. Wage Rate Calculations'!$A$19:$Z$288,25,FALSE) -> 0 | K21: =IF($D21>=1,$J21+(D21*E21)+(F21*G21)+(H21*I21),IF($F21>=1,$J21+(D21*E21)+(F21*G21)+(H21*I21),IF($H21>=1,$J21+(D21*E21)+(F21*G21)+(H21*I21),"")))
B22: =VLOOKUP($C$11:$C$24,Personnel!$A$1:$B$1234,2,FALSE) -> 0 | E22: =VLOOKUP($B$11:$B$24,'Constr. Wage Rate Calculations'!$A$19:$Z$288,22,FALSE) -> 0 | G22: =VLOOKUP($B$11:$B$24,'Constr. Wage Rate Calculations'!$A$19:$Z$288,23,FALSE) -> 0 | I22: =VLOOKUP($B$11:$B$24,'Constr. Wage Rate Calculations'!$A$19:$Z$288,24,FALSE) -> 0 | J22: =VLOOKUP($B$11:$B$25,'Constr. Wage Rate Calculations'!$A$19:$Z$288,25,FALSE) -> 0 | K22: =IF($D22>=1,$J22+(D22*E22)+(F22*G22)+(H22*I22),IF($F22>=1,$J22+(D22*E22)+(F22*G22)+(H22*I22),IF($H22>=1,$J22+(D22*E22)+(F22*G22)+(H22*I22),"")))
B23: =VLOOKUP($C$11:$C$24,Personnel!$A$1:$B$1234,2,FALSE) -> 0 | E23: =VLOOKUP($B$11:$B$24,'Constr. Wage Rate Calculations'!$A$19:$Z$288,22,FALSE) -> 0 | G23: =VLOOKUP($B$11:$B$24,'Constr. Wage Rate Calculations'!$A$19:$Z$288,23,FALSE) -> 0 | I23: =VLOOKUP($B$11:$B$24,'Constr. Wage Rate Calculations'!$A$19:$Z$288,24,FALSE) -> 0 | J23: =VLOOKUP($B$11:$B$25,'Constr. Wage Rate Calculations'!$A$19:$Z$288,25,FALSE) -> 0 | K23: =IF($D23>=1,$J23+(D23*E23)+(F23*G23)+(H23*I23),IF($F23>=1,$J23+(D23*E23)+(F23*G23)+(H23*I23),IF($H23>=1,$J23+(D23*E23)+(F23*G23)+(H23*I23),"")))
B24: =VLOOKUP($C$11:$C$24,Personnel!$A$1:$B$1234,2,FALSE) -> 0 | E24: =VLOOKUP($B$11:$B$24,'Constr. Wage Rate Calculations'!$A$19:$Z$288,22,FALSE) -> 0 | G24: =VLOOKUP($B$11:$B$24,'Constr. Wage Rate Calculations'!$A$19:$Z$288,23,FALSE) -> 0 | I24: =VLOOKUP($B$11:$B$24,'Constr. Wage Rate Calculations'!$A$19:$Z$288,24,FALSE) -> 0 | J24: =VLOOKUP($B$11:$B$25,'Constr. Wage Rate Calculations'!$A$19:$Z$288,25,FALSE) -> 0 | K24: =IF($D24>=1,$J24+(D24*E24)+(F24*G24)+(H24*I24),IF($F24>=1,$J24+(D24*E24)+(F24*G24)+(H24*I24),IF($H24>=1,$J24+(D24*E24)+(F24*G24)+(H24*I24),""))) | M24: =SUM(M11:M23) -> 0
I25: TOTAL LABOUR | K25: =SUM(K11:K24) -> 0 | M25: =SUMIFS(D11:D24,D11:D24,"<3",D11:D24,"<5") -> 0 | N25: =SUMIFS(D11:D24,D11:D24,">3",D11:D24,">5") -> 0 | O25: =SUM(F11:F24,H11:H24,M25,N25)-M24 -> 0
A27: Equipment ID | B27: Equipment | H27: Days | I27: Hrs. | J27: Rate | K27: Total
B28: =VLOOKUP($C$28:$C$49,Equipment!$A$1:$B$2322,2,FALSE) -> 0 | J28: =VLOOKUP($B$28:$B$49,'Alberta Equip. Rates Year 3'!$B$13:$K$314,10,FALSE) -> 0 | K28: =(H28+I28)*J28 -> 0
B29: =VLOOKUP($C$28:$C$49,Equipment!$A$1:$B$2322,2,FALSE) -> 0 | J29: =VLOOKUP($B$28:$B$49,'Alberta Equip. Rates Year 3'!$B$13:$K$314,10,FALSE) -> 0 | K29: =(H29+I29)*J29 -> 0
B30: =VLOOKUP($C$28:$C$49,Equipment!$A$1:$B$2322,2,FALSE) -> 0 | J30: =VLOOKUP($B$28:$B$49,'Alberta Equip. Rates Year 3'!$B$13:$K$314,10,FALSE) -> 0 | K30: =(H30+I30)*J30 -> 0
B31: =VLOOKUP($C$28:$C$49,Equipment!$A$1:$B$2322,2,FALSE) -> 0 | J31: =VLOOKUP($B$28:$B$49,'Alberta Equip. Rates Year 3'!$B$13:$K$314,10,FALSE) -> 0 | K31: =(H31+I31)*J31 -> 0
B32: =VLOOKUP($C$28:$C$49,Equipment!$A$1:$B$2322,2,FALSE) -> 0 | J32: =VLOOKUP($B$28:$B$49,'Alberta Equip. Rates Year 3'!$B$13:$K$314,10,FALSE) -> 0 | K32: =(H32+I32)*J32 -> 0
B33: =VLOOKUP($C$28:$C$49,Equipment!$A$1:$B$2322,2,FALSE) -> 0 | J33: =VLOOKUP($B$28:$B$49,'Alberta Equip. Rates Year 3'!$B$13:$K$314,10,FALSE) -> 0 | K33: =(H33+I33)*J33 -> 0
B34: =VLOOKUP($C$28:$C$49,Equipment!$A$1:$B$2322,2,FALSE) -> 0 | J34: =VLOOKUP($B$28:$B$49,'Alberta Equip. Rates Year 3'!$B$13:$K$314,10,FALSE) -> 0 | K34: =(H34+I34)*J34 -> 0
B35: =VLOOKUP($C$28:$C$49,Equipment!$A$1:$B$2322,2,FALSE) -> 0 | J35: =VLOOKUP($B$28:$B$49,'Alberta Equip. Rates Year 3'!$B$13:$K$314,10,FALSE) -> 0 | K35: =(H35+I35)*J35 -> 0
B36: =VLOOKUP($C$28:$C$49,Equipment!$A$1:$B$2322,2,FALSE) -> 0 | J36: =VLOOKUP($B$28:$B$49,'Alberta Equip. Rates Year 3'!$B$13:$K$314,10,FALSE) -> 0 | K36: =(H36+I36)*J36 -> 0
B37: =VLOOKUP($C$28:$C$49,Equipment!$A$1:$B$2322,2,FALSE) -> 0 | J37: =VLOOKUP($B$28:$B$49,'Alberta Equip. Rates Year 3'!$B$13:$K$314,10,FALSE) -> 0 | K37: =(H37+I37)*J37 -> 0
B38: =VLOOKUP($C$28:$C$49,Equipment!$A$1:$B$2322,2,FALSE) -> 0 | J38: =VLOOKUP($B$28:$B$49,'Alberta Equip. Rates Year 3'!$B$13:$K$314,10,FALSE) -> 0 | K38: =(H38+I38)*J38 -> 0
B39: =VLOOKUP($C$28:$C$49,Equipment!$A$1:$B$2322,2,FALSE) -> 0 | J39: =VLOOKUP($B$28:$B$49,'Alberta Equip. Rates Year 3'!$B$13:$K$314,10,FALSE) -> 0 | K39: =(H39+I39)*J39 -> 0
... B49: =VLOOKUP($C$28:$C$49,Equipment!$A$1:$B$2322,2,FALSE) -> 0 | J49: =VLOOKUP($B$28:$B$49,'Alberta Equip. Rates Year 3'!$B$13:$K$314,10,FALSE) -> 0 | K49: =(H49+I49)*J49 -> 0
I50: TOTAL EQUIPMENT | K50: =SUM(K28:K49) -> 0
A52: Scope of Work: | I52: LABOUR | K52: =K25 -> 0
I53: EQUIPMENT | K53: =K50 -> 0
I54: SMALL TOOLS | K54: =(O25)*14.15 -> 0
I55: MATERIALS
I56: TRUCKING
...

Sheet Field Log (46)
J1: Date:
G6: Field Log ID: | J6: Status:
A7: Address: | G7: Account #: | J7: Account:
G8: Foreman:
A10: Employee ID | B10: Labor Type | C10: Employee | D10: RT Hours | E10: RT Rate | F10: OT Hours | G10: OT Rate | H10: DT Hours | I10: DT Rate | J10: Sub. | K10: Total | M10: Additional Hours
B11: =VLOOKUP($C$11:$C$24,Personnel!$A$1:$B$1234,2,FALSE) -> 0 | E11: =VLOOKUP($B$11:$B$24,'Constr. Wage Rate Calculations'!$A$19:$Z$288,22,FALSE) -> 0 | G11: =VLOOKUP($B$11:$B$24,'Constr. Wage Rate Calculations'!$A$19:$Z$288,23,FALSE) -> 0 | I11: =VLOOKUP($B$11:$B$24,'Constr. Wage Rate Calculations'!$A$19:$Z$288,24,FALSE) -> 0 | J11: =VLOOKUP($B$11:$B$25,'Constr. Wage Rate Calculations'!$A$19:$Z$288,25,FALSE) -> 0 | K11: =IF($D11>=1,$J11+(D11*E11)+(F11*G11)+(H11*I11),IF($F11>=1,$J11+(D11*E11)+(F11*G11)+(H11*I11),IF($H11>=1,$J11+(D11*E11)+(F11*G11)+(H11*I11),"")))
B12: =VLOOKUP($C$11:$C$24,Personnel!$A$1:$B$1234,2,FALSE) -> 0 | E12: =VLOOKUP($B$11:$B$24,'Constr. Wage Rate Calculations'!$A$19:$Z$288,22,FALSE) -> 0 | G12: =VLOOKUP($B$11:$B$24,'Constr. Wage Rate Calculations'!$A$19:$Z$288,23,FALSE) -> 0 | I12: =VLOOKUP($B$11:$B$24,'Constr. Wage Rate Calculations'!$A$19:$Z$288,24,FALSE) -> 0 | J12: =VLOOKUP($B$11:$B$25,'Constr. Wage Rate Calculations'!$A$19:$Z$288,25,FALSE) -> 0 | K12: =IF($D12>=1,$J12+(D12*E12)+(F12*G12)+(H12*I12),IF($F12>=1,$J12+(D12*E12)+(F12*G12)+(H12*I12),IF($H12>=1,$J12+(D12*E12)+(F12*G12)+(H12*I12),"")))
B13: =VLOOKUP($C$11:$C$24,Personnel!$A$1:$B$1234,2,FALSE) -> 0 | E13: =VLOOKUP($B$11:$B$24,'Constr. Wage Rate Calculations'!$A$19:$Z$288,22,FALSE) -> 0 | G13: =VLOOKUP($B$11:$B$24,'Constr. Wage Rate Calculations'!$A$19:$Z$288,23,FALSE) -> 0 | I13: =VLOOKUP($B$11:$B$24,'Constr. Wage Rate Calculations'!$A$19:$Z$288,24,FALSE) -> 0 | J13: =VLOOKUP($B$11:$B$25,'Constr. Wage Rate Calculations'!$A$19:$Z$288,25,FALSE) -> 0 | K13: =IF($D13>=1,$J13+(D13*E13)+(F13*G13)+(H13*I13),IF($F13>=1,$J13+(D13*E13)+(F13*G13)+(H13*I13),IF($H13>=1,$J13+(D13*E13)+(F13*G13)+(H13*I13),"")))
B14: =VLOOKUP($C$11:$C$24,Personnel!$A$1:$B$1234,2,FALSE) -> 0 | E14: =VLOOKUP($B$11:$B$24,'Constr. Wage Rate Calculations'!$A$19:$Z$288,22,FALSE) -> 0 | G14: =VLOOKUP($B$11:$B$24,'Constr. Wage Rate Calculations'!$A$19:$Z$288,23,FALSE) -> 0 | I14: =VLOOKUP($B$11:$B$24,'Constr. Wage Rate Calculations'!$A$19:$Z$288,24,FALSE) -> 0 | J14: =VLOOKUP($B$11:$B$25,'Constr. Wage Rate Calculations'!$A$19:$Z$288,25,FALSE) -> 0 | K14: =IF($D14>=1,$J14+(D14*E14)+(F14*G14)+(H14*I14),IF($F14>=1,$J14+(D14*E14)+(F14*G14)+(H14*I14),IF($H14>=1,$J14+(D14*E14)+(F14*G14)+(H14*I14),"")))
B15: =VLOOKUP($C$11:$C$24,Personnel!$A$1:$B$1234,2,FALSE) -> 0 | E15: =VLOOKUP($B$11:$B$24,'Constr. Wage Rate Calculations'!$A$19:$Z$288,22,FALSE) -> 0 | G15: =VLOOKUP($B$11:$B$24,'Constr. Wage Rate Calculations'!$A$19:$Z$288,23,FALSE) -> 0 | I15: =VLOOKUP($B$11:$B$24,'Constr. Wage Rate Calculations'!$A$19:$Z$288,24,FALSE) -> 0 | J15: =VLOOKUP($B$11:$B$25,'Constr. Wage Rate Calculations'!$A$19:$Z$288,25,FALSE) -> 0 | K15: =IF($D15>=1,$J15+(D15*E15)+(F15*G15)+(H15*I15),IF($F15>=1,$J15+(D15*E15)+(F15*G15)+(H15*I15),IF($H15>=1,$J15+(D15*E15)+(F15*G15)+(H15*I15),"")))
B16: =VLOOKUP($C$11:$C$24,Personnel!$A$1:$B$1234,2,FALSE) -> 0 | E16: =VLOOKUP($B$11:$B$24,'Constr. Wage Rate Calculations'!$A$19:$Z$288,22,FALSE) -> 0 | G16: =VLOOKUP($B$11:$B$24,'Constr. Wage Rate Calculations'!$A$19:$Z$288,23,FALSE) -> 0 | I16: =VLOOKUP($B$11:$B$24,'Constr. Wage Rate Calculations'!$A$19:$Z$288,24,FALSE) -> 0 | J16: =VLOOKUP($B$11:$B$25,'Constr. Wage Rate Calculations'!$A$19:$Z$288,25,FALSE) -> 0 | K16: =IF($D16>=1,$J16+(D16*E16)+(F16*G16)+(H16*I16),IF($F16>=1,$J16+(D16*E16)+(F16*G16)+(H16*I16),IF($H16>=1,$J16+(D16*E16)+(F16*G16)+(H16*I16),"")))
B17: =VLOOKUP($C$11:$C$24,Personnel!$A$1:$B$1234,2,FALSE) -> 0 | E17: =VLOOKUP($B$11:$B$24,'Constr. Wage Rate Calculations'!$A$19:$Z$288,22,FALSE) -> 0 | G17: =VLOOKUP($B$11:$B$24,'Constr. Wage Rate Calculations'!$A$19:$Z$288,23,FALSE) -> 0 | I17: =VLOOKUP($B$11:$B$24,'Constr. Wage Rate Calculations'!$A$19:$Z$288,24,FALSE) -> 0 | J17: =VLOOKUP($B$11:$B$25,'Constr. Wage Rate Calculations'!$A$19:$Z$288,25,FALSE) -> 0 | K17: =IF($D17>=1,$J17+(D17*E17)+(F17*G17)+(H17*I17),IF($F17>=1,$J17+(D17*E17)+(F17*G17)+(H17*I17),IF($H17>=1,$J17+(D17*E17)+(F17*G17)+(H17*I17),"")))
B18: =VLOOKUP($C$11:$C$24,Personnel!$A$1:$B$1234,2,FALSE) -> 0 | E18: =VLOOKUP($B$11:$B$24,'Constr. Wage Rate Calculations'!$A$19:$Z$288,22,FALSE) -> 0 | G18: =VLOOKUP($B$11:$B$24,'Constr. Wage Rate Calculations'!$A$19:$Z$288,23,FALSE) -> 0 | I18: =VLOOKUP($B$11:$B$24,'Constr. Wage Rate Calculations'!$A$19:$Z$288,24,FALSE) -> 0 | J18: =VLOOKUP($B$11:$B$25,'Constr. Wage Rate Calculations'!$A$19:$Z$288,25,FALSE) -> 0 | K18: =IF($D18>=1,$J18+(D18*E18)+(F18*G18)+(H18*I18),IF($F18>=1,$J18+(D18*E18)+(F18*G18)+(H18*I18),IF($H18>=1,$J18+(D18*E18)+(F18*G18)+(H18*I18),"")))
B19: =VLOOKUP($C$11:$C$24,Personnel!$A$1:$B$1234,2,FALSE) -> 0 | E19: =VLOOKUP($B$11:$B$24,'Constr. Wage Rate Calculations'!$A$19:$Z$288,22,FALSE) -> 0 | G19: =VLOOKUP($B$11:$B$24,'Constr. Wage Rate Calculations'!$A$19:$Z$288,23,FALSE) -> 0 | I19: =VLOOKUP($B$11:$B$24,'Constr. Wage Rate Calculations'!$A$19:$Z$288,24,FALSE) -> 0 | J19: =VLOOKUP($B$11:$B$25,'Constr. Wage Rate Calculations'!$A$19:$Z$288,25,FALSE) -> 0 | K19: =IF($D19>=1,$J19+(D19*E19)+(F19*G19)+(H19*I19),IF($F19>=1,$J19+(D19*E19)+(F19*G19)+(H19*I19),IF($H19>=1,$J19+(D19*E19)+(F19*G19)+(H19*I19),"")))
B20: =VLOOKUP($C$11:$C$24,Personnel!$A$1:$B$1234,2,FALSE) -> 0 | E20: =VLOOKUP($B$11:$B$24,'Constr. Wage Rate Calculations'!$A$19:$Z$288,22,FALSE) -> 0 | G20: =VLOOKUP($B$11:$B$24,'Constr. Wage Rate Calculations'!$A$19:$Z$288,23,FALSE) -> 0 | I20: =VLOOKUP($B$11:$B$24,'Constr. Wage Rate Calculations'!$A$19:$Z$288,24,FALSE) -> 0 | J20: =VLOOKUP($B$11:$B$25,'Constr. Wage Rate Calculations'!$A$19:$Z$288,25,FALSE) -> 0 | K20: =IF($D20>=1,$J20+(D20*E20)+(F20*G20)+(H20*I20),IF($F20>=1,$J20+(D20*E20)+(F20*G20)+(H20*I20),IF($H20>=1,$J20+(D20*E20)+(F20*G20)+(H20*I20),"")))
B21: =VLOOKUP($C$11:$C$24,Personnel!$A$1:$B$1234,2,FALSE) -> 0 | E21: =VLOOKUP($B$11:$B$24,'Constr. Wage Rate Calculations'!$A$19:$Z$288,22,FALSE) -> 0 | G21: =VLOOKUP($B$11:$B$24,'Constr. Wage Rate Calculations'!$A$19:$Z$288,23,FALSE) -> 0 | I21: =VLOOKUP($B$11:$B$24,'Constr. Wage Rate Calculations'!$A$19:$Z$288,24,FALSE) -> 0 | J21: =VLOOKUP($B$11:$B$25,'Constr. Wage Rate Calculations'!$A$19:$Z$288,25,FALSE) -> 0 | K21: =IF($D21>=1,$J21+(D21*E21)+(F21*G21)+(H21*I21),IF($F21>=1,$J21+(D21*E21)+(F21*G21)+(H21*I21),IF($H21>=1,$J21+(D21*E21)+(F21*G21)+(H21*I21),"")))
B22: =VLOOKUP($C$11:$C$24,Personnel!$A$1:$B$1234,2,FALSE) -> 0 | E22: =VLOOKUP($B$11:$B$24,'Constr. Wage Rate Calculations'!$A$19:$Z$288,22,FALSE) -> 0 | G22: =VLOOKUP($B$11:$B$24,'Constr. Wage Rate Calculations'!$A$19:$Z$288,23,FALSE) -> 0 | I22: =VLOOKUP($B$11:$B$24,'Constr. Wage Rate Calculations'!$A$19:$Z$288,24,FALSE) -> 0 | J22: =VLOOKUP($B$11:$B$25,'Constr. Wage Rate Calculations'!$A$19:$Z$288,25,FALSE) -> 0 | K22: =IF($D22>=1,$J22+(D22*E22)+(F22*G22)+(H22*I22),IF($F22>=1,$J22+(D22*E22)+(F22*G22)+(H22*I22),IF($H22>=1,$J22+(D22*E22)+(F22*G22)+(H22*I22),"")))
B23: =VLOOKUP($C$11:$C$24,Personnel!$A$1:$B$1234,2,FALSE) -> 0 | E23: =VLOOKUP($B$11:$B$24,'Constr. Wage Rate Calculations'!$A$19:$Z$288,22,FALSE) -> 0 | G23: =VLOOKUP($B$11:$B$24,'Constr. Wage Rate Calculations'!$A$19:$Z$288,23,FALSE) -> 0 | I23: =VLOOKUP($B$11:$B$24,'Constr. Wage Rate Calculations'!$A$19:$Z$288,24,FALSE) -> 0 | J23: =VLOOKUP($B$11:$B$25,'Constr. Wage Rate Calculations'!$A$19:$Z$288,25,FALSE) -> 0 | K23: =IF($D23>=1,$J23+(D23*E23)+(F23*G23)+(H23*I23),IF($F23>=1,$J23+(D23*E23)+(F23*G23)+(H23*I23),IF($H23>=1,$J23+(D23*E23)+(F23*G23)+(H23*I23),"")))
B24: =VLOOKUP($C$11:$C$24,Personnel!$A$1:$B$1234,2,FALSE) -> 0 | E24: =VLOOKUP($B$11:$B$24,'Constr. Wage Rate Calculations'!$A$19:$Z$288,22,FALSE) -> 0 | G24: =VLOOKUP($B$11:$B$24,'Constr. Wage Rate Calculations'!$A$19:$Z$288,23,FALSE) -> 0 | I24: =VLOOKUP($B$11:$B$24,'Constr. Wage Rate Calculations'!$A$19:$Z$288,24,FALSE) -> 0 | J24: =VLOOKUP($B$11:$B$25,'Constr. Wage Rate Calculations'!$A$19:$Z$288,25,FALSE) -> 0 | K24: =IF($D24>=1,$J24+(D24*E24)+(F24*G24)+(H24*I24),IF($F24>=1,$J24+(D24*E24)+(F24*G24)+(H24*I24),IF($H24>=1,$J24+(D24*E24)+(F24*G24)+(H24*I24),""))) | M24: =SUM(M11:M23) -> 0
I25: TOTAL LABOUR | K25: =SUM(K11:K24) -> 0 | M25: =SUMIFS(D11:D24,D11:D24,"<3",D11:D24,"<5") -> 0 | N25: =SUMIFS(D11:D24,D11:D24,">3",D11:D24,">5") -> 0 | O25: =SUM(F11:F24,H11:H24,M25,N25)-M24 -> 0
A27: Equipment ID | B27: Equipment | H27: Days | I27: Hrs. | J27: Rate | K27: Total
B28: =VLOOKUP($C$28:$C$49,Equipment!$A$1:$B$2322,2,FALSE) -> 0 | J28: =VLOOKUP($B$28:$B$49,'Alberta Equip. Rates Year 3'!$B$13:$K$314,10,FALSE) -> 0 | K28: =(H28+I28)*J28 -> 0
B29: =VLOOKUP($C$28:$C$49,Equipment!$A$1:$B$2322,2,FALSE) -> 0 | J29: =VLOOKUP($B$28:$B$49,'Alberta Equip. Rates Year 3'!$B$13:$K$314,10,FALSE) -> 0 | K29: =(H29+I29)*J29 -> 0
B30: =VLOOKUP($C$28:$C$49,Equipment!$A$1:$B$2322,2,FALSE) -> 0 | J30: =VLOOKUP($B$28:$B$49,'Alberta Equip. Rates Year 3'!$B$13:$K$314,10,FALSE) -> 0 | K30: =(H30+I30)*J30 -> 0
B31: =VLOOKUP($C$28:$C$49,Equipment!$A$1:$B$2322,2,FALSE) -> 0 | J31: =VLOOKUP($B$28:$B$49,'Alberta Equip. Rates Year 3'!$B$13:$K$314,10,FALSE) -> 0 | K31: =(H31+I31)*J31 -> 0
B32: =VLOOKUP($C$28:$C$49,Equipment!$A$1:$B$2322,2,FALSE) -> 0 | J32: =VLOOKUP($B$28:$B$49,'Alberta Equip. Rates Year 3'!$B$13:$K$314,10,FALSE) -> 0 | K32: =(H32+I32)*J32 -> 0
B33: =VLOOKUP($C$28:$C$49,Equipment!$A$1:$B$2322,2,FALSE) -> 0 | J33: =VLOOKUP($B$28:$B$49,'Alberta Equip. Rates Year 3'!$B$13:$K$314,10,FALSE) -> 0 | K33: =(H33+I33)*J33 -> 0
B34: =VLOOKUP($C$28:$C$49,Equipment!$A$1:$B$2322,2,FALSE) -> 0 | J34: =VLOOKUP($B$28:$B$49,'Alberta Equip. Rates Year 3'!$B$13:$K$314,10,FALSE) -> 0 | K34: =(H34+I34)*J34 -> 0
B35: =VLOOKUP($C$28:$C$49,Equipment!$A$1:$B$2322,2,FALSE) -> 0 | J35: =VLOOKUP($B$28:$B$49,'Alberta Equip. Rates Year 3'!$B$13:$K$314,10,FALSE) -> 0 | K35: =(H35+I35)*J35 -> 0
B36: =VLOOKUP($C$28:$C$49,Equipment!$A$1:$B$2322,2,FALSE) -> 0 | J36: =VLOOKUP($B$28:$B$49,'Alberta Equip. Rates Year 3'!$B$13:$K$314,10,FALSE) -> 0 | K36: =(H36+I36)*J36 -> 0
B37: =VLOOKUP($C$28:$C$49,Equipment!$A$1:$B$2322,2,FALSE) -> 0 | J37: =VLOOKUP($B$28:$B$49,'Alberta Equip. Rates Year 3'!$B$13:$K$314,10,FALSE) -> 0 | K37: =(H37+I37)*J37 -> 0
B38: =VLOOKUP($C$28:$C$49,Equipment!$A$1:$B$2322,2,FALSE) -> 0 | J38: =VLOOKUP($B$28:$B$49,'Alberta Equip. Rates Year 3'!$B$13:$K$314,10,FALSE) -> 0 | K38: =(H38+I38)*J38 -> 0
B39: =VLOOKUP($C$28:$C$49,Equipment!$A$1:$B$2322,2,FALSE) -> 0 | J39: =VLOOKUP($B$28:$B$49,'Alberta Equip. Rates Year 3'!$B$13:$K$314,10,FALSE) -> 0 | K39: =(H39+I39)*J39 -> 0
... B49: =VLOOKUP($C$28:$C$49,Equipment!$A$1:$B$2322,2,FALSE) -> 0 | J49: =VLOOKUP($B$28:$B$49,'Alberta Equip. Rates Year 3'!$B$13:$K$314,10,FALSE) -> 0 | K49: =(H49+I49)*J49 -> 0
I50: TOTAL EQUIPMENT | K50: =SUM(K28:K49) -> 0
A52: Scope of Work: | I52: LABOUR | K52: =K25 -> 0
I53: EQUIPMENT | K53: =K50 -> 0
I54: SMALL TOOLS | K54: =(O25)*14.15 -> 0
I55: MATERIALS
I56: TRUCKING
...

Sheet Field Log (45)
J1: Date:
G6: Field Log ID: | J6: Status:
A7: Address: | G7: Account #: | J7: Account:
G8: Foreman:
A10: Employee ID | B10: Labor Type | C10: Employee | D10: RT Hours | E10: RT Rate | F10: OT Hours | G10: OT Rate | H10: DT Hours | I10: DT Rate | J10: Sub. | K10: Total | M10: Additional Hours
B11: =VLOOKUP($C$11:$C$25,Personnel!$A$1:$B$1234,2,FALSE) -> 0 | E11: =VLOOKUP($B$11:$B$25,'Constr. Wage Rate Calculations'!$A$19:$Z$288,22,FALSE) -> 0 | G11: =VLOOKUP($B$11:$B$25,'Constr. Wage Rate Calculations'!$A$19:$Z$288,23,FALSE) -> 0 | I11: =VLOOKUP($B$11:$B$25,'Constr. Wage Rate Calculations'!$A$19:$Z$288,24,FALSE) -> 0 | J11: =VLOOKUP($B$11:$B$25,'Constr. Wage Rate Calculations'!$A$19:$Z$288,25,FALSE) -> 0 | K11: =IF($D11>=1,$J11+(D11*E11)+(F11*G11)+(H11*I11),IF($F11>=1,$J11+(D11*E11)+(F11*G11)+(H11*I11),IF($H11>=1,$J11+(D11*E11)+(F11*G11)+(H11*I11),"")))
B12: =VLOOKUP($C$11:$C$25,Personnel!$A$1:$B$1234,2,FALSE) -> 0 | E12: =VLOOKUP($B$11:$B$25,'Constr. Wage Rate Calculations'!$A$19:$Z$288,22,FALSE) -> 0 | G12: =VLOOKUP($B$11:$B$25,'Constr. Wage Rate Calculations'!$A$19:$Z$288,23,FALSE) -> 0 | I12: =VLOOKUP($B$11:$B$25,'Constr. Wage Rate Calculations'!$A$19:$Z$288,24,FALSE) -> 0 | J12: =VLOOKUP($B$11:$B$25,'Constr. Wage Rate Calculations'!$A$19:$Z$288,25,FALSE) -> 0 | K12: =IF($D12>=1,$J12+(D12*E12)+(F12*G12)+(H12*I12),IF($F12>=1,$J12+(D12*E12)+(F12*G12)+(H12*I12),IF($H12>=1,$J12+(D12*E12)+(F12*G12)+(H12*I12),"")))
B13: =VLOOKUP($C$11:$C$25,Personnel!$A$1:$B$1234,2,FALSE) -> 0 | E13: =VLOOKUP($B$11:$B$25,'Constr. Wage Rate Calculations'!$A$19:$Z$288,22,FALSE) -> 0 | G13: =VLOOKUP($B$11:$B$25,'Constr. Wage Rate Calculations'!$A$19:$Z$288,23,FALSE) -> 0 | I13: =VLOOKUP($B$11:$B$25,'Constr. Wage Rate Calculations'!$A$19:$Z$288,24,FALSE) -> 0 | J13: =VLOOKUP($B$11:$B$25,'Constr. Wage Rate Calculations'!$A$19:$Z$288,25,FALSE) -> 0 | K13: =IF($D13>=1,$J13+(D13*E13)+(F13*G13)+(H13*I13),IF($F13>=1,$J13+(D13*E13)+(F13*G13)+(H13*I13),IF($H13>=1,$J13+(D13*E13)+(F13*G13)+(H13*I13),"")))
B14: =VLOOKUP($C$11:$C$25,Personnel!$A$1:$B$1234,2,FALSE) -> 0 | E14: =VLOOKUP($B$11:$B$25,'Constr. Wage Rate Calculations'!$A$19:$Z$288,22,FALSE) -> 0 | G14: =VLOOKUP($B$11:$B$25,'Constr. Wage Rate Calculations'!$A$19:$Z$288,23,FALSE) -> 0 | I14: =VLOOKUP($B$11:$B$25,'Constr. Wage Rate Calculations'!$A$19:$Z$288,24,FALSE) -> 0 | J14: =VLOOKUP($B$11:$B$25,'Constr. Wage Rate Calculations'!$A$19:$Z$288,25,FALSE) -> 0 | K14: =IF($D14>=1,$J14+(D14*E14)+(F14*G14)+(H14*I14),IF($F14>=1,$J14+(D14*E14)+(F14*G14)+(H14*I14),IF($H14>=1,$J14+(D14*E14)+(F14*G14)+(H14*I14),"")))
B15: =VLOOKUP($C$11:$C$25,Personnel!$A$1:$B$1234,2,FALSE) -> 0 | E15: =VLOOKUP($B$11:$B$25,'Constr. Wage Rate Calculations'!$A$19:$Z$288,22,FALSE) -> 0 | G15: =VLOOKUP($B$11:$B$25,'Constr. Wage Rate Calculations'!$A$19:$Z$288,23,FALSE) -> 0 | I15: =VLOOKUP($B$11:$B$25,'Constr. Wage Rate Calculations'!$A$19:$Z$288,24,FALSE) -> 0 | J15: =VLOOKUP($B$11:$B$25,'Constr. Wage Rate Calculations'!$A$19:$Z$288,25,FALSE) -> 0 | K15: =IF($D15>=1,$J15+(D15*E15)+(F15*G15)+(H15*I15),IF($F15>=1,$J15+(D15*E15)+(F15*G15)+(H15*I15),IF($H15>=1,$J15+(D15*E15)+(F15*G15)+(H15*I15),"")))
B16: =VLOOKUP($C$11:$C$25,Personnel!$A$1:$B$1234,2,FALSE) -> 0 | E16: =VLOOKUP($B$11:$B$25,'Constr. Wage Rate Calculations'!$A$19:$Z$288,22,FALSE) -> 0 | G16: =VLOOKUP($B$11:$B$25,'Constr. Wage Rate Calculations'!$A$19:$Z$288,23,FALSE) -> 0 | I16: =VLOOKUP($B$11:$B$25,'Constr. Wage Rate Calculations'!$A$19:$Z$288,24,FALSE) -> 0 | J16: =VLOOKUP($B$11:$B$25,'Constr. Wage Rate Calculations'!$A$19:$Z$288,25,FALSE) -> 0 | K16: =IF($D16>=1,$J16+(D16*E16)+(F16*G16)+(H16*I16),IF($F16>=1,$J16+(D16*E16)+(F16*G16)+(H16*I16),IF($H16>=1,$J16+(D16*E16)+(F16*G16)+(H16*I16),"")))
B17: =VLOOKUP($C$11:$C$25,Personnel!$A$1:$B$1234,2,FALSE) -> 0 | E17: =VLOOKUP($B$11:$B$25,'Constr. Wage Rate Calculations'!$A$19:$Z$288,22,FALSE) -> 0 | G17: =VLOOKUP($B$11:$B$25,'Constr. Wage Rate Calculations'!$A$19:$Z$288,23,FALSE) -> 0 | I17: =VLOOKUP($B$11:$B$25,'Constr. Wage Rate Calculations'!$A$19:$Z$288,24,FALSE) -> 0 | J17: =VLOOKUP($B$11:$B$25,'Constr. Wage Rate Calculations'!$A$19:$Z$288,25,FALSE) -> 0 | K17: =IF($D17>=1,$J17+(D17*E17)+(F17*G17)+(H17*I17),IF($F17>=1,$J17+(D17*E17)+(F17*G17)+(H17*I17),IF($H17>=1,$J17+(D17*E17)+(F17*G17)+(H17*I17),"")))
